Workbook
Name Diagramm_dT: Diagrammdaten!$C$5
Name Diagramm_Tmin: Diagrammdaten!$C$4
Name eta: Übersicht!$F$67
Name eta_V1: Übersicht!$F$65
Name eta_V2: Übersicht!$F$66
Name grad_V1: Übersicht!$F$55
Name Kopf_grenz: 'Kaverne & Gassäule'!$D$19
Name Kopf_leer: 'Kaverne & Gassäule'!$D$20
Name Kopf_voll: 'Kaverne & Gassäule'!$D$18
Name MV_Kopf_CH4: Medienvergleich!$E$11
Name MV_Kopf_CO2: Medienvergleich!$C$11
Name MV_Kopf_H2: Medienvergleich!$F$11
Name p_blase_TK: 'Gemisch & Grenzen'!$H$15
Name p_cricondenbar: 'Gemisch & Grenzen'!$H$11
Name p_grenz: 'Kaverne & Gassäule'!$C$19
Name p_lith_V1: Übersicht!$F$73
Name p_S1: Übersicht!$F$43
Name p_S2: Übersicht!$F$46
Name p_tau_TK: 'Gemisch & Grenzen'!$H$16
Name p_uek: Übersicht!$F$50
Name p_zw: Übersicht!$F$51
Name pmax_V1: Übersicht!$F$56
Name pmin_V1: Übersicht!$F$57
Name rho_min: Übersicht!$F$69
Name rho_n: 'Einspeicherung S1'!$E$19
Name rhoSalz_V1: Übersicht!$F$58
Name Stand_ok: Übersicht!$Q$39
Name Szen1_eta: 'Einspeicherung S1'!$E$14
Name Szen1_h1: 'Einspeicherung S1'!$E$10
Name Szen1_h2: 'Einspeicherung S1'!$E$15
Name Szen1_h2s: 'Einspeicherung S1'!$E$13
Name Szen1_mmax: 'Einspeicherung S1'!$E$21
Name Szen1_mmin: 'Einspeicherung S1'!$E$20
Name Szen1_p1: 'Einspeicherung S1'!$E$8
Name Szen1_p2: 'Einspeicherung S1'!$E$12
Name Szen1_Pmax: 'Einspeicherung S1'!$E$23
Name Szen1_Pmin: 'Einspeicherung S1'!$E$22
Name Szen1_s1: 'Einspeicherung S1'!$E$11
Name Szen1_T1: 'Einspeicherung S1'!$E$9
Name Szen1_T2: 'Einspeicherung S1'!$E$16
Name Szen1_w: 'Einspeicherung S1'!$E$18
Name T_Kav_V1: Übersicht!$F$72
Name T_maxV: Übersicht!$F$49
Name T_S1: Übersicht!$F$44
Name T_S2: Übersicht!$F$47
Name Tober_V1: Übersicht!$F$54
Name U_PG: 'Gemisch & Grenzen'!$H$14
Name V_max: Übersicht!$F$64
Name V_min: Übersicht!$F$63
Name Z_min: Übersicht!$F$68
Name z_V1: Übersicht!$F$53
Name Zoom_Tmin: Diagrammdaten!$C$6
Name Zoom2_Tmin: Diagrammdaten!$F$6
Name T_ZK: Übersicht!$F$48
Name T_KW: Übersicht!$F$60
Name T_K: Übersicht!$F$61
Name Kopf_betr_S1: 'Kaverne & Gassäule'!$D$91
Name Kopf_betr_S2: 'Kaverne & Gassäule'!$D$93
Name Szen2_h1: 'Einspeicherung S2'!$E$11
Name Szen2_h1s: 'Einspeicherung S2'!$E$14

Sheet Übersicht
B1: CO₂-Zwischenspeicherung in Salzkavernen – Obertageanlage · Worst-Case-Gemisch
B2: Rechenübersicht Einspeicherung · Masterarbeit Sarah Maxara · TH Köln / Uniper Energy Storage
B3: Stand: 15.10.2026 (nach der Besprechung mit K. Vosbeck) · Stoffdaten: CoolProp 8.0.0, Mehrfluid-Helmholtz-Modell (GERG-2008-Mischungsregel, Reinstoffe u. a. Span & Wagner 1996) · Worst-Case-Gemisch 95 % CO₂, 2,4 % N₂, 1 % Ar, 1 % CH₄, 0,5 % H₂, 0,1 % CO (mol-%)
B5: Worum geht es? | J5: Farblegende der Zellen
B6: Diese Mappe zeigt Schritt für Schritt, wie die Obertageanlage für die Einspeicherung berechnet wird: 1. Welcher Druck muss am Bohrlochkopf anliegen? → das gibt die Kaverne über die Gassäule vor. 2. Wie bringt die Anlage das CO₂ auf diesen Druck? → Pumpe (dichte Anlieferung, S1) bzw. zwei Verdichterstufen, Kühler und Pumpe (gasförmige Anlieferung, S2). 3. Wo liegen alle Zustände im Phasendiagramm – und wo liegt das Betriebsfenster von Bohrloch und Kaverne? Diese Mappe rechnet das Worst-Case-Gemisch mit 5 % Begleitstoffen – gleicher Aufbau wie die Mappe für reines CO₂. Was sich an den Grenzen ändert und warum: Blatt „Gemisch & Grenzen“. | J6: 91 | K6: Annahme – darf geändert werden
J7: 246.6 | K7: Stoffwert aus CoolProp – fest
J8: 100 | K8: Excel-Formel – rechnet sofort mit
J9: 114.9 | K9: wichtiges Ergebnis
J10: rot | K10: Stoffwert passt nicht mehr zu den Annahmen
B12: Inhalt
B13: → Kaverne & Gassäule | E13: Welchen Kopfdruck gibt die Kaverne vor? Stillstand für drei Füllstände (wie Q-028, Fig. 3) und – neu – im Betrieb: strömende Säule beim Einspeisen (Zieldruck der Pumpe).
B14: → Medienvergleich | E14: Warum braucht CO₂ oben weniger Druck als Erdgas oder Wasserstoff? Mit reinem CO₂ zum Vergleich.
B15: → Einspeicherung S1 | E15: Anlieferung dicht: Pumpe – jeder Rechenschritt einzeln. Mit Phasendiagramm der Schritte.
B16: → Einspeicherung S2 | E16: Anlieferung gasförmig: 2 Verdichterstufen (Zwischenkühler 40 °C), Kühler bei 91 bar auf 26 °C, Pumpe – mit Begründung des Wegs.
B17: → Phasendiagramm | E17: Diagramm 1: Prozesspfade bis zum Bohrlochkopf. Diagramm 2: Betriebsfenster von Bohrloch und Kaverne (nur Stillstand).
B18: → Quellen | E18: Herkunft aller Annahmen und Stoffdaten.
B19: → Diagrammdaten | E19: Hilfstabellen für die Diagramme (nicht ändern).
B20: → Gemisch & Grenzen | E20: Was die Begleitstoffe ändern: Zweiphasengebiet, Unsicherheit ±3 bar, neue Grenzen der Anlage. Mit Phasendiagrammen rein vs. Gemisch.
B21: Prozesskette Einspeicherung – Szenarien
B35: Neu (15.10.2026): | D35: → Annahmen & Begründung | G35: → Kühlung | I35: → Massenströme
B36: Annahmen mit Quelle und Fundstelle (Seite, Folie, Tabelle) · warum Zwischenkühler 40 °C und Kühler vor der Pumpe 26 °C · ein Massenstrom, viele Volumenströme
B37: Szenarien & Annahmen
B38: Blaue Werte dürfen geändert werden. Weiße Formelwerte rechnen sofort mit. Graue Stoffwerte (CoolProp) kann Excel nicht selbst berechnen – ändert sich eine Annahme, zeigt der Status, welche Werte neu berechnet werden müssen.
B39: Status | E39: =IF(Stand_ok,"✔ Alle grauen Stoffwerte passen zu den Annahmen.","⚠ Mindestens eine Annahme wurde geändert – rot markierte Stoffwerte sind veraltet und müssen neu berechnet werden.") | Q39: =COUNTIF($N$42:$N$69,"⚠*")=0
B41: Größe | E41: Symbol | F41: Wert | G41: Einheit | H41: Quelle / Begründung | M41: gerechnet mit | N41: Status
B42: Anlieferszenario S1 – dichte Phase (Pipeline OGE)
B43: Übergabedruck | E43: p_S1 | F43: 91 | G43: bar | H43: OGE-Notizen 16.09.2026, Pkt. 6: mind. 91 bar (vorher 85 bar), Worst Case mit Begleitstoffen | M43: 91 | N43: =IF(ABS(F43-M43)<0.000000001,"✔ passt","⚠ geändert – neu rechnen")
B44: Übergabetemperatur | E44: T_S1 | F44: 15 | G44: °C | H44: Annahme: Medientemperatur der Fernleitung (nicht Gebirgstemperatur) | M44: 15 | N44: =IF(ABS(F44-M44)<0.000000001,"✔ passt","⚠ geändert – neu rechnen")
B45: Anlieferszenario S2 – gasförmig
B46: Übergabedruck | E46: p_S2 | F46: 30 | G46: bar | H46: Annahme aus Vorarbeit; alte Tabelle nennt Q-040 (ISO 27913) – dort noch nicht ausgewertet, zu prüfen | M46: 30 | N46: =IF(ABS(F46-M46)<0.000000001,"✔ passt","⚠ geändert – neu rechnen")
B47: Übergabetemperatur | E47: T_S2 | F47: 15 | G47: °C | H47: Annahme: Medientemperatur | M47: 15 | N47: =IF(ABS(F47-M47)<0.000000001,"✔ passt","⚠ geändert – neu rechnen")
B48: CO₂-Temperatur nach dem Zwischenkühler (S2) | E48: T_ZK | F48: 40 | G48: °C | H48: Q-017 S. 37 (Tab. 3): Soll-Kühltemperatur CO₂ 40 °C; Q-063 Kap. 5.1: CO₂ „no more than about 40 °C“, Kühlung zwischen den Stufen – Begründung: Blatt „Kühlung“ | M48: 40 | N48: =IF(ABS(F48-M48)<0.000000001,"✔ passt","⚠ geändert – neu rechnen")
B49: Max. Austrittstemperatur je Verdichterstufe | E49: T_max | F49: 95 | G49: °C | H49: Q-016 S. 4 (Kap. 2.3, dort Lit. [24]): höchstens 95 °C nach jeder Stufe → legt die Zahl der Stufen fest | M49: 95 | N49: =IF(ABS(F49-M49)<0.000000001,"✔ passt","⚠ geändert – neu rechnen")
B50: Druck nach Verdichtung = Kühldruck (S2) | E50: p_ük | F50: 91 | G50: bar | H50: über der Cricondenbar (82,2 bar) + 8,8 bar ≥ 3 bar Unsicherheit → Kühler ohne Phasenwechsel; = Übergabedruck S1 (gleicher Pumpeneintritt) | M50: 91 | N50: =IF(ABS(F50-M50)<0.000000001,"✔ passt","⚠ geändert – neu rechnen")
B51: Zwischendruck (S2) | E51: p_zw | F51: 55 | G51: bar | H51: eigene Herleitung (Blatt „Kühlung“): höchster runder Druck mit Z ≥ 0,7 (Q-017 S. 44) am Eintritt Stufe 2 bei 40 °C für rein und Gemisch; beide Stufen < 95 °C | M51: 55 | N51: =IF(ABS(F51-M51)<0.000000001,"✔ passt","⚠ geändert – neu rechnen")
B52: Kaverne V1 – tief (Referenzkaverne; flache Kaverne entfällt)
B53: Teufe (LCCS) | E53: z | F53: 1200 | G53: m | H53: Q-030 Tab. 1, Option 2; abgestimmt mit M. Wall (Uniper). Flache Kaverne entfällt: Q-030 S. 17 (DBI: fast sofort Flüssigphase in Kaverne bzw. am Kopf), Besprechung K. Vosbeck 15.10.2026 | M53: 1200 | N53: =IF(ABS(F53-M53)<0.000000001,"✔ passt","⚠ geändert – neu rechnen")
B54: Gebirgstemperatur an der Oberfläche | E54: T₀ | F54: 10 | G54: °C | H54: Q-028 Kap. 3 (S. 5), Fig. 3: 10 °C an der Oberfläche | M54: 10 | N54: =IF(ABS(F54-M54)<0.000000001,"✔ passt","⚠ geändert – neu rechnen")
B55: Geothermischer Gradient | E55: grad T | F55: 0.03 | G55: K/m | H55: Q-028 Kap. 3 (S. 5), Fig. 3: 0,03 K/m | M55: 0.03 | N55: =IF(ABS(F55-M55)<0.000000001,"✔ passt","⚠ geändert – neu rechnen")
B56: Maximaldruck an der LCCS | E56: p_max | F56: 210 | G56: bar | H56: Zwischenwert aus Q-028 Tab. 1 (200 bar) und Q-030 Tab. 1, Opt. 2 (240 bar); Vorgabe M. Wall | M56: 210 | N56: =IF(ABS(F56-M56)<0.000000001,"✔ passt","⚠ geändert – neu rechnen")
...

Sheet Gemisch & Grenzen
B1: Gemisch & Grenzen – was die Begleitstoffe am Phasendiagramm ändern
B2: Worst-Case-Gemisch Anlieferung · Stoffdaten CoolProp 8.0.0 (GERG-2008-Mischungsregel) · Vergleich mit der Mappe für reines CO₂ · rechts: Phasendiagramme reines CO₂ und Gemisch nebeneinander, darunter die Erklärung
B3: ← zur Übersicht
B5: Kurz gesagt
B6: Reines CO₂ hat eine Dampfdrucklinie: bei jeder Temperatur genau ein Druck, bei dem es siedet. Das Gemisch hat stattdessen ein Zweiphasengebiet zwischen Taulinie (erster Tropfen) und Blasenlinie (letzte Blase). Die leichtflüchtigen Begleitstoffe (vor allem H₂ und N₂) schieben die Blasenlinie nach oben – für „sicher flüssig“ braucht man mehr Druck. Weil die Phasengrenze eines Gemischs unsicherer ist als die von reinem CO₂, gilt ein Sicherheitsabstand von ±3 bar (Modellvergleich, Dokumentation Kap. 9).
B8: Zusammensetzung (mol-%) | F8: Kennpunkte der Phasengrenze
B9: Komponente | C9: mol-% | D9: Beleg | F9: Kennpunkt | G9: T [°C] | H9: p [bar] | I9: reines CO₂ | J9: Bedeutung
B10: CO₂ | C10: 95 | D10: DIN EN 18397 / ISO 27913 | F10: Kritischer Punkt | G10: 27.954721 | H10: 81.455056 | I10: 31,0 °C / 73,8 bar | J10: Tau- und Blasenlinie treffen sich
B11: N₂ | C11: 2.4 | D11: Porthos-Grenzwert | F11: Cricondenbar | G11: 27.213118 | H11: 82.177594 | I11: = krit. Punkt | J11: darüber bei jeder Temperatur einphasig
B12: Ar | C12: 1 | D12: ca. Oxyfuel-Zusammensetzung | F12: Cricondentherm | G12: 28.093324 | H12: 80.896474 | I12: = krit. Punkt | J12: darüber bei jedem Druck einphasig
B13: CH₄ | C13: 1 | D13: Porthos-Grenzwert
B14: H₂ | C14: 0.5 | D14: DIN EN 18397 / DVGW C 260 | F14: Unsicherheit der Phasengrenze | H14: 3 | I14: bar | J14: Dokumentation Kap. 9: Modellstreuung 1 bar + Modellfehler 1–3 %
B15: CO | C15: 0.1 | D15: DIN EN 18397 (1000 ppm) | F15: Blasendruck bei T_K | G15: 26 | H15: 81.716223 | I15: 65,8 (p_sat) | J15: darüber vollständig flüssig
B16: Σ Begleitstoffe | C16: =SUM(C11:C15) | D16: = Grenze DIN EN 18397 | F16: Taudruck bei T_K | G16: 26 | H16: 74.435087 | I16: 65,8 (p_sat) | J16: darunter vollständig gasförmig
B18: Tau- und Blasendruck über der Temperatur
B19: T [°C] | C19: p_sat reines CO₂ [bar] | D19: Taudruck Gemisch [bar] | E19: Blasendruck Gemisch [bar] | F19: sicher gasförmig unter [bar] | G19: sicher flüssig über [bar]
B20: -50 | C20: 6.8234161 | D20: 7.2245097 | E20: 48.12601 | F20: =D20-U_PG | G20: =E20+U_PG
B21: -40 | C21: 10.044957 | D21: 10.657067 | E21: 46.018104 | F21: =D21-U_PG | G21: =E21+U_PG
B22: -30 | C22: 14.277617 | D22: 15.186693 | E22: 46.414444 | F22: =D22-U_PG | G22: =E22+U_PG
B23: -20 | C23: 19.69628 | D23: 21.019382 | E23: 48.909095 | F23: =D23-U_PG | G23: =E23+U_PG
B24: -10 | C24: 26.486767 | D24: 28.387878 | E24: 53.310212 | F24: =D24-U_PG | G24: =E24+U_PG
B25: 0 | C25: 34.851408 | D25: 37.573277 | E25: 59.51839 | F25: =D25-U_PG | G25: =E25+U_PG
B26: 5 | C26: 39.694653 | D26: 42.961015 | E26: 63.272176 | F26: =D26-U_PG | G26: =E26+U_PG
B27: 10 | C27: 45.021829 | D27: 48.964344 | E27: 67.428739 | F27: =D27-U_PG | G27: =E27+U_PG
B28: 15 | C28: 50.871474 | D28: 55.683743 | E28: 71.932696 | F28: =D28-U_PG | G28: =E28+U_PG
B29: 20 | C29: 57.290526 | D29: 63.370088 | E29: 76.650851 | F29: =D29-U_PG | G29: =E29+U_PG
B30: 25 | C30: 64.342443 | D30: 72.32523 | E30: 81.055196 | F30: =D30-U_PG | G30: =E30+U_PG
B31: 27 | C31: 67.361486 | D31: 76.817923 | E31: 82.152582 | F31: =D31-U_PG | G31: =E31+U_PG | L31: WARUM AUS DER LINIE EIN GEBIET WIRD – kurz erklärt • Reiner Stoff: Siedet eine Flüssigkeit, bleiben Druck und Temperatur fest verbunden (Gibbs'sche Phasenregel F = K − P + 2 = 1 − 2 + 2 = 1). Zu jeder Temperatur gehört genau ein Dampfdruck → Sättigungslinie. Verdampfen und Kondensieren passieren bei einer einzigen Temperatur. • Gemisch aus 6 Stoffen: F = 6 − 2 + 2 = 6 → Gas und Flüssigkeit können über einen Bereich von Druck und Temperatur nebeneinander bestehen. Aus der Linie wird ein Gebiet zwischen Taulinie (erster Tropfen) und Blasenlinie (letzte Blase). • Die Begleitstoffe sind „leicht“: ihre kritischen Temperaturen liegen weit unter 0 °C (H₂ −240 °C, N₂ −147 °C, CO −140 °C, Ar −122 °C, CH₄ −83 °C). Sie wollen gasförmig bleiben und lösen sich in flüssigem CO₂ nur unter höherem Druck → die Blasenlinie steigt: bei 20 °C von 57,3 bar (reines CO₂) auf 76,7 bar. • Die Taulinie liegt ebenfalls höher (63,4 bar bei 20 °C): das CO₂ kondensiert erst, wenn sein eigener Partialdruck (≈ 95 % des Gesamtdrucks) seinen Dampfdruck erreicht → Gesamtdruck ≈ 57,3 / 0,95 ≈ 60 bar (real etwas mehr). • Beim Abkühlen fällt zuerst fast reines CO₂ aus; die Gasphase reichert sich mit N₂ und H₂ an (bei 30 bar / −40 °C: 30 % N₂, 11 % H₂ in der Gasphase). Deshalb Temperaturgleit statt fester Kondensationstemperatur – bei 80 bar von 27,9 auf 23,7 °C. • Kalt öffnet sich das Gebiet weit: in kaltem flüssigem CO₂ lösen sich die leichten Gase kaum, der Blasendruck fällt nie unter 45,9 bar. Ein Gemisch lässt sich bei 30 bar nicht vollständig verflüssigen. • Der kritische Punkt wandert von 31,0 °C / 73,8 bar nach 28,0 °C / 81,5 bar; höchster Druck des Gebiets (Cricondenbar) 82,2 bar, höchste Temperatur (Cricondentherm) 28,1 °C. Darüber gibt es – wie beim reinen CO₂ über dem kritischen Punkt – keine Phasengrenze mehr. • FOLGE: Grenzen, die bei reinem CO₂ an p_krit hängen, hängen beim Gemisch an der Cricondenbar + 3 bar Unsicherheit = 85,2 bar (S1-Übergabe, Pumpeneintritt, einphasiges Bohrloch). Die Tabellen links nennen die Zahlen, Dokumentation_S2_Gemisch.docx die Folgen für die Einspeicherkette.
B32: Unter −56,6 °C bildet sich Trockeneis (nicht im Modell). Oberhalb von 28,1 °C gibt es beim Gemisch kein Zweiphasengebiet mehr.
B34: Neue Grenzen der Einspeicherung – wo sie sich ergeben
B35: Grenze | D35: reines CO₂ | E35: Gemisch | F35: Folge für die Anlage | G35: Blatt
B36: Mindestdruck dichte Anlieferung bei 15 °C | D36: 50,9 bar | E36: 71,9 + 3 bar | F36: S1 mit 91 bar sicher dicht (8,8 bar über der Cricondenbar) | G36: Einspeicherung S1
B37: Druck für den Kühler (S2) | D37: 91 bar (über p_krit 73,8 bar) – gleicher Weg | E37: 91 bar (Cricondenbar 82,2 + 8,8) | F37: überkritisch kühlen: kein Verflüssiger, keine Kondensation | G37: Einspeicherung S2
B38: Verdichtung 30 bar → Enddruck in einer Stufe | D38: 111,8 °C ✘ (bis 91 bar) | E38: 112,7 °C ✘ (bis 91 bar) | F38: zwei Verdichterstufen nötig: 30 → 55 → 91 bar (rein und Gemisch) | G38: Einspeicherung S2
B39: Zwischenkühler 40 °C (S2) | D39: über T_krit (31,0 °C) – keine Kondensation | E39: über der Cricondentherm (28,1 °C) – keine Kondensation | F39: Zwischendruck frei wählbar → 55 bar: Z ≥ 0,7 (Q-017 S. 44), Stufe 2 84,7 °C ≤ 95 °C | G39: Kühlung
B40: Kopfdruck bei voller Kaverne | D40: 107,6 bar | E40: 114,9 bar | F40: Stillstand; im Betrieb (100.000 Nm³/h): S1 114,3 / S2 127,3 bar (rein 105,4 / 114,6 bar) | G40: Kaverne & Gassäule
B41: Bohrloch ganz einphasig (Grenzfall) | D41: Kopf ≥ 73,8 bar (p_krit) | E41: Kopf ≥ 82,2 bar (Cricondenbar) | F41: Kavernendruck ab 171,2 bar (rein: 171,7 bar) | G41: Kaverne & Gassäule
B42: Leere Kaverne (70 bar unten) | D42: Kopf 45,0 bar, 0–236 m zweiphasig | E42: Kopf 50,7 bar, 0–82 m zweiphasig | F42: Zweiphasengebiet im oberen Bohrloch kleiner, aber vorhanden | G42: Kaverne & Gassäule
B43: Kritische Temperatur | D43: 31,0 °C | E43: 28,0 °C | F43: S2-Kühler liegt über der Cricondenbar – keine Kondensation nötig; Dichte ≥ 500 kg/m³ bis 32 °C | G43: Einspeicherung S2
B44: Dichte am Kavernenboden (210 bar, 46 °C) | D44: 817,6 kg/m³ | E44: 756,0 kg/m³ | F44: -7.5 % Masse je m³ Kavernenvolumen | G44: Kaverne & Gassäule
...

Sheet Kaverne & Gassäule
B1: Kaverne & Gassäule – welcher Druck muss am Bohrlochkopf anliegen?
B2: Einspeicherung, Kaverne V1 (tief) · Stillstand: Temperatur = Gebirgstemperatur · Worst-Case-Gemisch
B3: ← zur Übersicht
B4: WAS WIRD BERECHNET? Die Kaverne legt fest, welcher Druck unten an der LCCS (letzte zementierte Rohrtour) höchstens anliegen darf: 210 bar. Gesucht ist der Druck, den die Anlage dafür oben am Bohrlochkopf liefern muss. WARUM? Zwischen Kopf und Kaverne steht eine 1200 m hohe Säule aus dem CO₂-Gemisch. Ihr Gewicht erhöht den Druck nach unten: dp/dz = ρ(p,T) · g. WIE WIRD GERECHNET? Die Dichte ρ hängt selbst von Druck und Temperatur ab – deshalb wird die Säule in 600 Schritten à 2 m gerechnet, in jedem Schritt mit neuer Dichte aus CoolProp (Gemisch). Temperatur = Gebirgstemperatur T(z) = T₀ + grad T · z (Stillstand). Gerechnet wird von unten (bekannter Kavernendruck) nach oben – das Ergebnis ist direkt der Kopfdruck. GRENZFALL: Mit dem Sekantenverfahren wird der Kavernendruck gesucht, bei dem der Kopfdruck genau die Cricondenbar des Gemischs ist (82,2 bar = höchster Druck des Zweiphasengebiets; bei reinem CO₂ war es p_krit = 73,8 bar). Darüber bleibt das ganze Bohrloch einphasig, darunter kann sich im oberen Bohrloch eine Gasphase bilden. ERGEBNIS: Für 210 bar unten sind 114,9 bar am Kopf nötig – die Säule liefert rund 95 bar (reines CO₂: 107,6 bar bzw. 102 bar). Das Gemisch ist leichter, deshalb muss die Anlage oben mehr Druck aufbringen. VERGLEICH: Unter der Ergebnistabelle stehen dieselben drei Füllstände für reines CO₂; in den Diagrammen Druck und Dichte gepunktet. Das Gemisch ist in der Säule 7–10 % leichter – deshalb 7,3 bar mehr am Kopf bei voller Kaverne. IM BETRIEB (NEU): Beim Einspeisen strömt das CO₂ mit der Temperatur nach der Pumpe nach unten – Abschnitt unten. Zieldruck der Pumpe bei 100.000 Nm³/h: S1 114,3 bar, S2 127,3 bar (Stillstand 114,9 bar).
B6: Kavernenparameter
B7: Größe | C7: Kaverne V1 (tief) | D7: Kaverne V2 (flach): entfällt | E7: Einheit
B8: Teufe (LCCS) | C8: =z_V1 | E8: m
B9: Gebirgstemperatur Oberfläche | C9: =Tober_V1 | E9: °C
B10: Geothermischer Gradient | C10: =grad_V1 | E10: K/m
B11: Kavernentemperatur | C11: =T_Kav_V1 | E11: °C
B12: Maximaldruck an der LCCS | C12: =pmax_V1 | E12: bar
B13: Minimaldruck an der LCCS | C13: =pmin_V1 | E13: bar
B14: Werte kommen von der Übersicht. Die flache Kaverne entfällt (Q-030 S. 17: DBI verwirft sie selbst; Besprechung K. Vosbeck 15.10.2026).
B16: Ergebnis: drei Füllstände der Kaverne
B17: Fall | C17: Druck unten (LCCS) [bar] | D17: Kopfdruck [bar] | E17: T am Kopf [°C] | F17: ρ Kopf [kg/m³] | G17: ρ unten [kg/m³] | H17: Säulengewinn [bar] | I17: Bedeutung
B18: voll (p_max) | C18: 210 | D18: 114.9313 | E18: 10 | F18: 865.00462 | G18: 755.95384 | H18: =C18-D18 | I18: Zieldruck für die Einspeicherung
B19: Grenzfall | C19: 171.19473 | D19: 82.177594 | E19: 10 | F19: 825.29682 | G19: 695.90622 | H19: =C19-D19 | I19: Kopfdruck = Cricondenbar (82,2 bar): ab hier ist das Bohrloch ganz einphasig
B20: leer (p_min) | C20: 70 | D20: 50.705459 | E20: 10 | F20: 208.63402 | G20: 166.94226 | H20: =C20-D20 | I20: Kopf 50,7 bar → zweiphasig 0–82 m (reines CO₂: 45,0 bar, 0–236 m)
B22: Zum Vergleich: reines CO₂ (gleiche Kaverne, Werte aus der Mappe für reines CO₂)
B23: Fall | C23: Druck unten (LCCS) [bar] | D23: Kopfdruck [bar] | E23: T am Kopf [°C] | F23: ρ Kopf [kg/m³] | G23: ρ unten [kg/m³] | H23: Säulengewinn [bar] | I23: Gemisch − rein: Kopfdruck [bar]
B24: voll (p_max) | C24: 210 | D24: 107.60322 | E24: 10 | F24: 926.32204 | G24: 817.60427 | H24: =C24-D24 | I24: =D18-D24
B25: Grenzfall (Kopf = p_krit 73,8 bar) | C25: 171.65228 | D25: 73.772984 | E25: 10 | F25: 897.02184 | G25: 771.2552 | H25: =C25-D25 | I25: =D19-D25
B26: leer (p_min) | C26: 70 | D26: 44.992994 | E26: 10 | F26: 134.97287 | G26: 180.73732 | H26: =C26-D26 | I26: =D20-D26
B28: Diagramme – Darstellung nach Buzogany & Kruck (2022), Fig. 3 (dort 1150 m Teufe, hier Kaverne V1 mit 1200 m)
B29: HIER ZUM STILLSTAND: Die Gassäulen gelten für ruhendes CO₂ mit Gebirgstemperatur und für die drei Füllstände nach Q-028 (Buzogany & Kruck 2022, Fig. 3: voll, Grenzfall, leer). Was Injektion und Ausspeicherung für das Fenster bedeuten (Reibungsdruckverlust im Strang, Wärmeaustausch mit dem Gebirge, Erwärmung bzw. Abkühlung in der Kaverne, Drosselung beim Ausspeichern), ist hier NICHT dargestellt.
B53: Tiefenprofile (gerechnet in 2-m-Schritten, dargestellt alle 50 m)
B54: Teufe z [m] | C54: T [°C] | D54: p voll [bar] | E54: ρ voll [kg/m³] | F54: p Grenzfall [bar] | G54: ρ Grenzfall [kg/m³] | H54: p leer [bar] | I54: ρ leer [kg/m³] | J54: p voll rein [bar] | K54: ρ voll rein [kg/m³] | L54: p Grenzfall rein [bar] | M54: ρ Grenzfall rein [kg/m³] | N54: p leer rein [bar] | O54: ρ leer rein [kg/m³]
B55: 0 | C55: 10 | D55: 114.9313 | E55: 865.00462 | F55: 82.177594 | G55: 825.29682 | H55: 50.705459 | I55: 208.63402 | J55: 107.60322 | K55: 926.32204 | L55: 73.772984 | M55: 897.02184 | N55: 44.992994 | O55: 134.97287
B56: 50 | C56: 11.5 | D56: 119.16101 | E56: 859.85865 | F56: 86.209692 | G56: 819.03601 | H56: 51.65963 | I56: 180.45339 | J56: 112.13418 | K56: 921.36649 | L56: 78.158267 | M56: 891.29696 | N56: 46.658027
B57: 100 | C57: 13 | D57: 123.36557 | E57: 854.75081 | F57: 90.211177 | G57: 812.81436 | H57: 52.470045 | I57: 158.26745 | J57: 116.6409 | K57: 916.43579 | L57: 82.515515 | M57: 885.59013 | N57: 48.469674
B58: 150 | C58: 14.5 | D58: 127.54518 | E58: 849.68334 | F58: 94.182258 | G58: 806.63793 | H58: 53.247139 | I58: 158.58157 | J58: 121.12349 | K58: 911.53193 | L58: 86.844824 | M58: 879.9048 | N58: 50.287387
B59: 200 | C59: 16 | D59: 131.70005 | E59: 844.65845 | F59: 98.123172 | G59: 800.51281 | H59: 54.025824 | I59: 158.91436 | J59: 125.58211 | K59: 906.65681 | L59: 91.146309 | M59: 874.24443 | N59: 52.113012
B60: 250 | C60: 17.5 | D60: 135.83037 | E60: 839.67828 | F60: 102.03419 | G60: 794.4451 | H60: 54.806181 | I60: 159.26271 | J60: 130.01689 | K60: 901.81229 | L60: 95.420101 | M60: 868.61242 | N60: 53.576396 | O60: 172.35313
B61: 300 | C61: 19 | D61: 139.93639 | E61: 834.74497 | F61: 105.9156 | G61: 788.4408 | H61: 55.588282 | I61: 159.62407 | J61: 134.428 | K61: 897.00015 | L61: 99.666347 | M61: 863.01213 | N61: 54.422451 | O61: 172.62152
B62: 350 | C62: 20.5 | D62: 144.01834 | E62: 829.86064 | F62: 109.76773 | G62: 782.50579 | H62: 56.372183 | I62: 159.9963 | J62: 138.81558 | K62: 892.22209 | L62: 103.88521 | M62: 857.44688 | N62: 55.269946 | O62: 172.93614
B63: 400 | C63: 22 | D63: 148.07646 | E63: 825.0274 | F63: 113.59095 | G63: 776.64564 | H63: 57.157934 | I63: 160.37761 | J63: 143.17982 | K63: 887.47971 | L63: 108.07688 | M63: 851.91995 | N63: 56.119079 | O63: 173.28715
B64: 450 | C64: 23.5 | D64: 152.111 | E64: 820.24733 | F64: 117.38562 | G64: 770.86559 | H64: 57.945576 | I64: 160.76647 | J64: 147.52089 | K64: 882.77457 | L64: 112.24153 | M64: 846.43458 | N64: 56.970012 | O64: 173.66732
B65: 500 | C65: 25 | D65: 156.12224 | E65: 815.52247 | F65: 121.15215 | G65: 765.17044 | H65: 58.735141 | I65: 161.1616 | J65: 151.83898 | K65: 878.10816 | L65: 116.3794 | M65: 840.99405 | N65: 57.822871 | O65: 174.07112
B66: 550 | C66: 26.5 | D66: 160.11045 | E66: 810.85475 | F66: 124.89098 | G66: 759.56449 | H66: 59.526657 | I66: 161.5619 | J66: 156.13429 | K66: 873.48191 | L66: 120.4907 | M66: 835.60164 | N66: 58.677762 | O66: 174.49423
B67: 600 | C67: 28 | D67: 164.07591 | E67: 806.24602 | F67: 128.60254 | G67: 754.05156 | H67: 60.320149 | I67: 161.96641 | J67: 160.407 | K67: 868.89724 | L67: 124.57568 | M67: 830.26066 | N67: 59.53477 | O67: 174.93315
...

Sheet Medienvergleich
B1: Medienvergleich – warum CO₂ oben weniger Druck braucht
B2: Gleiche Kaverne (Ziel 210 bar unten, Gebirge 10 °C + 0,03 K/m), gleiche Rechnung – nur das Medium ist anders
B3: ← zur Übersicht
B4: IDEE: Je schwerer die Säule im Bohrloch, desto mehr Druck liefert sie und desto weniger muss die Anlage oben aufbringen. Das CO₂-Gemisch ist unter diesen Bedingungen dicht (756–865 kg/m³; reines CO₂ 820–930 kg/m³), Erdgas und Wasserstoff bleiben Gase (Erdgas ~150 kg/m³, Wasserstoff ~15 kg/m³). FOLGE: Für das CO₂-Gemisch reicht eine Pumpe auf ~115 bar (reines CO₂ ~108 bar). Erdgas- und Wasserstoffspeicher brauchen Verdichter fast bis zum vollen Kavernendruck. Rechnung wie auf Blatt „Kaverne & Gassäule“: dp/dz = ρ(p,T) · g, von unten nach oben, Dichte aus CoolProp (CO₂: Worst-Case-Gemisch, Methan als Erdgas-Ersatz, reiner Wasserstoff). Der Zieldruck unten bleibt für alle Teufen bewusst bei 210 bar, damit nur der Effekt der Säule sichtbar wird. REINES CO₂: zum Vergleich in allen Tabellen und Diagrammen (dunkelblau gestrichelt, Werte aus der Mappe für reines CO₂). Reines CO₂ ist dichter (820–930 statt 756–865 kg/m³) und braucht oben 7,3 bar weniger.
B6: 1) Nötiger Kopfdruck über der Teufe (210 bar unten)
B7: Teufe [m] | C7: CO₂-Gemisch [bar] | D7: reines CO₂ [bar] | E7: Erdgas CH₄ [bar] | F7: Wasserstoff H₂ [bar] | G7: Ziel unten [bar]
B8: 600 | C8: 158.49008 | D8: 155.16617 | E8: 200.16601 | F8: 209.09501 | G8: =pmax_V1
B9: 800 | C9: 142.98603 | D9: 138.41709 | E9: 197.20927 | F9: 208.805 | G9: =pmax_V1
B10: 1000 | C10: 128.4373 | D10: 122.53672 | E10: 194.39268 | F10: 208.52047 | G10: =pmax_V1
B11: 1200 | C11: 114.9313 | D11: 107.60322 | E11: 191.70534 | F11: 208.24119 | G11: =pmax_V1
B12: 1400 | C12: 102.56219 | D12: 93.705839 | E12: 189.13736 | F12: 207.96699 | G12: =pmax_V1
B13: 1600 | C13: 91.42468 | D13: 80.943841 | E13: 186.67971 | F13: 207.69769 | G13: =pmax_V1
B14: CO₂-Gemisch: 67 bar weniger Kopfdruck zwischen 600 und 1600 m (reines CO₂: 74 bar) – Erdgas und Wasserstoff profitieren kaum von der Teufe.
B16: 2) Kennzahlen bei 1200 m Teufe
B17: Medium | C17: Kopfdruck [bar] | D17: Säulengewinn [bar] | E17: ρ Kopf [kg/m³] | F17: ρ unten [kg/m³] | G17: Übertagetechnik
B18: CO₂-Gemisch | C18: 114.9313 | D18: =pmax_V1-C18 | E18: 865.00462 | F18: 755.95384 | G18: Pumpe (91 → 115 bar)
B19: reines CO₂ | C19: 107.60322 | D19: =pmax_V1-C19 | E19: 926.32204 | F19: 817.60427 | G19: Pumpe (91 → 108 bar)
B20: Erdgas (CH₄) | C20: 191.70534 | D20: =pmax_V1-C20 | E20: 167.47194 | F20: 145.17947 | G20: Verdichter bis ~192 bar
B21: Wasserstoff (H₂) | C21: 208.24119 | D21: =pmax_V1-C21 | E21: 15.728831 | F21: 14.210688 | G21: Verdichter bis ~208 bar
B22: Bei Erdgas und Wasserstoff ist die Dichte unten kleiner als oben: der Temperaturanstieg überwiegt den Druckanstieg.
B24: 3) Druck- und Dichteprofile über die Teufe (Kaverne V1, 1200 m – gerechnet in 2-m-Schritten, dargestellt alle 50 m)
B25: Teufe z [m] | C25: p CO₂-Gemisch [bar] | D25: ρ CO₂-Gemisch [kg/m³] | E25: p reines CO₂ [bar] | F25: ρ reines CO₂ [kg/m³] | G25: p CH₄ [bar] | H25: ρ CH₄ [kg/m³] | I25: p H₂ [bar] | J25: ρ H₂ [kg/m³]
B26: 0 | C26: 114.9313 | D26: 865.00462 | E26: 107.60322 | F26: 926.32204 | G26: 191.70534 | H26: 167.47194 | I26: 208.24119 | J26: 15.728831
B27: 50 | C27: 119.16101 | D27: 859.85865 | E27: 112.13418 | F27: 921.36649 | G27: 192.5238 | H27: 166.30248 | I27: 208.31816 | J27: 15.658526
B28: 100 | C28: 123.36557 | D28: 854.75081 | E28: 116.6409 | F28: 916.43579 | G28: 193.33659 | H28: 165.15879 | I28: 208.39479 | J28: 15.588903
B29: 150 | C29: 127.54518 | D29: 849.68334 | E29: 121.12349 | F29: 911.53193 | G29: 194.14383 | H29: 164.0401 | I29: 208.47108 | J29: 15.519951
B30: 200 | C30: 131.70005 | D30: 844.65845 | E30: 125.58211 | F30: 906.65681 | G30: 194.94564 | H30: 162.94567 | I30: 208.54703 | J30: 15.451659
B31: 250 | C31: 135.83037 | D31: 839.67828 | E31: 130.01689 | F31: 901.81229 | G31: 195.74215 | H31: 161.87476 | I31: 208.62264 | J31: 15.384018
B32: 300 | C32: 139.93639 | D32: 834.74497 | E32: 134.428 | F32: 897.00015 | G32: 196.53346 | H32: 160.82667 | I32: 208.69793 | J32: 15.317018
B33: 350 | C33: 144.01834 | D33: 829.86064 | E33: 138.81558 | F33: 892.22209 | G33: 197.31969 | H33: 159.80073 | I33: 208.77289 | J33: 15.25065
B34: 400 | C34: 148.07646 | D34: 825.0274 | E34: 143.17982 | F34: 887.47971 | G34: 198.10094 | H34: 158.79625 | I34: 208.84753 | J34: 15.184904
B35: 450 | C35: 152.111 | D35: 820.24733 | E35: 147.52089 | F35: 882.77457 | G35: 198.87732 | H35: 157.81261 | I35: 208.92184 | J35: 15.119771
B36: 500 | C36: 156.12224 | D36: 815.52247 | E36: 151.83898 | F36: 878.10816 | G36: 199.64893 | H36: 156.84918 | I36: 208.99584 | J36: 15.055243
B37: 550 | C37: 160.11045 | D37: 810.85475 | E37: 156.13429 | F37: 873.48191 | G37: 200.41586 | H37: 155.90536 | I37: 209.06952 | J37: 14.99131
... B50: 1200 | C50: 210 | D50: 755.95384 | E50: 210 | F50: 817.60427 | G50: 210 | H50: 145.17947 | I50: 210 | J50: 14.210688
B51: Gleiche Rechnung wie auf Blatt „Kaverne & Gassäule“ (Fall voll): von 210 bar unten nach oben integriert, Gebirge 10 °C + 0,03 K/m.

Sheet Einspeicherung S1
B1: Einspeicherung S1 – Anlieferung in dichter Phase: Pumpe (Worst-Case-Gemisch)
B2: Netzübergabe → Messtechnik/Filtration → Pumpe → Bohrlochkopf
B3: ← zur Übersicht
B4: AUSGANGSLAGE: Das CO₂-Gemisch kommt dicht (flüssigkeitsähnlich) aus der Fernleitung: 91 bar, 15 °C. Es liegt 19 bar über der Blasenlinie und 8,8 bar über der Cricondenbar – sicher außerhalb der Unsicherheit der Phasengrenze (±3 bar). ZIEL: 114,3 bar am Bohrlochkopf im Betrieb (100.000 Nm³/h) – strömende Säule, Blatt „Kaverne & Gassäule“, Abschnitt Betrieb. Im Stillstand wären es 114,9 bar: das kalte CO₂ aus der Pumpe (18,3 °C statt Gebirgstemperatur) macht die Säule schwerer, die Reibung (1,7 bar) kostet etwas zurück. WARUM EINE PUMPE? Das Gemisch ist bereits dicht und kaum kompressibel. Eine Pumpe genügt, ein Verdichter wäre nur für Gas nötig. RECHENWEG: (1) Zustand am Eintritt → Enthalpie h₁, Entropie s₁. (2) Idealfall: isentrope Druckerhöhung (Entropie bleibt gleich) → h₂s. (3) Realfall mit Verlusten über den isentropen Wirkungsgrad: h₂ = h₁ + (h₂s − h₁) / η. (4) Aus p₂ und h₂ → Austrittstemperatur T₂. (5) Spezifische Arbeit w = h₂ − h₁, Leistung P = ṁ · w. BEGRIFF: isentrop = Entropie konstant (Pumpe, Verdichter). Nicht verwechseln mit isenthalp = Enthalpie konstant (Drossel bei der Ausspeicherung). ANNAHMEN: η = 0,80 (eigene Annahme – Q-016 S. 4 nennt nur eine Glykolpumpe mit 70 %; Herstellerwert einholen); kein Druckverlust in Messtechnik und Filtration; Worst-Case-Gemisch (Enthalpien haben einen anderen Nullpunkt als bei reinem CO₂ – vergleichbar sind nur Differenzen).
B6: Rechenschritte
B7: Nr. | C7: Rechenschritt | D7: Formel / Funktion | E7: Wert | F7: Einheit | G7: Art des Werts
B8: 1 | C8: Eintrittsdruck | D8: = Übergabedruck S1 | E8: =p_S1 | F8: bar | G8: aus anderem Blatt
B9: 2 | C9: Eintrittstemperatur | D9: = Übergabetemperatur S1 | E9: =T_S1 | F9: °C | G9: aus anderem Blatt
B10: 3 | C10: Enthalpie Eintritt h₁ | D10: CoolProp: H(p₁, T₁) | E10: 246.62641 | F10: kJ/kg | G10: CoolProp (fest)
B11: 4 | C11: Entropie Eintritt s₁ | D11: CoolProp: S(p₁, T₁) | E11: 1.2726354 | F11: kJ/(kg·K) | G11: CoolProp (fest)
B12: 5 | C12: Austrittsdruck p₂ (= Zieldruck im Betrieb) | D12: Kaverne & Gassäule: Betrieb, V_n,max | E12: =Kopf_betr_S1 | F12: bar | G12: aus anderem Blatt
B13: 6 | C13: Enthalpie isentrop h₂s | D13: CoolProp: H(p₂, s = s₁) | E13: 249.52399 | F13: kJ/kg | G13: CoolProp (fest)
B14: 7 | C14: Isentroper Wirkungsgrad η | D14: Annahme (Übersicht) | E14: =eta | F14: – | G14: aus anderem Blatt
B15: 8 | C15: Enthalpie real h₂ | D15: h₂ = h₁ + (h₂s − h₁) / η | E15: =Szen1_h1+(Szen1_h2s-Szen1_h1)/eta | F15: kJ/kg | G15: Excel-Formel
B16: 9 | C16: Austrittstemperatur T₂ | D16: CoolProp: T(p₂, h₂) | E16: 18.305735 | F16: °C | G16: CoolProp (fest)
B17: 10 | C17: Phase am Austritt | D17: CoolProp: Phase(p₂, h₂) | E17: dicht (flüssig) | F17: – | G17: CoolProp (fest)
B18: 11 | C18: Spezifische Arbeit w | D18: w = h₂ − h₁ | E18: =Szen1_h2-Szen1_h1 | F18: kJ/kg | G18: Ergebnis (Formel)
B19: 12 | C19: Normdichte Gemisch (0 °C; 1,01325 bar) | D19: CoolProp: D(p_n, T_n), DIN 1343 | E19: 1.934285 | F19: kg/m³ | G19: CoolProp (fest)
B20: 13 | C20: Massenstrom, unterer Fall | D20: ṁ = V_n,min · ρ_n / 3600 | E20: =V_min*rho_n/3600 | F20: kg/s | G20: Excel-Formel
B21: 14 | C21: Massenstrom, oberer Fall | D21: ṁ = V_n,max · ρ_n / 3600 | E21: =V_max*rho_n/3600 | F21: kg/s | G21: Excel-Formel
B22: 15 | C22: Pumpenleistung, unterer Fall | D22: P = ṁ · w | E22: =Szen1_mmin*Szen1_w | F22: kW | G22: Ergebnis (Formel)
B23: 16 | C23: Pumpenleistung, oberer Fall | D23: P = ṁ · w | E23: =Szen1_mmax*Szen1_w | F23: kW | G23: Ergebnis (Formel)
B24: Wird η auf der Übersicht geändert, rechnen h₂, w und P sofort mit. T₂ kommt aus CoolProp und färbt sich dann rot (veraltet).
B26: Zustandspunkte
C27: Punkt | D27: p [bar] | E27: T [°C] | F27: h [kJ/kg] | G27: Phase
C28: Netzübergabe / Pumpe ein | D28: 91 | E28: 15 | F28: 246.62641 | G28: dicht (flüssig) | I28: Die Pumpe hebt den Druck von 91 auf 114,3 bar; die Temperatur steigt nur um 3,3 K. Der ganze Weg liegt über der Cricondenbar (82,2 bar) – das Gemisch bleibt einphasig dicht, die Pumpe sieht nie das Zweiphasengebiet. Gesamtbild: Blatt „Phasendiagramm“.
C29: Pumpe aus / Bohrlochkopf | D29: =Szen1_p2 | E29: =Szen1_T2 | F29: =Szen1_h2 | G29: dicht (flüssig)

Sheet Einspeicherung S2
B1: Einspeicherung S2 – gasförmige Anlieferung: verdichten, kühlen, pumpen (Worst-Case-Gemisch)
B2: Netzübergabe → Messtechnik/Filtration → Verdichter 1 → Zwischenkühler (40 °C) → Verdichter 2 → Kühler (91 bar, 26 °C) → Pumpe → Bohrlochkopf
B3: ← zur Übersicht
B4: AUSGANGSLAGE: Das CO₂-Gemisch kommt gasförmig an: 30 bar, 15 °C. Ziel: 127,3 bar am Bohrlochkopf im Betrieb (100.000 Nm³/h; Stillstand 114,9 bar – Blatt „Kaverne & Gassäule“). WEG: Zwei Verdichterstufen 30 → 55 → 91 bar mit Zwischenkühler auf 40 °C; 91 bar liegt über der Cricondenbar des Gemischs (82,2 bar). Der Kühler vor der Pumpe kühlt bei 91 bar auf 26 °C – das CO₂ wird stetig dichter, ohne ein Zweiphasengebiet zu berühren (keine Kondensation, kein Verflüssiger). Die Pumpe saugt einphasig dichtes CO₂ an (660 kg/m³) – bei demselben Druck wie in S1. ZWEI KÜHLER, ZWEI ZWECKE: Zwischenkühler senkt die Verdichterarbeit und hält Stufe 2 unter 95 °C → 40 °C (Q-017 S. 37; Q-063 Kap. 5.1). Kühler vor der Pumpe so kalt wie das Kühlwasser erlaubt, weit weg von der pseudokritischen Linie (32,8 °C bei 91 bar) → 26 °C = Kühlwasser 20 °C + 6 K (Q-120 Folie 24/32). Herleitung: Blatt „Kühlung“. ANNAHMEN (Übersicht): Zwischendruck 55 bar (Z ≥ 0,7, Q-017 S. 44) · höchstens 95 °C je Stufe (Q-016 S. 4) · Z > 0,65 am Verdichtereintritt (Siemens Energy) · ρ ≥ 500 kg/m³ an der Pumpe (Q-121 S. 2) · Wirkungsgrade 84 / 82 % (Q-016 S. 4), Pumpe 80 % (eigene Annahme). Quellen mit Fundstelle: Blatt „Annahmen & Begründung“. RECHENWEG: wie in S1 – Verdichter und Pumpe isentrop + Wirkungsgrad: h_aus = h_ein + (h_s − h_ein) / η. Kühler: abgeführte Wärme q = h_vor − h_nach. Grau = CoolProp-Wert (fest), weiß = Excel-Formel, grün = Ergebnis.
B6: Rechenschritte
B7: Nr. | C7: Rechenschritt | D7: Formel / Funktion | E7: Wert | F7: Einheit | G7: Art des Werts
B8: Verdichter 1. Stufe
B9: 1 | C9: Eintrittsdruck | D9: = Übergabe S2 | E9: =p_S2 | F9: bar | G9: aus anderem Blatt
B10: 2 | C10: Eintrittstemperatur | D10: = Übergabe S2 | E10: =T_S2 | F10: °C | G10: aus anderem Blatt
B11: 3 | C11: Enthalpie Eintritt | D11: CoolProp: H(p_ein, T_ein) | E11: 460.1284 | F11: kJ/kg | G11: CoolProp (fest)
B12: 4 | C12: Zwischendruck | D12: Annahme (Übersicht), Blatt „Kühlung“ | E12: =p_zw | F12: bar | G12: aus anderem Blatt
B13: 5 | C13: Wirkungsgrad η_V1 | D13: Annahme (Übersicht), Q-016 S. 4 | E13: =eta_V1 | F13: – | G13: aus anderem Blatt
B14: 6 | C14: Enthalpie isentrop | D14: CoolProp: H(p_zw, s_ein) | E14: 489.70648 | F14: kJ/kg | G14: CoolProp (fest)
B15: 7 | C15: Enthalpie real Austritt | D15: h = h_ein + (h_s − h_ein) / η_V1 | E15: =Szen2_h1+(Szen2_h1s-Szen2_h1)/eta_V1 | F15: kJ/kg | G15: Excel-Formel
B16: 8 | C16: Austrittstemperatur | D16: CoolProp: T(p_zw, h) | E16: 65.899089 | F16: °C | G16: CoolProp (fest)
B17: 9 | C17: Prüfung 95-°C-Grenze (Q-016 S. 4) | D17: T_aus ≤ T_max ? | E17: =IF(Szen2_T1a<=T_maxV,"✔ eingehalten","⚠ überschritten") | F17: – | G17: Excel-Formel
B18: 10 | C18: Spezifische Arbeit Stufe 1 | D18: w₁ = h_aus − h_ein | E18: =Szen2_h1a-Szen2_h1 | F18: kJ/kg | G18: Ergebnis (Formel)
B19: Zwischenkühler (auf T_ZK = 40 °C)
B20: 11 | C20: Prüfung: bleibt gasförmig? | D20: T_ZK > Cricondentherm ? | E20: =IF(T_ZK>T_cricondentherm,"✔ gasförmig ("&FIXED(T_ZK-T_cricondentherm,1)&" K über der Cricondentherm)","⚠ unter der Cricondentherm – Taudruck prüfen") | F20: – | G20: Excel-Formel
B21: 12 | C21: Enthalpie nach Zwischenkühler | D21: CoolProp: H(p_zw, T_ZK) | E21: 459.93005 | F21: kJ/kg | G21: CoolProp (fest)
B22: 13 | C22: Abgeführte Wärme | D22: q = h_vor − h_nach | E22: =Szen2_h1a-Szen2_hZK | F22: kJ/kg | G22: Excel-Formel
B23: 14 | C23: Realgasfaktor Eintritt Stufe 2 | D23: CoolProp: Z(p_zw, T_ZK) | E23: 0.74124743 | F23: – | G23: CoolProp (fest)
B24: 15 | C24: Prüfung Realgasfaktor (Siemens 0,65; Q-017: 0,7) | D24: Z > Z_min ? | E24: =IF(Szen2_Z2>=0.7,"✔ eingehalten (auch ≥ 0,7 nach Q-017)",IF(Szen2_Z2>Z_min,"✔ über "&FIXED(Z_min,2)&", unter 0,7 (Q-017)","⚠ nicht über "&FIXED(Z_min,2))) | F24: – | G24: Excel-Formel
B25: Verdichter 2. Stufe
B26: 16 | C26: Wirkungsgrad η_V2 | D26: Annahme (Übersicht), Q-016 S. 4 | E26: =eta_V2 | F26: – | G26: aus anderem Blatt
B27: 17 | C27: Austrittsdruck | D27: Annahme (Übersicht) | E27: =p_uek | F27: bar | G27: aus anderem Blatt
B28: 18 | C28: Enthalpie isentrop | D28: CoolProp: H(p_ük, s(p_zw, T_ZK)) | E28: 483.91014 | F28: kJ/kg | G28: CoolProp (fest)
B29: 19 | C29: Enthalpie real Austritt | D29: h = h_ein + (h_s − h_ein) / η_V2 | E29: =Szen2_hZK+(Szen2_h2s-Szen2_hZK)/eta_V2 | F29: kJ/kg | G29: Excel-Formel
B30: 20 | C30: Austrittstemperatur | D30: CoolProp: T(p_ük, h) | E30: 84.713427 | F30: °C | G30: CoolProp (fest)
B31: 21 | C31: Prüfung 95-°C-Grenze (Q-016 S. 4) | D31: T_aus ≤ T_max ? | E31: =IF(Szen2_T2a<=T_maxV,"✔ eingehalten","⚠ überschritten") | F31: – | G31: Excel-Formel
B32: 22 | C32: Spezifische Arbeit Stufe 2 | D32: w₂ = h_aus − h_ein | E32: =Szen2_h2a-Szen2_hZK | F32: kJ/kg | G32: Ergebnis (Formel)
B33: Kühler vor der Pumpe bei 91 bar (über der Cricondenbar – kein Phasenwechsel)
B34: 23 | C34: Prüfung: über der Phasengrenze? | D34: p_ük ≥ Cricondenbar + 3 bar ? | E34: =IF(p_uek>=p_cricondenbar+U_PG,"✔ "&FIXED(p_uek-p_cricondenbar,1)&" bar darüber – keine Phasengrenze","⚠ Kühler kreuzt das Zweiphasengebiet") | F34: – | G34: Excel-Formel
B35: 24 | C35: Enthalpie nach Kühler | D35: CoolProp: H(p_ük, T_K) | E35: 287.1366 | F35: kJ/kg | G35: CoolProp (fest)
B36: 25 | C36: Dichte nach Kühler = Pumpeneintritt | D36: CoolProp: D(p_ük, T_K) | E36: 660.42105 | F36: kg/m³ | G36: CoolProp (fest)
B37: 26 | C37: Prüfung Dichte (Q-121 S. 2) | D37: ρ ≥ ρ_min ? | E37: =IF(Szen2_rhoP>=rho_min,"✔ pumpbar (≥ "&TEXT(rho_min,"0")&" kg/m³)","⚠ zu dünn für eine Pumpe") | F37: – | G37: Excel-Formel
B38: 27 | C38: Abgeführte Wärme | D38: q = h_vor − h_nach | E38: =Szen2_h2a-Szen2_hK | F38: kJ/kg | G38: Excel-Formel
B39: Pumpe
B40: 28 | C40: Austrittsdruck (= Zieldruck im Betrieb) | D40: Kaverne & Gassäule: Betrieb, V_n,max | E40: =Kopf_betr_S2 | F40: bar | G40: aus anderem Blatt
B41: 29 | C41: Wirkungsgrad η_P | D41: Annahme (Übersicht) | E41: =eta | F41: – | G41: aus anderem Blatt
...

Sheet Kühlung
B1: Kühlung – Zwischenkühler 40 °C, Kühler vor der Pumpe 26 °C, Zwischendruck 55 bar
B2: Besprechung K. Vosbeck 15.10.2026, Pkt. 2 · Rechnung: Einspeicherung/Begleitstoffe_CO2/Prozesskette/05_kuehlung_begruendung.py · reines CO₂ und Worst-Case-Gemisch nebeneinander
B3: ← zur Übersicht
B4: ZWEI KÜHLER – ZWEI ZWECKE: Der Zwischenkühler (zwischen den Verdichterstufen, 55 bar) soll die Verdichterarbeit senken und die zweite Stufe unter 95 °C halten. Der Kühler vor der Pumpe (91 bar) soll das CO₂ so dicht wie möglich machen, damit die Pumpe einphasig und mit wenig Förderhöhe arbeitet. Deshalb zwei verschiedene Temperaturen. ZWISCHENKÜHLER 40 °C: Q-017 S. 37 (Tab. 3): „Soll-Kühltemperatur CO₂ 40 °C“, S. 61 (Siemens-Konzept, Eingangstemperatur 40 °C); Q-063 Kap. 5.1 (PDF-S. 22): CO₂ „no more than about 40 °C“, Kühlung „between and after compressor stages“. Kälter ist nicht besser: der Realgasfaktor sinkt (Tabelle 3) – bei 26 °C wäre Z beim reinen CO₂ 0,63 und damit unter 0,65 (Siemens). KÜHLER VOR DER PUMPE 26 °C: Kühlwasser 20 °C + 6 K (Q-120 Folie 24: CO₂ „seldom lower than 6 deg. C warmer than the air or water“). Q-120 Folie 32: für Pumpen auf 27–32 °C oder kälter kühlen, über 38 °C steigt die Förderhöhe stark. Bei 91 bar liegt die pseudokritische Linie (cp-Maximum, steilster Dichteabfall) beim Gemisch bei 32,8 °C, beim reinen CO₂ bei 40,5 °C (Tabelle 1) – 26 °C liegt sicher auf der dichten Seite. ZWISCHENDRUCK 55 bar: höchster runder Druck, bei dem am Eintritt Stufe 2 (40 °C) Z ≥ 0,7 (Q-017 S. 44) für beide Gasqualitäten gilt; beide Stufen bleiben dann unter 95 °C (Tabelle 2). MIT HERSTELLERN ABSTIMMEN (Messe Hamburg 20.–22.10.2026): Kühlwassertemperatur am Standort, erreichbare Grädigkeit, Z-Grenze der Laufradauslegung, Pumpenwirkungsgrad und Mindest-Saugdichte.
B6: 1) Dichte und Wärmekapazität bei 91 bar (Druck des Kühlers vor der Pumpe)
B7: T [°C] | C7: ρ rein [kg/m³] | D7: cp rein [kJ/(kg·K)] | E7: ρ Gemisch [kg/m³] | F7: cp Gemisch [kJ/(kg·K)]
B8: 10 | C8: 913.03975 | D8: 2.3954881 | E8: 837.81476 | F8: 2.6758407
B9: 11 | C9: 906.89906 | D9: 2.4204225 | E9: 830.15819 | F9: 2.7244325
B10: 12 | C10: 900.62977 | D10: 2.4470302 | E10: 822.25234 | F10: 2.7776822
B11: 13 | C11: 894.22335 | D11: 2.4755026 | E11: 814.07347 | F11: 2.8362241
B12: 14 | C12: 887.6703 | D12: 2.5060618 | E12: 805.59454 | F12: 2.9007945
B13: 15 | C13: 880.96005 | D13: 2.538965 | E13: 796.78462 | F13: 2.9722614
B14: 16 | C14: 874.08072 | D14: 2.5745095 | E14: 787.60812 | F14: 3.0516728
B15: 17 | C15: 867.01896 | D15: 2.6130386 | E15: 778.02387 | F15: 3.1403325
B16: 18 | C16: 859.75969 | D16: 2.654948 | E16: 767.98363 | F16: 3.2399169
B17: 19 | C17: 852.28583 | D17: 2.7006935 | E17: 757.43018 | F17: 3.3526514
B18: 20 | C18: 844.57798 | D18: 2.7508014 | E18: 746.29432 | F18: 3.4815633
B19: 21 | C19: 836.61401 | D19: 2.8058812 | E19: 734.49067 | F19: 3.6308295
... B48: 50 | C48: 293.16097 | D48: 3.8812279 | E48: 252.03251 | F48: 2.7015141
B49: Kennwert | C49: rein | E49: Gemisch
B50: pseudokritisch (cp-Max.) [°C] | C50: 40.5 | E50: 32.8
B51: ρ = 500 kg/m³ bei T [°C] | C51: 40.231549 | E51: 32.049765
B52: Fett: 26 °C (Kühler vor der Pumpe) und 40 °C (Zwischenkühler). Graue Werte: CoolProp, gerechnet in 05_kuehlung_begruendung.py.
B54: 2) Wahl des Zwischendrucks (Zwischenkühler 40 °C, Stufe 1 ab 30 bar / 15 °C, Stufe 2 bis 91 bar)
C55: reines CO₂ | H55: Worst-Case-Gemisch
B56: p_zw [bar] | C56: T Stufe 1 aus [°C] | D56: T Stufe 2 aus [°C] | E56: Z Eintritt Stufe 2 | F56: w Verdichter [kJ/kg] | H56: T Stufe 1 aus [°C] | I56: T Stufe 2 aus [°C] | J56: Z Eintritt Stufe 2 | K56: w Verdichter [kJ/kg] | M56: beide Stufen ≤ T_max? | N56: Z ≥ 0,7 (rein und Gemisch)?
B57: 45 | C57: 48.071179 | D57: 103.74032 | E57: 0.77825363 | F57: 64.902498 | H57: 48.386986 | I57: 104.38389 | J57: 0.79656389 | K57: 67.90234 | M57: =IF(MAX(C57:D57,H57:I57)<=T_maxV,"✔ ja","✘ nein") | N57: =IF(MIN(E57,J57)>=Z_lit,"✔ ja","✘ nein")
B58: 50 | C58: 57.10272 | D58: 93.414852 | E58: 0.74756944 | F58: 62.756562 | H58: 57.499984 | I58: 94.005279 | J58: 0.76957371 | K58: 65.823678 | M58: =IF(MAX(C58:D58,H58:I58)<=T_maxV,"✔ ja","✘ nein") | N58: =IF(MIN(E58,J58)>=Z_lit,"✔ ja","✘ nein")
B59: 55 | C59: 65.427615 | D59: 84.142709 | E59: 0.71481144 | F59: 61.316191 | H59: 65.899089 | I59: 84.713427 | J59: 0.74124743 | K59: 64.45601 | M59: =IF(MAX(C59:D59,H59:I59)<=T_maxV,"✔ ja","✘ nein") | N59: =IF(MIN(E59,J59)>=Z_lit,"✔ ja","✘ nein")
B60: 60 | C60: 73.155392 | D60: 75.748058 | E60: 0.67946731 | F60: 60.460437 | H60: 73.69577 | I60: 76.330109 | J60: 0.71136843 | K60: 63.674712 | M60: =IF(MAX(C60:D60,H60:I60)<=T_maxV,"✔ ja","✘ nein") | N60: =IF(MIN(E60,J60)>=Z_lit,"✔ ja","✘ nein")
B62: Literaturrichtwert Z (Q-017 S. 37 / S. 44): | E62: 0.7 | F62: – darf zum Vergleich geändert werden (Hersteller: 0,65)
B63: Gewählt 55 bar (fett): höchster runder Druck, der beide Prüfungen besteht. Mit 50 bar läge Stufe 2 bei 93–94 °C (knapp unter 95 °C), mit 60 bar wäre Z beim reinen CO₂ unter 0,7.
B65: 3) Temperatur nach dem Zwischenkühler (Zwischendruck 55 bar)
C66: reines CO₂ | H66: Worst-Case-Gemisch
B67: T_ZK [°C] | C67: Z Eintritt Stufe 2 | D67: T Stufe 2 aus [°C] | E67: w Verdichter [kJ/kg] | F67: q Zwischenkühler [kJ/kg] | H67: Z Eintritt Stufe 2 | I67: T Stufe 2 aus [°C] | J67: w Verdichter [kJ/kg] | K67: q Zwischenkühler [kJ/kg] | M67: Z > Z_min (0,65)? | N67: Z ≥ 0,7?
B68: 20 | C68: 0.57427492 | D68: 58.857774 | E68: 54.57624 | F68: 78.618299 | H68: 0.63246323 | I68: 60.543161 | J68: 58.657087 | K68: 71.367547 | M68: =IF(MIN(C68,H68)>Z_min,"✔ ja","✘ nein") | N68: =IF(MIN(C68,H68)>=Z_lit,"✔ ja","✘ nein")
B69: 26 | C69: 0.63233981 | D69: 67.103832 | E69: 57.103436 | F69: 62.595805 | H69: 0.67380298 | I69: 68.111687 | J69: 60.661946 | K69: 58.912804 | M69: =IF(MIN(C69,H69)>Z_min,"✔ ja","✘ nein") | N69: =IF(MIN(C69,H69)>=Z_lit,"✔ ja","✘ nein")
B70: 30 | C70: 0.66082293 | D70: 72.157429 | E70: 58.459114 | F70: 54.112918 | H70: 0.69623463 | I70: 72.962263 | J70: 61.840601 | K70: 51.619086 | M70: =IF(MIN(C70,H70)>Z_min,"✔ ja","✘ nein") | N70: =IF(MIN(C70,H70)>=Z_lit,"✔ ja","✘ nein")
B71: 35 | C71: 0.6901789 | D71: 78.233296 | E71: 59.959395 | F71: 44.756595 | H71: 0.72037303 | I71: 78.89034 | J71: 63.19659 | K71: 43.225813 | M71: =IF(MIN(C71,H71)>Z_min,"✔ ja","✘ nein") | N71: =IF(MIN(C71,H71)>=Z_lit,"✔ ja","✘ nein")
B72: 40 | C72: 0.71481144 | D72: 84.142709 | E72: 61.316191 | F72: 36.291982 | H72: 0.74124743 | I72: 84.713427 | J72: 64.45601 | K72: 35.410349 | M72: =IF(MIN(C72,H72)>Z_min,"✔ ja","✘ nein") | N72: =IF(MIN(C72,H72)>=Z_lit,"✔ ja","✘ nein")
...

Sheet Massenströme
B1: Massenströme – ein Massenstrom, viele Volumenströme
B2: Besprechung K. Vosbeck 15.10.2026, Pkt. 4 · Rechnung: Einspeicherung/Begleitstoffe_CO2/Prozesskette/06_massenstrom_volumenstroeme.py
B3: ← zur Übersicht
B4: GRUNDSATZ: Die Volumenströme der verschiedenen Phasen dürfen nicht gleichgesetzt werden – verknüpft wird über einen Massenstrom, der entlang der ganzen Kette gleich bleibt (keine Abzweigung, kein Speicher). RECHENWEG: ṁ = V_n · ρ_n / 3600 mit dem Normvolumenstrom V_n (0 °C, 1,01325 bar, DIN 1343). An jedem Zustandspunkt ist der tatsächliche Volumenstrom V̇ = ṁ / ρ(p, T) · 3600 in m³/h. FOLGE: Bei gleichem ṁ fördert Verdichter 1 rund 10-mal so viel Volumen wie die Pumpe (2.941 gegenüber 293 m³/h bei 100.000 Nm³/h). Maschinen und Rohre werden am Zustand ausgelegt, nicht am Normvolumenstrom (Nm³/h ≠ m³/h).
B6: 1) Massenstrom aus dem Normvolumenstrom
B7: Größe | C7: unterer Fall | D7: oberer Fall | E7: Einheit
B8: Normvolumenstrom V_n | C8: =V_min | D8: =V_max | E8: Nm³/h
B9: Normdichte ρ_n (CoolProp, DIN 1343) | C9: =rho_n | D9: =rho_n | E9: kg/m³
B10: Massenstrom ṁ = V_n · ρ_n / 3600 | C10: =Szen1_mmin | D10: =Szen1_mmax | E10: kg/s
B11: Massenstrom | C11: =C10*3.6 | D11: =D10*3.6 | E11: t/h
B12: Massenstrom | C12: =C10*86.4 | D12: =D10*86.4 | E12: t/d
B15: 2) Volumenströme an den Zustandspunkten – Worst-Case-Gemisch (diese Mappe; ṁ aus Tabelle 1)
B16: Zustandspunkt | C16: p [bar] | D16: T [°C] | E16: ρ [kg/m³] | F16: Phase | G16: V̇ bei 50.000 Nm³/h [m³/h] | H16: V̇ bei 100.000 Nm³/h [m³/h] | I16: Vielfaches des Pumpeneintritts
B17: S2 – gasförmige Anlieferung
B18: Netzübergabe S2 = Verdichter 1 ein | C18: 30 | D18: 15 | E18: 65.761928 | F18: gasförmig | G18: =$C$10/E18*3600 | H18: =$D$10/E18*3600 | I18: =H18/$H$22
B19: Verdichter 1 aus | C19: 55 | D19: 65.899089 | E19: 102.75644 | F19: gasförmig | G19: =$C$10/E19*3600 | H19: =$D$10/E19*3600 | I19: =H19/$H$22
B20: Zwischenkühler aus = Verdichter 2 ein | C20: 55 | D20: 40 | E20: 122.76791 | F20: gasförmig | G20: =$C$10/E20*3600 | H20: =$D$10/E20*3600 | I20: =H20/$H$22
B21: Verdichter 2 aus | C21: 91 | D21: 84.713427 | E21: 175.05614 | F21: gasförmig | G21: =$C$10/E21*3600 | H21: =$D$10/E21*3600 | I21: =H21/$H$22
B22: Kühler aus = Pumpe ein | C22: 91 | D22: 26 | E22: 660.42105 | F22: dicht (flüssig) | G22: =$C$10/E22*3600 | H22: =$D$10/E22*3600 | I22: =H22/$H$22
B23: Pumpe aus = Bohrlochkopf | C23: 127.2718 | D23: 34.406495 | E23: 691.97463 | F23: dicht (flüssig) | G23: =$C$10/E23*3600 | H23: =$D$10/E23*3600 | I23: =H23/$H$22
B24: LCCS (Kaverne voll) | C24: 210 | D24: 48.115197 | E24: 744.04801 | F24: dicht (flüssig) | G24: =$C$10/E24*3600 | H24: =$D$10/E24*3600 | I24: =H24/$H$22
B25: S1 – dichte Anlieferung
B26: Netzübergabe S1 | C26: 91 | D26: 15 | E26: 796.78462 | F26: dicht (flüssig) | G26: =$C$10/E26*3600 | H26: =$D$10/E26*3600 | I26: =H26/$H$22
B27: Pumpe aus = Bohrlochkopf | C27: 114.2738 | D27: 18.305735 | E27: 807.33708 | F27: dicht (flüssig) | G27: =$C$10/E27*3600 | H27: =$D$10/E27*3600 | I27: =H27/$H$22
B28: LCCS (Kaverne voll) | C28: 210 | D28: 28.789554 | E28: 846.41705 | F28: dicht (flüssig) | G28: =$C$10/E28*3600 | H28: =$D$10/E28*3600 | I28: =H28/$H$22
B31: 3) Zum Vergleich: reines CO₂ (eigener Massenstrom, da andere Normdichte)
B32: Zustandspunkt | C32: p [bar] | D32: T [°C] | E32: ρ [kg/m³] | F32: Phase | G32: V̇ bei 50.000 Nm³/h [m³/h] | H32: V̇ bei 100.000 Nm³/h [m³/h] | I32: Vielfaches des Pumpeneintritts | K32: ṁ unten [kg/s] | L32: ṁ oben [kg/s]
B33: S2 – gasförmige Anlieferung | K33: 27.455733 | L33: 54.911465
B34: Netzübergabe S2 = Verdichter 1 ein | C34: 30 | D34: 15 | E34: 68.444351 | F34: gasförmig | G34: =$K$33/E34*3600 | H34: =$L$33/E34*3600 | I34: =H34/$H$38
B35: Verdichter 1 aus | C35: 55 | D35: 65.427615 | E35: 107.40888 | F35: überkritisch (gasähnlich) | G35: =$K$33/E35*3600 | H35: =$L$33/E35*3600 | I35: =H35/$H$38
B36: Zwischenkühler aus = Verdichter 2 ein | C36: 55 | D36: 40 | E36: 130.05634 | F36: überkritisch (gasähnlich) | G36: =$K$33/E36*3600 | H36: =$L$33/E36*3600 | I36: =H36/$H$38
B37: Verdichter 2 aus | C37: 91 | D37: 84.142709 | E37: 186.0123 | F37: überkritisch | G37: =$K$33/E37*3600 | H37: =$L$33/E37*3600 | I37: =H37/$H$38
B38: Kühler aus = Pumpe ein | C38: 91 | D38: 26 | E38: 791.91673 | F38: dicht (überkritisch) | G38: =$K$33/E38*3600 | H38: =$L$33/E38*3600 | I38: =H38/$H$38
B39: Pumpe aus = Bohrlochkopf | C39: 114.63416 | D39: 29.589764 | E39: 803.64153 | F39: dicht (überkritisch) | G39: =$K$33/E39*3600 | H39: =$L$33/E39*3600 | I39: =H39/$H$38
B40: LCCS (Kaverne voll) | C40: 210 | D40: 40.718353 | E40: 845.15671 | F40: überkritisch | G40: =$K$33/E40*3600 | H40: =$L$33/E40*3600 | I40: =H40/$H$38
B41: S1 – dichte Anlieferung
B42: Netzübergabe S1 | C42: 91 | D42: 15 | E42: 880.96005 | F42: dicht (überkritisch) | G42: =$K$33/E42*3600 | H42: =$L$33/E42*3600 | I42: =H42/$H$38
B43: Pumpe aus = Bohrlochkopf | C43: 105.4411 | D43: 16.571862 | E43: 885.38971 | F43: dicht (überkritisch) | G43: =$K$33/E43*3600 | H43: =$L$33/E43*3600 | I43: =H43/$H$38
B44: LCCS (Kaverne voll) | C44: 210 | D44: 25.574241 | E44: 917.9393 | F44: dicht (überkritisch) | G44: =$K$33/E44*3600 | H44: =$L$33/E44*3600 | I44: =H44/$H$38
B45: Graue Zustandswerte aus 06_massenstrom_volumenstroeme.py (Betrieb bei 100.000 Nm³/h: Kopfdruck und LCCS-Temperatur aus der strömenden Säule). V̇ und Vielfaches rechnen live mit dem Massenstrom.
...

Sheet Phasendiagramm
B1: Phasendiagramm – Prozesspfade der Einspeicherung und Betriebsfenster von Bohrloch und Kaverne (Worst-Case-Gemisch)
B2: Worst-Case-Gemisch (95 % CO₂ + 5 % Begleitstoffe) · Stoffdaten CoolProp (GERG-2008-Mischungsregel) · Fest-Gebiet, Sublimations- und Schmelzlinie: Näherung reines CO₂ (Span & Wagner 1996)
B3: ← zur Übersicht
B4: Diagramm 1 – Einspeicherung: von der Netzübergabe bis zum Bohrlochkopf
B36: DIAGRAMM 1: Farbflächen = Phasengebiete des Gemischs, rot = Zweiphasengebiet (reines CO₂ hat nur eine Linie, grau zum Vergleich). Rot gestrichelt = ±3 bar Unsicherheit der Phasengrenze. Grün = S1 (Pumpe). Blau = S2 (2 Verdichterstufen bis 91 bar mit Zwischenkühler 40 °C, Kühler bei 91 bar auf 26 °C, Pumpe) – der Kühler liegt über der Cricondenbar und kreuzt kein Zweiphasengebiet. Violett gestrichelt = Vergleich Durchverdichten (2 Stufen bis 127,3 bar). Orange gepunktet = Dichte 500 kg/m³: rechts davon ist das Gemisch zu dünn für eine Pumpe. ENDPUNKT: Die Pfade enden am Bohrlochkopf im Betrieb (100.000 Nm³/h): S1 bei 114,3 bar, S2 und Durchverdichten bei 127,3 bar – das wärmere CO₂ aus der S2-Pumpe (34,4 °C) macht die Säule leichter. Im Stillstand wären es 114,9 bar. Diagramm 2 zeigt Bohrloch und Kaverne – nur im Stillstand.
B39: Diagramm 2 – Bohrloch und Kaverne im Stillstand: Betriebsfenster (nur Stillstand, 3 Füllstände nach Q-028)
B40: NUR STILLSTAND: Die Gassäulen gelten für ruhendes CO₂ mit Gebirgstemperatur und für die drei Füllstände nach Q-028 (Buzogany & Kruck 2022, Fig. 3: voll, Grenzfall, leer). Was Injektion und Ausspeicherung für das Fenster bedeuten (Reibungsdruckverlust im Strang, Wärmeaustausch mit dem Gebirge, Erwärmung bzw. Abkühlung in der Kaverne, Drosselung beim Ausspeichern), ist hier NICHT dargestellt.
B72: DIAGRAMM 2: Jede gestrichelte Linie ist eine Gassäule – ein Füllstand der Kaverne im Stillstand. Sie läuft vom Bohrlochkopf (grauer Balken, 0 m, 10 °C) bis zur Kaverne (dunkelblauer Balken, 1200 m, 46 °C). Jeder Punkt auf der Linie ist eine Teufe: oben kalt und niedriger Druck, unten warm und hoher Druck. BETRIEBSFENSTER IM STILLSTAND: Der Bereich zwischen der Linie „voll“ (oben) und der Linie „leer“ (unten), links begrenzt durch den Kopf-Balken und rechts durch den Kavernen-Balken. WICHTIG BEI LEERER KAVERNE: 70 bar unten ergeben oben 50,7 bar (reines CO₂: 45,0 bar). Das obere Bohrloch (0–82 m) liegt dann im Zweiphasengebiet des Gemischs. Erst ab ca. 171,2 bar Kavernendruck (Grenzfall: Kopf = Cricondenbar 82,2 bar) bleibt das ganze Bohrloch einphasig. KAVERNE SELBST: Bei 46 °C liegt sie immer über der Cricondentherm des Gemischs (28,1 °C) – dort gibt es keine Flüssigphase. Über 81,5 bar ist das Gemisch überkritisch, bei 70 bar gasförmig. STILLSTAND VS. BETRIEB: Die Gassäulen sind mit Gebirgstemperatur gerechnet (Kopf 10 °C) und gelten nur, solange nichts fließt. Beim Einspeichern kommt das Gemisch wärmer aus der Pumpe (S1 18,3 °C, S2 34,4 °C) – Zieldrücke im Betrieb: Blatt „Kaverne & Gassäule“ unten; Kopfdruckfenster über den ganzen Zyklus: Kaverne-Mappe.

Sheet Annahmen & Begründung
B1: Annahmen & Begründung – woher jede Zahl kommt
B2: Stand 15.10.2026 (nach der Besprechung mit K. Vosbeck) · Worst-Case-Gemisch · gleiche Annahmen wie im Python-Code (Einspeicherung/Begleitstoffe_CO2/Grundlagen/einspeicherung_bausteine.py, Kaverne/Grundlagen/kaverne_bausteine.py)
B3: ← zur Übersicht
B4: SO IST DIE TABELLE AUFGEBAUT: Jede Annahme mit Wert, Quelle (ID wie in der Quellen- und Wissensmatrix, Blatt „Quellen“) und Fundstelle (Seite S., Folie, Tabelle oder Kapitel) – damit jede Zahl nachgelesen werden kann. „Begründung“ sagt, was in der Quelle steht und warum der Wert so gewählt ist. „Code“ nennt die Konstante im Python-Code mit demselben Wert. WERTE: weiß = verknüpft mit der Übersicht (ändert sich mit), grau = fester Wert im Code. Geändert wird nur auf der Übersicht. STATUS: ✔ belegt = steht so in der Quelle · ◐ abgeleitet = aus Quellen hergeleitet · ○ eigene Annahme · ? = noch zu klären (Quelle offen bzw. mit Hersteller bestätigen, Messe Hamburg 20.–22.10.2026).
B6: Nr. | C6: Größe | D6: Symbol | E6: Wert | F6: Einheit | G6: Quelle | H6: Fundstelle | I6: Inhalt der Quelle / Begründung | J6: Code | K6: Status
B7: A Anlieferung (Netzübergabe)
B8: 1 | C8: Übergabedruck S1 (dicht) | D8: p_S1 | E8: =p_S1 | F8: bar | G8: OGE | H8: Notizen 16.09.2026, Pkt. 6 | I8: mind. 91 bar (vorher 85 bar), Worst Case mit Begleitstoffen. Beim Gemisch 8,8 bar über der Cricondenbar (82,2 bar) → dichte, einphasige Übergabe. | J8: eb.p_S1 | K8: ✔ belegt
B9: 2 | C9: Übergabetemperatur S1 | D9: T_S1 | E9: =T_S1 | F9: °C | G9: eigene Annahme | H9: – | I9: Medientemperatur der erdverlegten Fernleitung (nicht Gebirgstemperatur) – mit OGE abzustimmen. | J9: eb.T_S1 | K9: ○ eigene Annahme
B10: 3 | C10: Übergabedruck S2 (gasförmig) | D10: p_S2 | E10: =p_S2 | F10: bar | G10: Vorarbeit | H10: – | I10: aus der eigenen Vorarbeit; alte Annahmentabelle nennt ISO 27913 (Q-040) – dort noch nicht ausgewertet. | J10: eb.p_S2 | K10: ? Quelle offen
B11: 4 | C11: Übergabetemperatur S2 | D11: T_S2 | E11: =T_S2 | F11: °C | G11: eigene Annahme | H11: – | I11: Medientemperatur wie S1. | J11: eb.T_S2 | K11: ○ eigene Annahme
B12: B Verdichtung S2 (2 Stufen 30 → 55 → 91 bar)
B13: 5 | C13: Zwischendruck | D13: p_zw | E13: =p_zw | F13: bar | G13: eigene Herleitung (Q-017, Q-016) | H13: Blatt „Kühlung“, Tabelle 2 | I13: höchster runder Zwischendruck, bei dem am Eintritt Stufe 2 (40 °C) Z ≥ 0,7 für reines CO₂ UND Gemisch gilt (rein 0,715, Gemisch 0,741). Beide Stufen bleiben dann unter 95 °C (Stufe 2: rein 84,1 °C, Gemisch 84,7 °C). Mit 50 bar läge Stufe 2 bei 93–94 °C, mit 60 bar wäre Z beim reinen CO₂ < 0,7. | J13: eb.P_ZW | K13: ◐ abgeleitet
B14: 6 | C14: Druck nach Verdichtung = Kühldruck = Pumpeneintritt | D14: p_ük | E14: =p_uek | F14: bar | G14: eigene Festlegung | H14: Blatt „Gemisch & Grenzen“ | I14: über der Cricondenbar des Gemischs (82,2 bar) + 3 bar Unsicherheit bzw. über p_krit (73,8 bar): der Kühler kreuzt kein Zweiphasengebiet. = Übergabedruck S1 → eine Pumpenbauart für S1 und S2. | J14: eb.P_UEK | K14: ◐ abgeleitet
B15: 7 | C15: Höchste Austrittstemperatur je Stufe | D15: T_max | E15: =T_maxV | F15: °C | G15: Q-016 | H15: S. 4, Kap. 2.3 (dort Lit. [24]) | I15: „… might not be higher than the assumed value of 95 °C“ – legt die Zahl der Stufen fest. | J15: eb.T_MAX_STUFE | K15: ✔ belegt
B16: 8 | C16: Isentroper Wirkungsgrad Stufe 1 | D16: η_V1 | E16: =eta_V1 | F16: – | G16: Q-016 | H16: S. 4, Kap. 2.3 | I16: „efficiency of compressors … for the first stage is 84 %“ | J16: eb.eta_V1 | K16: ✔ belegt
B17: 9 | C17: Isentroper Wirkungsgrad Stufe 2 | D17: η_V2 | E17: =eta_V2 | F17: – | G17: Q-016 | H17: S. 4, Kap. 2.3 | I17: „… for subsequent stages, it is successively reduced by 2 %“ → 82 % | J17: eb.eta_V2 | K17: ✔ belegt
B18: 10 | C18: Realgasfaktor am Stufeneintritt mindestens (Hersteller) | D18: Z_min | E18: =Z_min | F18: – | G18: Siemens Energy | H18: E-Mail-Auskunft 08/2026 | I18: „Damit die Berechnung der Laufräder in unseren Berechnungsprogrammen zuverlässig ausgeführt wird, bleiben wir bei einem Z-Wert von > 0,65.“ Gilt nur für Verdichter, nicht für die Pumpe. | J18: eb.Z_MIN | K18: ✔ persönliche Mitteilung
B19: 11 | C19: Realgasfaktor Literaturrichtwert | D19: Z | E19: 0.7 | F19: – | G19: Q-017 | H19: S. 37 (Tab. 3: Z_min 0,7); S. 44 | I19: „Als Grenzwert des Z-Faktors wird durch verschiedenste Hersteller 0,7 angegeben.“ Bei kleinerem Z steigen die Grenzschichtverluste (S. 44). Grundlage für den Zwischendruck. | J19: eb.Z_Q017 | K19: ✔ belegt
B20: C Kühlung – zwei Kühler, zwei Zwecke
B21: 12 | C21: CO₂ nach dem Zwischenkühler | D21: T_ZK | E21: =T_ZK | F21: °C | G21: Q-017; Q-063 | H21: Q-017 S. 37 (Tab. 3), S. 61; Q-063 Kap. 5.1 (PDF-S. 22) | I21: Q-017: „Soll-Kühltemperatur CO₂ 40 °C“ (Auslegung Kingsnorth), S. 61 Siemens-Konzept „Eingangstemperatur 40 °C“. Q-063: CO₂ „no more than about 40 °C. Cooling is therefore required between and after compressor stages“. Zweck: Verdichterarbeit senken, Stufe 2 < 95 °C. Kälter ist nicht besser: Z sinkt (Q-017 S. 44) – bei 26 °C wäre Z = 0,63 (rein) < 0,65. | J21: eb.T_ZK | K21: ✔ belegt
