Workbook
Name Diagramm_dT: Diagrammdaten!$C$5
Name Diagramm_Tmin: Diagrammdaten!$C$4
Name eta: Übersicht!$F$67
Name eta_V1: Übersicht!$F$65
Name eta_V2: Übersicht!$F$66
Name grad_V1: Übersicht!$F$55
Name Kopf_grenz: 'Kaverne & Gassäule'!$D$19
Name Kopf_leer: 'Kaverne & Gassäule'!$D$20
Name Kopf_voll: 'Kaverne & Gassäule'!$D$18
Name MV_Kopf_CH4: Medienvergleich!$D$11
Name MV_Kopf_CO2: Medienvergleich!$C$11
Name MV_Kopf_H2: Medienvergleich!$E$11
Name p_grenz: 'Kaverne & Gassäule'!$C$19
Name p_S1: Übersicht!$F$43
Name p_S2: Übersicht!$F$46
Name p_zw: Übersicht!$F$51
Name pmax_V1: Übersicht!$F$56
Name pmin_V1: Übersicht!$F$57
Name rho_n: 'Einspeicherung S1'!$E$19
Name rhoSalz_V1: Übersicht!$F$58
Name Stand_ok: Übersicht!$Q$39
Name Szen1_eta: 'Einspeicherung S1'!$E$14
Name Szen1_h1: 'Einspeicherung S1'!$E$10
Name Szen1_h2: 'Einspeicherung S1'!$E$15
Name Szen1_h2s: 'Einspeicherung S1'!$E$13
Name Szen1_mmax: 'Einspeicherung S1'!$E$21
Name Szen1_mmin: 'Einspeicherung S1'!$E$20
Name Szen1_p1: 'Einspeicherung S1'!$E$8
Name Szen1_p2: 'Einspeicherung S1'!$E$12
Name Szen1_Pmax: 'Einspeicherung S1'!$E$23
Name Szen1_Pmin: 'Einspeicherung S1'!$E$22
Name Szen1_s1: 'Einspeicherung S1'!$E$11
Name Szen1_T1: 'Einspeicherung S1'!$E$9
Name Szen1_T2: 'Einspeicherung S1'!$E$16
Name Szen1_w: 'Einspeicherung S1'!$E$18
Name T_maxV: Übersicht!$F$49
Name T_S1: Übersicht!$F$44
Name T_S2: Übersicht!$F$47
Name Tober_V1: Übersicht!$F$54
Name V_max: Übersicht!$F$64
Name V_min: Übersicht!$F$63
Name z_V1: Übersicht!$F$53
Name p_lith_V1: Übersicht!$F$73
Name T_Kav_V1: Übersicht!$F$72
Name Z_min: Übersicht!$F$68
Name rho_min: Übersicht!$F$69
Name T_ZK: Übersicht!$F$48
Name p_uek: Übersicht!$F$50
Name T_KW: Übersicht!$F$60
Name T_K: Übersicht!$F$61
Name Kopf_betr_S1: 'Kaverne & Gassäule'!$D$85
Name Kopf_betr_S2: 'Kaverne & Gassäule'!$D$87
Name Szen2_h1: 'Einspeicherung S2'!$E$11
Name Szen2_h1s: 'Einspeicherung S2'!$E$14
Name Szen2_h1a: 'Einspeicherung S2'!$E$15
Name Szen2_T1a: 'Einspeicherung S2'!$E$16
Name Szen2_w1: 'Einspeicherung S2'!$E$18
Name Szen2_hZK: 'Einspeicherung S2'!$E$21
Name Szen2_qZK: 'Einspeicherung S2'!$E$22
Name Szen2_Z2: 'Einspeicherung S2'!$E$23

Sheet Übersicht
B1: CO₂-Zwischenspeicherung in Salzkavernen – Obertageanlage
B2: Rechenübersicht Einspeicherung · Masterarbeit Sarah Maxara · TH Köln / Uniper Energy Storage
B3: Stand: 15.10.2026 (nach der Besprechung mit K. Vosbeck) · Stoffdaten: CoolProp 8.0.0, Referenz-Zustandsgleichung Span & Wagner (1996), reines CO₂ · Gemisch: eigene Mappe
B5: Worum geht es? | J5: Farblegende der Zellen
B6: Diese Mappe zeigt Schritt für Schritt, wie die Obertageanlage für die Einspeicherung berechnet wird: 1. Welcher Druck muss am Bohrlochkopf anliegen? → das gibt die Kaverne über die Gassäule vor. 2. Wie bringt die Anlage das CO₂ auf diesen Druck? → Pumpe (dichte Anlieferung, S1) bzw. zwei Verdichterstufen, Kühler und Pumpe (gasförmige Anlieferung, S2). 3. Wo liegen alle Zustände im Phasendiagramm – und wo liegt das Betriebsfenster von Bohrloch und Kaverne? Basisfall ist reines CO₂. Begleitstoffe folgen als eigener Schritt. | J6: 91 | K6: Annahme – darf geändert werden
J7: 231.2 | K7: Stoffwert aus CoolProp – fest
J8: 64.4 | K8: Excel-Formel – rechnet sofort mit
J9: 107.6 | K9: wichtiges Ergebnis
J10: rot | K10: Stoffwert passt nicht mehr zu den Annahmen
B12: Inhalt
B13: → Kaverne & Gassäule | E13: Welchen Kopfdruck gibt die Kaverne vor? Stillstand für drei Füllstände (wie Q-028, Fig. 3) und – neu – im Betrieb: strömende Säule beim Einspeisen (Zieldruck der Pumpe).
B14: → Medienvergleich | E14: Warum braucht CO₂ oben weniger Druck als Erdgas oder Wasserstoff?
B15: → Einspeicherung S1 | E15: Anlieferung dicht: Pumpe – jeder Rechenschritt einzeln.
B16: → Einspeicherung S2 | E16: Anlieferung gasförmig: 2 Verdichterstufen (Zwischenkühler 40 °C), Kühler bei 91 bar auf 26 °C, Pumpe – mit Begründung des Wegs.
B17: → Phasendiagramm | E17: Diagramm 1: Prozesspfade bis zum Bohrlochkopf. Diagramm 2: Betriebsfenster von Bohrloch und Kaverne (nur Stillstand).
B18: → Quellen | E18: Herkunft aller Annahmen und Stoffdaten.
B19: → Diagrammdaten | E19: Hilfstabellen für die Diagramme (nicht ändern).
B21: Prozesskette Einspeicherung – Szenarien
B35: Neu (15.10.2026): | D35: → Annahmen & Begründung | G35: → Kühlung | I35: → Massenströme
B36: Annahmen mit Quelle und Fundstelle (Seite, Folie, Tabelle) · warum Zwischenkühler 40 °C und Kühler vor der Pumpe 26 °C · ein Massenstrom, viele Volumenströme
B37: Szenarien & Annahmen
B38: Blaue Werte dürfen geändert werden. Weiße Formelwerte rechnen sofort mit. Graue Stoffwerte (CoolProp) kann Excel nicht selbst berechnen – ändert sich eine Annahme, zeigt der Status, welche Werte neu berechnet werden müssen.
B39: Status | E39: =IF(Stand_ok,"✔ Alle grauen Stoffwerte passen zu den Annahmen.","⚠ Mindestens eine Annahme wurde geändert – rot markierte Stoffwerte sind veraltet und müssen neu berechnet werden.") | Q39: =COUNTIF($N$42:$N$69,"⚠*")=0
B41: Größe | E41: Symbol | F41: Wert | G41: Einheit | H41: Quelle / Begründung | M41: gerechnet mit | N41: Status
B42: Anlieferszenario S1 – dichte Phase (Pipeline OGE)
B43: Übergabedruck | E43: p_S1 | F43: 91 | G43: bar | H43: OGE-Notizen 16.09.2026, Pkt. 6: mind. 91 bar (vorher 85 bar), Worst Case mit Begleitstoffen | M43: 91 | N43: =IF(ABS(F43-M43)<0.000000001,"✔ passt","⚠ geändert – neu rechnen")
B44: Übergabetemperatur | E44: T_S1 | F44: 15 | G44: °C | H44: Annahme: Medientemperatur der Fernleitung (nicht Gebirgstemperatur) | M44: 15 | N44: =IF(ABS(F44-M44)<0.000000001,"✔ passt","⚠ geändert – neu rechnen")
B45: Anlieferszenario S2 – gasförmig
B46: Übergabedruck | E46: p_S2 | F46: 30 | G46: bar | H46: Annahme aus Vorarbeit; alte Tabelle nennt Q-040 (ISO 27913) – dort noch nicht ausgewertet, zu prüfen | M46: 30 | N46: =IF(ABS(F46-M46)<0.000000001,"✔ passt","⚠ geändert – neu rechnen")
B47: Übergabetemperatur | E47: T_S2 | F47: 15 | G47: °C | H47: Annahme: Medientemperatur | M47: 15 | N47: =IF(ABS(F47-M47)<0.000000001,"✔ passt","⚠ geändert – neu rechnen")
B48: CO₂-Temperatur nach dem Zwischenkühler (S2) | E48: T_ZK | F48: 40 | G48: °C | H48: Q-017 S. 37 (Tab. 3): Soll-Kühltemperatur CO₂ 40 °C; Q-063 Kap. 5.1: CO₂ „no more than about 40 °C“, Kühlung zwischen den Stufen – Begründung: Blatt „Kühlung“ | M48: 40 | N48: =IF(ABS(F48-M48)<0.000000001,"✔ passt","⚠ geändert – neu rechnen")
B49: Max. Austrittstemperatur je Verdichterstufe | E49: T_max | F49: 95 | G49: °C | H49: Q-016 S. 4 (Kap. 2.3, dort Lit. [24]): höchstens 95 °C nach jeder Stufe → legt die Zahl der Stufen fest | M49: 95 | N49: =IF(ABS(F49-M49)<0.000000001,"✔ passt","⚠ geändert – neu rechnen")
B50: Druck nach Verdichtung = Kühldruck (S2) | E50: p_ük | F50: 91 | G50: bar | H50: über p_krit (73,8 bar) → Kühler ohne Phasenwechsel (überkritisch kühlen, Pfad B wie beim Gemisch); = Übergabedruck S1 (gleicher Pumpeneintritt) | M50: 91 | N50: =IF(ABS(F50-M50)<0.000000001,"✔ passt","⚠ geändert – neu rechnen")
B51: Zwischendruck (S2) | E51: p_zw | F51: 55 | G51: bar | H51: eigene Herleitung (Blatt „Kühlung“): höchster runder Druck mit Z ≥ 0,7 (Q-017 S. 44) am Eintritt Stufe 2 bei 40 °C für rein und Gemisch; beide Stufen < 95 °C | M51: 55 | N51: =IF(ABS(F51-M51)<0.000000001,"✔ passt","⚠ geändert – neu rechnen")
B52: Kaverne V1 – tief (Referenzkaverne; flache Kaverne entfällt)
B53: Teufe (LCCS) | E53: z | F53: 1200 | G53: m | H53: Q-030 Tab. 1, Option 2; abgestimmt mit M. Wall (Uniper). Flache Kaverne entfällt: Q-030 S. 17 (DBI: fast sofort Flüssigphase in Kaverne bzw. am Kopf), Besprechung K. Vosbeck 15.10.2026 | M53: 1200 | N53: =IF(ABS(F53-M53)<0.000000001,"✔ passt","⚠ geändert – neu rechnen")
B54: Gebirgstemperatur an der Oberfläche | E54: T₀ | F54: 10 | G54: °C | H54: Q-028 Kap. 3 (S. 5), Fig. 3: 10 °C an der Oberfläche | M54: 10 | N54: =IF(ABS(F54-M54)<0.000000001,"✔ passt","⚠ geändert – neu rechnen")
B55: Geothermischer Gradient | E55: grad T | F55: 0.03 | G55: K/m | H55: Q-028 Kap. 3 (S. 5), Fig. 3: 0,03 K/m | M55: 0.03 | N55: =IF(ABS(F55-M55)<0.000000001,"✔ passt","⚠ geändert – neu rechnen")
B56: Maximaldruck an der LCCS | E56: p_max | F56: 210 | G56: bar | H56: Zwischenwert aus Q-028 Tab. 1 (200 bar) und Q-030 Tab. 1, Opt. 2 (240 bar); Vorgabe M. Wall | M56: 210 | N56: =IF(ABS(F56-M56)<0.000000001,"✔ passt","⚠ geändert – neu rechnen")
B57: Minimaldruck an der LCCS | E57: p_min | F57: 70 | G57: bar | H57: Q-028 Tab. 1: geomechanisches Minimum | M57: 70 | N57: =IF(ABS(F57-M57)<0.000000001,"✔ passt","⚠ geändert – neu rechnen")
...

Sheet Kaverne & Gassäule
B1: Kaverne & Gassäule – welcher Druck muss am Bohrlochkopf anliegen?
B2: Einspeicherung, Kaverne V1 (tief) · Stillstand: Temperatur = Gebirgstemperatur
B3: ← zur Übersicht
B4: WAS WIRD BERECHNET? Die Kaverne legt fest, welcher Druck unten an der LCCS (letzte zementierte Rohrtour) höchstens anliegen darf: 210 bar. Gesucht ist der Druck, den die Anlage dafür oben am Bohrlochkopf liefern muss. WARUM? Zwischen Kopf und Kaverne steht eine 1200 m hohe CO₂-Säule. Ihr Gewicht erhöht den Druck nach unten: dp/dz = ρ(p,T) · g. WIE WIRD GERECHNET? Die Dichte ρ hängt selbst von Druck und Temperatur ab – deshalb wird die Säule in 600 Schritten à 2 m gerechnet, in jedem Schritt mit neuer Dichte aus CoolProp. Temperatur = Gebirgstemperatur T(z) = T₀ + grad T · z (Stillstand). Gerechnet wird von unten (bekannter Kavernendruck) nach oben – das Ergebnis ist direkt der Kopfdruck. GRENZFALL: Mit dem Sekantenverfahren (schrittweises Annähern) wird der Kavernendruck gesucht, bei dem der Kopfdruck genau p_krit = 73,8 bar ist. Darüber bleibt das ganze Bohrloch dicht, darunter kann das CO₂ im oberen Bohrloch verdampfen. ERGEBNIS: Für 210 bar unten reichen 107,6 bar am Kopf – die Säule liefert rund 102 bar. Das ist der Zieldruck für Pumpe bzw. Verdichter. IM BETRIEB (NEU): Beim Einspeisen strömt das CO₂ mit der Temperatur nach der Pumpe nach unten – Abschnitt unten. Zieldruck der Pumpe bei 100.000 Nm³/h: S1 105,4 bar, S2 114,6 bar (Stillstand 107,6 bar).
B6: Kavernenparameter
B7: Größe | C7: Kaverne V1 (tief) | D7: Kaverne V2 (flach): entfällt | E7: Einheit
B8: Teufe (LCCS) | C8: =z_V1 | E8: m
B9: Gebirgstemperatur Oberfläche | C9: =Tober_V1 | E9: °C
B10: Geothermischer Gradient | C10: =grad_V1 | E10: K/m
B11: Kavernentemperatur | C11: =T_Kav_V1 | E11: °C
B12: Maximaldruck an der LCCS | C12: =pmax_V1 | E12: bar
B13: Minimaldruck an der LCCS | C13: =pmin_V1 | E13: bar
B14: Werte kommen von der Übersicht. Die flache Kaverne entfällt (Q-030 S. 17: DBI verwirft sie selbst; Besprechung K. Vosbeck 15.10.2026).
B16: Ergebnis: drei Füllstände der Kaverne
B17: Fall | C17: Druck unten (LCCS) [bar] | D17: Kopfdruck [bar] | E17: T am Kopf [°C] | F17: ρ Kopf [kg/m³] | G17: ρ unten [kg/m³] | H17: Säulengewinn [bar] | I17: Bedeutung
B18: voll (p_max) | C18: 210 | D18: 107.60322 | E18: 10 | F18: 926.32204 | G18: 817.60427 | H18: =C18-D18 | I18: Zieldruck für die Einspeicherung
B19: Grenzfall | C19: 171.65228 | D19: 73.772984 | E19: 10 | F19: 897.02184 | G19: 771.2552 | H19: =C19-D19 | I19: Kopfdruck = p_krit: ab hier ist das Bohrloch ganz dicht
B20: leer (p_min) | C20: 70 | D20: 44.992994 | E20: 10 | F20: 134.97287 | G20: 180.73732 | H20: =C20-D20 | I20: Kopf = Dampfdruck bei 10 °C → Mehrphasengebiet 0–236 m
B22: Diagramme – Darstellung nach Buzogany & Kruck (2022), Fig. 3 (dort 1150 m Teufe, hier Kaverne V1 mit 1200 m)
B23: HIER ZUM STILLSTAND: Die Gassäulen gelten für ruhendes CO₂ mit Gebirgstemperatur und für die drei Füllstände nach Q-028 (Buzogany & Kruck 2022, Fig. 3: voll, Grenzfall, leer). Was Injektion und Ausspeicherung für das Fenster bedeuten (Reibungsdruckverlust im Strang, Wärmeaustausch mit dem Gebirge, Erwärmung bzw. Abkühlung in der Kaverne, Drosselung beim Ausspeichern), ist hier NICHT dargestellt.
B47: Tiefenprofile (gerechnet in 2-m-Schritten, dargestellt alle 50 m)
B48: Teufe z [m] | C48: T [°C] | D48: p voll [bar] | E48: ρ voll [kg/m³] | F48: p Grenzfall [bar] | G48: ρ Grenzfall [kg/m³] | H48: p leer [bar] | I48: ρ leer [kg/m³]
B49: 0 | C49: 10 | D49: 107.60322 | E49: 926.32204 | F49: 73.772984 | G49: 897.02184 | H49: 44.992994 | I49: 134.97287
B50: 50 | C50: 11.5 | D50: 112.13418 | E50: 921.36649 | F50: 78.158267 | G50: 891.29696 | H50: 46.658027
B51: 100 | C51: 13 | D51: 116.6409 | E51: 916.43579 | F51: 82.515515 | G51: 885.59013 | H51: 48.469674
B52: 150 | C52: 14.5 | D52: 121.12349 | E52: 911.53193 | F52: 86.844824 | G52: 879.9048 | H52: 50.287387
B53: 200 | C53: 16 | D53: 125.58211 | E53: 906.65681 | F53: 91.146309 | G53: 874.24443 | H53: 52.113012
B54: 250 | C54: 17.5 | D54: 130.01689 | E54: 901.81229 | F54: 95.420101 | G54: 868.61242 | H54: 53.576396 | I54: 172.35313
B55: 300 | C55: 19 | D55: 134.428 | E55: 897.00015 | F55: 99.666347 | G55: 863.01213 | H55: 54.422451 | I55: 172.62152
B56: 350 | C56: 20.5 | D56: 138.81558 | E56: 892.22209 | F56: 103.88521 | G56: 857.44688 | H56: 55.269946 | I56: 172.93614
B57: 400 | C57: 22 | D57: 143.17982 | E57: 887.47971 | F57: 108.07688 | G57: 851.91995 | H57: 56.119079 | I57: 173.28715
B58: 450 | C58: 23.5 | D58: 147.52089 | E58: 882.77457 | F58: 112.24153 | G58: 846.43458 | H58: 56.970012 | I58: 173.66732
B59: 500 | C59: 25 | D59: 151.83898 | E59: 878.10816 | F59: 116.3794 | G59: 840.99405 | H59: 57.822871 | I59: 174.07112
B60: 550 | C60: 26.5 | D60: 156.13429 | E60: 873.48191 | F60: 120.4907 | G60: 835.60164 | H60: 58.677762 | I60: 174.49423
B61: 600 | C61: 28 | D61: 160.407 | E61: 868.89724 | F61: 124.57568 | G61: 830.26066 | H61: 59.53477 | I61: 174.93315
B62: 650 | C62: 29.5 | D62: 164.65734 | E62: 864.35556 | F62: 128.63461 | G62: 824.97441 | H62: 60.393965 | I62: 175.38502
B63: 700 | C63: 31 | D63: 168.88552 | E63: 859.85825 | F63: 132.66775 | G63: 819.74615 | H63: 61.255404 | I63: 175.84746
B64: 750 | C64: 32.5 | D64: 173.09175 | E64: 855.40667 | F64: 136.6754 | G64: 814.5791 | H64: 62.119134 | I64: 176.31849
B65: 800 | C65: 34 | D65: 177.27627 | E65: 851.00219 | F65: 140.65786 | G65: 809.47631 | H65: 62.985193 | I65: 176.79644
... B73: 1200 | C73: 46 | D73: 210 | E73: 817.60427 | F73: 171.65228 | G73: 771.2552 | H73: 70 | I73: 180.73732
...

Sheet Medienvergleich
B1: Medienvergleich – warum CO₂ oben weniger Druck braucht
B2: Gleiche Kaverne (Ziel 210 bar unten, Gebirge 10 °C + 0,03 K/m), gleiche Rechnung – nur das Medium ist anders
B3: ← zur Übersicht
B4: IDEE: Je schwerer die Säule im Bohrloch, desto mehr Druck liefert sie und desto weniger muss die Anlage oben aufbringen. CO₂ ist unter diesen Bedingungen dicht (700–930 kg/m³), Erdgas und Wasserstoff bleiben Gase (Erdgas ~150 kg/m³, Wasserstoff ~15 kg/m³). FOLGE: Für CO₂ reicht eine Pumpe auf ~108 bar. Erdgas- und Wasserstoffspeicher brauchen Verdichter fast bis zum vollen Kavernendruck. Rechnung wie auf Blatt „Kaverne & Gassäule“: dp/dz = ρ(p,T) · g, von unten nach oben, Dichte aus CoolProp (Methan als Erdgas-Ersatz, reiner Wasserstoff). Der Zieldruck unten bleibt für alle Teufen bewusst bei 210 bar, damit nur der Effekt der Säule sichtbar wird.
B6: 1) Nötiger Kopfdruck über der Teufe (210 bar unten)
B7: Teufe [m] | C7: CO₂ [bar] | D7: Erdgas CH₄ [bar] | E7: Wasserstoff H₂ [bar] | F7: Ziel unten [bar]
B8: 600 | C8: 155.16617 | D8: 200.16601 | E8: 209.09501 | F8: =pmax_V1
B9: 800 | C9: 138.41709 | D9: 197.20927 | E9: 208.805 | F9: =pmax_V1
B10: 1000 | C10: 122.53672 | D10: 194.39268 | E10: 208.52047 | F10: =pmax_V1
B11: 1200 | C11: 107.60322 | D11: 191.70534 | E11: 208.24119 | F11: =pmax_V1
B12: 1400 | C12: 93.705839 | D12: 189.13736 | E12: 207.96699 | F12: =pmax_V1
B13: 1600 | C13: 80.943841 | D13: 186.67971 | E13: 207.69769 | F13: =pmax_V1
B14: CO₂: 74 bar weniger Kopfdruck zwischen 600 und 1600 m – Erdgas und Wasserstoff profitieren kaum von der Teufe.
B16: 2) Kennzahlen bei 1200 m Teufe
B17: Medium | C17: Kopfdruck [bar] | D17: Säulengewinn [bar] | E17: ρ Kopf [kg/m³] | F17: ρ unten [kg/m³] | G17: Übertagetechnik
B18: CO₂ | C18: 107.60322 | D18: =pmax_V1-C18 | E18: 926.32204 | F18: 817.60427 | G18: Pumpe (91 → 108 bar)
B19: Erdgas (CH₄) | C19: 191.70534 | D19: =pmax_V1-C19 | E19: 167.47194 | F19: 145.17947 | G19: Verdichter bis ~192 bar
B20: Wasserstoff (H₂) | C20: 208.24119 | D20: =pmax_V1-C20 | E20: 15.728831 | F20: 14.210688 | G20: Verdichter bis ~208 bar
B21: Bei Erdgas und Wasserstoff ist die Dichte unten kleiner als oben: der Temperaturanstieg überwiegt den Druckanstieg.
B23: 3) Druck- und Dichteprofile über die Teufe (Kaverne V1, 1200 m – gerechnet in 2-m-Schritten, dargestellt alle 50 m)
B24: Teufe z [m] | C24: p CO₂ [bar] | D24: ρ CO₂ [kg/m³] | E24: p CH₄ [bar] | F24: ρ CH₄ [kg/m³] | G24: p H₂ [bar] | H24: ρ H₂ [kg/m³]
B25: 0 | C25: 107.60322 | D25: 926.32204 | E25: 191.70534 | F25: 167.47194 | G25: 208.24119 | H25: 15.728831
B26: 50 | C26: 112.13418 | D26: 921.36649 | E26: 192.5238 | F26: 166.30248 | G26: 208.31816 | H26: 15.658526
B27: 100 | C27: 116.6409 | D27: 916.43579 | E27: 193.33659 | F27: 165.15879 | G27: 208.39479 | H27: 15.588903
B28: 150 | C28: 121.12349 | D28: 911.53193 | E28: 194.14383 | F28: 164.0401 | G28: 208.47108 | H28: 15.519951
B29: 200 | C29: 125.58211 | D29: 906.65681 | E29: 194.94564 | F29: 162.94567 | G29: 208.54703 | H29: 15.451659
B30: 250 | C30: 130.01689 | D30: 901.81229 | E30: 195.74215 | F30: 161.87476 | G30: 208.62264 | H30: 15.384018
B31: 300 | C31: 134.428 | D31: 897.00015 | E31: 196.53346 | F31: 160.82667 | G31: 208.69793 | H31: 15.317018
B32: 350 | C32: 138.81558 | D32: 892.22209 | E32: 197.31969 | F32: 159.80073 | G32: 208.77289 | H32: 15.25065
B33: 400 | C33: 143.17982 | D33: 887.47971 | E33: 198.10094 | F33: 158.79625 | G33: 208.84753 | H33: 15.184904
B34: 450 | C34: 147.52089 | D34: 882.77457 | E34: 198.87732 | F34: 157.81261 | G34: 208.92184 | H34: 15.119771
B35: 500 | C35: 151.83898 | D35: 878.10816 | E35: 199.64893 | F35: 156.84918 | G35: 208.99584 | H35: 15.055243
B36: 550 | C36: 156.13429 | D36: 873.48191 | E36: 200.41586 | F36: 155.90536 | G36: 209.06952 | H36: 14.99131
... B49: 1200 | C49: 210 | D49: 817.60427 | E49: 210 | F49: 145.17947 | G49: 210 | H49: 14.210688
B50: Gleiche Rechnung wie auf Blatt „Kaverne & Gassäule“ (Fall voll): von 210 bar unten nach oben integriert, Gebirge 10 °C + 0,03 K/m.

Sheet Einspeicherung S1
B1: Einspeicherung S1 – Anlieferung in dichter Phase: Pumpe
B2: Netzübergabe → Messtechnik/Filtration → Pumpe → Bohrlochkopf
B3: ← zur Übersicht
B4: AUSGANGSLAGE: Das CO₂ kommt dicht (flüssigkeitsähnlich) aus der Fernleitung: 91 bar, 15 °C. ZIEL: 105,4 bar am Bohrlochkopf im Betrieb (100.000 Nm³/h) – strömende Säule, Blatt „Kaverne & Gassäule“, Abschnitt Betrieb. Im Stillstand wären es 107,6 bar: das kalte CO₂ aus der Pumpe (16,6 °C statt Gebirgstemperatur) macht die Säule schwerer, die Reibung (1,6 bar) kostet etwas zurück. WARUM EINE PUMPE? Das CO₂ ist bereits dicht und kaum kompressibel. Eine Pumpe genügt, ein Verdichter wäre nur für Gas nötig. RECHENWEG: (1) Zustand am Eintritt → Enthalpie h₁, Entropie s₁. (2) Idealfall: isentrope Druckerhöhung (Entropie bleibt gleich) → h₂s. (3) Realfall mit Verlusten über den isentropen Wirkungsgrad: h₂ = h₁ + (h₂s − h₁) / η. (4) Aus p₂ und h₂ → Austrittstemperatur T₂. (5) Spezifische Arbeit w = h₂ − h₁, Leistung P = ṁ · w. BEGRIFF: isentrop = Entropie konstant (Pumpe, Verdichter). Nicht verwechseln mit isenthalp = Enthalpie konstant (Drossel bei der Ausspeicherung). ANNAHMEN: η = 0,80 (eigene Annahme – Q-016 S. 4 nennt nur eine Glykolpumpe mit 70 %; Herstellerwert einholen); kein Druckverlust in Messtechnik und Filtration; reines CO₂.
B6: Rechenschritte
B7: Nr. | C7: Rechenschritt | D7: Formel / Funktion | E7: Wert | F7: Einheit | G7: Art des Werts
B8: 1 | C8: Eintrittsdruck | D8: = Übergabedruck S1 | E8: =p_S1 | F8: bar | G8: aus anderem Blatt
B9: 2 | C9: Eintrittstemperatur | D9: = Übergabetemperatur S1 | E9: =T_S1 | F9: °C | G9: aus anderem Blatt
B10: 3 | C10: Enthalpie Eintritt h₁ | D10: CoolProp: H(p₁, T₁) | E10: 231.18824 | F10: kJ/kg | G10: CoolProp (fest)
B11: 4 | C11: Entropie Eintritt s₁ | D11: CoolProp: S(p₁, T₁) | E11: 1.089033 | F11: kJ/(kg·K) | G11: CoolProp (fest)
B12: 5 | C12: Austrittsdruck p₂ (= Zieldruck im Betrieb) | D12: Kaverne & Gassäule: Betrieb, V_n,max | E12: =Kopf_betr_S1 | F12: bar | G12: aus anderem Blatt
B13: 6 | C13: Enthalpie isentrop h₂s | D13: CoolProp: H(p₂, s = s₁) | E13: 232.82235 | F13: kJ/kg | G13: CoolProp (fest)
B14: 7 | C14: Isentroper Wirkungsgrad η | D14: Annahme (Übersicht) | E14: =eta | F14: – | G14: aus anderem Blatt
B15: 8 | C15: Enthalpie real h₂ | D15: h₂ = h₁ + (h₂s − h₁) / η | E15: =Szen1_h1+(Szen1_h2s-Szen1_h1)/eta | F15: kJ/kg | G15: Excel-Formel
B16: 9 | C16: Austrittstemperatur T₂ | D16: CoolProp: T(p₂, h₂) | E16: 16.571862 | F16: °C | G16: CoolProp (fest)
B17: 10 | C17: Phase am Austritt | D17: CoolProp: Phase(p₂, h₂) | E17: dicht (flüssig) | F17: – | G17: CoolProp (fest)
B18: 11 | C18: Spezifische Arbeit w | D18: w = h₂ − h₁ | E18: =Szen1_h2-Szen1_h1 | F18: kJ/kg | G18: Ergebnis (Formel)
B19: 12 | C19: Normdichte CO₂ (0 °C; 1,01325 bar) | D19: CoolProp: D(p_n, T_n), DIN 1343 | E19: 1.9768127 | F19: kg/m³ | G19: CoolProp (fest)
B20: 13 | C20: Massenstrom, unterer Fall | D20: ṁ = V_n,min · ρ_n / 3600 | E20: =V_min*rho_n/3600 | F20: kg/s | G20: Excel-Formel
B21: 14 | C21: Massenstrom, oberer Fall | D21: ṁ = V_n,max · ρ_n / 3600 | E21: =V_max*rho_n/3600 | F21: kg/s | G21: Excel-Formel
B22: 15 | C22: Pumpenleistung, unterer Fall | D22: P = ṁ · w | E22: =Szen1_mmin*Szen1_w | F22: kW | G22: Ergebnis (Formel)
B23: 16 | C23: Pumpenleistung, oberer Fall | D23: P = ṁ · w | E23: =Szen1_mmax*Szen1_w | F23: kW | G23: Ergebnis (Formel)
B24: Wird η auf der Übersicht geändert, rechnen h₂, w und P sofort mit. T₂ kommt aus CoolProp und färbt sich dann rot (veraltet).
B26: Zustandspunkte
C27: Punkt | D27: p [bar] | E27: T [°C] | F27: h [kJ/kg] | G27: Phase
C28: Netzübergabe / Pumpe ein | D28: 91 | E28: 15 | F28: 231.18824 | G28: dicht (flüssig) | I28: Die Pumpe hebt den Druck von 91 auf 105,4 bar; die Temperatur steigt nur um 1,6 K. Der ganze Weg liegt über p_krit (73,8 bar) – das CO₂ bleibt dicht. Gesamtbild: Blatt „Phasendiagramm“.
C29: Pumpe aus / Bohrlochkopf | D29: =Szen1_p2 | E29: =Szen1_T2 | F29: =Szen1_h2 | G29: dicht (flüssig)

Sheet Einspeicherung S2
B1: Einspeicherung S2 – gasförmige Anlieferung: verdichten, kühlen, pumpen
B2: Netzübergabe → Messtechnik/Filtration → Verdichter 1 → Zwischenkühler (40 °C) → Verdichter 2 → Kühler (91 bar, 26 °C) → Pumpe → Bohrlochkopf
B3: ← zur Übersicht
B4: AUSGANGSLAGE: Das CO₂ kommt gasförmig an: 30 bar, 15 °C. Ziel: 114,6 bar am Bohrlochkopf im Betrieb (100.000 Nm³/h; Stillstand 107,6 bar – Blatt „Kaverne & Gassäule“). WEG: Zwei Verdichterstufen 30 → 55 → 91 bar mit Zwischenkühler auf 40 °C; 91 bar liegt über der p_krit (73,8 bar). Der Kühler vor der Pumpe kühlt bei 91 bar auf 26 °C – das CO₂ wird stetig dichter, ohne ein Zweiphasengebiet zu berühren (keine Kondensation, kein Verflüssiger). Die Pumpe saugt einphasig dichtes CO₂ an (792 kg/m³) – bei demselben Druck wie in S1. ZWEI KÜHLER, ZWEI ZWECKE: Zwischenkühler senkt die Verdichterarbeit und hält Stufe 2 unter 95 °C → 40 °C (Q-017 S. 37; Q-063 Kap. 5.1). Kühler vor der Pumpe so kalt wie das Kühlwasser erlaubt, weit weg von der pseudokritischen Linie (40,5 °C bei 91 bar) → 26 °C = Kühlwasser 20 °C + 6 K (Q-120 Folie 24/32). Herleitung: Blatt „Kühlung“. ANNAHMEN (Übersicht): Zwischendruck 55 bar (Z ≥ 0,7, Q-017 S. 44) · höchstens 95 °C je Stufe (Q-016 S. 4) · Z > 0,65 am Verdichtereintritt (Siemens Energy) · ρ ≥ 500 kg/m³ an der Pumpe (Q-121 S. 2) · Wirkungsgrade 84 / 82 % (Q-016 S. 4), Pumpe 80 % (eigene Annahme). Quellen mit Fundstelle: Blatt „Annahmen & Begründung“. RECHENWEG: wie in S1 – Verdichter und Pumpe isentrop + Wirkungsgrad: h_aus = h_ein + (h_s − h_ein) / η. Kühler: abgeführte Wärme q = h_vor − h_nach. Grau = CoolProp-Wert (fest), weiß = Excel-Formel, grün = Ergebnis.
B6: Rechenschritte
B7: Nr. | C7: Rechenschritt | D7: Formel / Funktion | E7: Wert | F7: Einheit | G7: Art des Werts
B8: Verdichter 1. Stufe
B9: 1 | C9: Eintrittsdruck | D9: = Übergabe S2 | E9: =p_S2 | F9: bar | G9: aus anderem Blatt
B10: 2 | C10: Eintrittstemperatur | D10: = Übergabe S2 | E10: =T_S2 | F10: °C | G10: aus anderem Blatt
B11: 3 | C11: Enthalpie Eintritt | D11: CoolProp: H(p_ein, T_ein) | E11: 462.33879 | F11: kJ/kg | G11: CoolProp (fest)
B12: 4 | C12: Zwischendruck | D12: Annahme (Übersicht), Blatt „Kühlung“ | E12: =p_zw | F12: bar | G12: aus anderem Blatt
B13: 5 | C13: Wirkungsgrad η_V1 | D13: Annahme (Übersicht), Q-016 S. 4 | E13: =eta_V1 | F13: – | G13: aus anderem Blatt
B14: 6 | C14: Enthalpie isentrop | D14: CoolProp: H(p_zw, s_ein) | E14: 490.69526 | F14: kJ/kg | G14: CoolProp (fest)
B15: 7 | C15: Enthalpie real Austritt | D15: h = h_ein + (h_s − h_ein) / η_V1 | E15: =Szen2_h1+(Szen2_h1s-Szen2_h1)/eta_V1 | F15: kJ/kg | G15: Excel-Formel
B16: 8 | C16: Austrittstemperatur | D16: CoolProp: T(p_zw, h) | E16: 65.427615 | F16: °C | G16: CoolProp (fest)
B17: 9 | C17: Prüfung 95-°C-Grenze (Q-016 S. 4) | D17: T_aus ≤ T_max ? | E17: =IF(Szen2_T1a<=T_maxV,"✔ eingehalten","⚠ überschritten") | F17: – | G17: Excel-Formel
B18: 10 | C18: Spezifische Arbeit Stufe 1 | D18: w₁ = h_aus − h_ein | E18: =Szen2_h1a-Szen2_h1 | F18: kJ/kg | G18: Ergebnis (Formel)
B19: Zwischenkühler (auf T_ZK = 40 °C)
B20: 11 | C20: Prüfung: bleibt gasförmig? | D20: T_ZK > T_krit (31,0 °C) ? | E20: =IF(T_ZK>30.978,"✔ gasförmig ("&FIXED(T_ZK-30.978,1)&" K über T_krit)","⚠ unter T_krit – Dampfdruck prüfen") | F20: – | G20: Excel-Formel
B21: 12 | C21: Enthalpie nach Zwischenkühler | D21: CoolProp: H(p_zw, T_ZK) | E21: 459.80451 | F21: kJ/kg | G21: CoolProp (fest)
B22: 13 | C22: Abgeführte Wärme | D22: q = h_vor − h_nach | E22: =Szen2_h1a-Szen2_hZK | F22: kJ/kg | G22: Excel-Formel
B23: 14 | C23: Realgasfaktor Eintritt Stufe 2 | D23: CoolProp: Z(p_zw, T_ZK) | E23: 0.71481144 | F23: – | G23: CoolProp (fest)
B24: 15 | C24: Prüfung Realgasfaktor (Siemens 0,65; Q-017: 0,7) | D24: Z > Z_min ? | E24: =IF(Szen2_Z2>=0.7,"✔ eingehalten (auch ≥ 0,7 nach Q-017)",IF(Szen2_Z2>Z_min,"✔ über "&FIXED(Z_min,2)&", unter 0,7 (Q-017)","⚠ nicht über "&FIXED(Z_min,2))) | F24: – | G24: Excel-Formel
B25: Verdichter 2. Stufe
B26: 16 | C26: Wirkungsgrad η_V2 | D26: Annahme (Übersicht), Q-016 S. 4 | E26: =eta_V2 | F26: – | G26: aus anderem Blatt
B27: 17 | C27: Austrittsdruck | D27: Annahme (Übersicht) | E27: =p_uek | F27: bar | G27: aus anderem Blatt
B28: 18 | C28: Enthalpie isentrop | D28: CoolProp: H(p_ük, s(p_zw, T_ZK)) | E28: 482.40247 | F28: kJ/kg | G28: CoolProp (fest)
B29: 19 | C29: Enthalpie real Austritt | D29: h = h_ein + (h_s − h_ein) / η_V2 | E29: =Szen2_hZK+(Szen2_h2s-Szen2_hZK)/eta_V2 | F29: kJ/kg | G29: Excel-Formel
B30: 20 | C30: Austrittstemperatur | D30: CoolProp: T(p_ük, h) | E30: 84.142709 | F30: °C | G30: CoolProp (fest)
B31: 21 | C31: Prüfung 95-°C-Grenze (Q-016 S. 4) | D31: T_aus ≤ T_max ? | E31: =IF(Szen2_T2a<=T_maxV,"✔ eingehalten","⚠ überschritten") | F31: – | G31: Excel-Formel
B32: 22 | C32: Spezifische Arbeit Stufe 2 | D32: w₂ = h_aus − h_ein | E32: =Szen2_h2a-Szen2_hZK | F32: kJ/kg | G32: Ergebnis (Formel)
B33: Kühler vor der Pumpe bei 91 bar (überkritischer Druck – kein Phasenwechsel)
B34: 23 | C34: Prüfung: über der Phasengrenze? | D34: p_ük ≥ p_krit (73,8 bar) + 3 bar ? | E34: =IF(p_uek>=73.773+3,"✔ "&FIXED(p_uek-73.773,1)&" bar über p_krit – keine Phasengrenze","⚠ Kühler kreuzt die Sättigungslinie") | F34: – | G34: Excel-Formel
B35: 24 | C35: Enthalpie nach Kühler | D35: CoolProp: H(p_ük, T_K) | E35: 262.04716 | F35: kJ/kg | G35: CoolProp (fest)
B36: 25 | C36: Dichte nach Kühler = Pumpeneintritt | D36: CoolProp: D(p_ük, T_K) | E36: 791.91673 | F36: kg/m³ | G36: CoolProp (fest)
B37: 26 | C37: Prüfung Dichte (Q-121 S. 2) | D37: ρ ≥ ρ_min ? | E37: =IF(Szen2_rhoP>=rho_min,"✔ pumpbar (≥ "&TEXT(rho_min,"0")&" kg/m³)","⚠ zu dünn für eine Pumpe") | F37: – | G37: Excel-Formel
B38: 27 | C38: Abgeführte Wärme | D38: q = h_vor − h_nach | E38: =Szen2_h2a-Szen2_hK | F38: kJ/kg | G38: Excel-Formel
B39: Pumpe
B40: 28 | C40: Austrittsdruck (= Zieldruck im Betrieb) | D40: Kaverne & Gassäule: Betrieb, V_n,max | E40: =Kopf_betr_S2 | F40: bar | G40: aus anderem Blatt
B41: 29 | C41: Wirkungsgrad η_P | D41: Annahme (Übersicht) | E41: =eta | F41: – | G41: aus anderem Blatt
...

Sheet Kühlung
B1: Kühlung – Zwischenkühler 40 °C, Kühler vor der Pumpe 26 °C, Zwischendruck 55 bar
B2: Besprechung K. Vosbeck 15.10.2026, Pkt. 2 · Rechnung: Einspeicherung/Begleitstoffe_CO2/Prozesskette/05_kuehlung_begruendung.py · reines CO₂ und Worst-Case-Gemisch nebeneinander
B3: ← zur Übersicht
B4: ZWEI KÜHLER – ZWEI ZWECKE: Der Zwischenkühler (zwischen den Verdichterstufen, 55 bar) soll die Verdichterarbeit senken und die zweite Stufe unter 95 °C halten. Der Kühler vor der Pumpe (91 bar) soll das CO₂ so dicht wie möglich machen, damit die Pumpe einphasig und mit wenig Förderhöhe arbeitet. Deshalb zwei verschiedene Temperaturen. ZWISCHENKÜHLER 40 °C: Q-017 S. 37 (Tab. 3): „Soll-Kühltemperatur CO₂ 40 °C“, S. 61 (Siemens-Konzept, Eingangstemperatur 40 °C); Q-063 Kap. 5.1 (PDF-S. 22): CO₂ „no more than about 40 °C“, Kühlung „between and after compressor stages“. Kälter ist nicht besser: der Realgasfaktor sinkt (Tabelle 3) – bei 26 °C wäre Z beim reinen CO₂ 0,63 und damit unter 0,65 (Siemens). KÜHLER VOR DER PUMPE 26 °C: Kühlwasser 20 °C + 6 K (Q-120 Folie 24: CO₂ „seldom lower than 6 deg. C warmer than the air or water“). Q-120 Folie 32: für Pumpen auf 27–32 °C oder kälter kühlen, über 38 °C steigt die Förderhöhe stark. Bei 91 bar liegt die pseudokritische Linie (cp-Maximum, steilster Dichteabfall) beim Gemisch bei 32,8 °C, beim reinen CO₂ bei 40,5 °C (Tabelle 1) – 26 °C liegt sicher auf der dichten Seite. ZWISCHENDRUCK 55 bar: höchster runder Druck, bei dem am Eintritt Stufe 2 (40 °C) Z ≥ 0,7 (Q-017 S. 44) für beide Gasqualitäten gilt; beide Stufen bleiben dann unter 95 °C (Tabelle 2). MIT HERSTELLERN ABSTIMMEN (Messe Hamburg 20.–22.10.2026): Kühlwassertemperatur am Standort, erreichbare Grädigkeit, Z-Grenze der Laufradauslegung, Pumpenwirkungsgrad und Mindest-Saugdichte.
B6: 1) Dichte und Wärmekapazität bei 91 bar (Druck des Kühlers vor der Pumpe)
B7: T [°C] | C7: ρ rein [kg/m³] | D7: cp rein [kJ/(kg·K)] | E7: ρ Gemisch [kg/m³] | F7: cp Gemisch [kJ/(kg·K)]
B8: 10 | C8: 913.03975 | D8: 2.3954881 | E8: 837.81476 | F8: 2.6758407
B9: 11 | C9: 906.89906 | D9: 2.4204225 | E9: 830.15819 | F9: 2.7244325
B10: 12 | C10: 900.62977 | D10: 2.4470302 | E10: 822.25234 | F10: 2.7776822
B11: 13 | C11: 894.22335 | D11: 2.4755026 | E11: 814.07347 | F11: 2.8362241
B12: 14 | C12: 887.6703 | D12: 2.5060618 | E12: 805.59454 | F12: 2.9007945
B13: 15 | C13: 880.96005 | D13: 2.538965 | E13: 796.78462 | F13: 2.9722614
B14: 16 | C14: 874.08072 | D14: 2.5745095 | E14: 787.60812 | F14: 3.0516728
B15: 17 | C15: 867.01896 | D15: 2.6130386 | E15: 778.02387 | F15: 3.1403325
B16: 18 | C16: 859.75969 | D16: 2.654948 | E16: 767.98363 | F16: 3.2399169
B17: 19 | C17: 852.28583 | D17: 2.7006935 | E17: 757.43018 | F17: 3.3526514
B18: 20 | C18: 844.57798 | D18: 2.7508014 | E18: 746.29432 | F18: 3.4815633
B19: 21 | C19: 836.61401 | D19: 2.8058812 | E19: 734.49067 | F19: 3.6308295
... B48: 50 | C48: 293.16097 | D48: 3.8812279 | E48: 252.03251 | F48: 2.7015141
B49: Kennwert | C49: rein | E49: Gemisch
B50: pseudokritisch (cp-Max.) [°C] | C50: 40.5 | E50: 32.8
B51: ρ = 500 kg/m³ bei T [°C] | C51: 40.231549 | E51: 32.049765
B52: Fett: 26 °C (Kühler vor der Pumpe) und 40 °C (Zwischenkühler). Graue Werte: CoolProp, gerechnet in 05_kuehlung_begruendung.py.
B54: 2) Wahl des Zwischendrucks (Zwischenkühler 40 °C, Stufe 1 ab 30 bar / 15 °C, Stufe 2 bis 91 bar)
C55: reines CO₂ | H55: Worst-Case-Gemisch
B56: p_zw [bar] | C56: T Stufe 1 aus [°C] | D56: T Stufe 2 aus [°C] | E56: Z Eintritt Stufe 2 | F56: w Verdichter [kJ/kg] | H56: T Stufe 1 aus [°C] | I56: T Stufe 2 aus [°C] | J56: Z Eintritt Stufe 2 | K56: w Verdichter [kJ/kg] | M56: beide Stufen ≤ T_max? | N56: Z ≥ 0,7 (rein und Gemisch)?
B57: 45 | C57: 48.071179 | D57: 103.74032 | E57: 0.77825363 | F57: 64.902498 | H57: 48.386986 | I57: 104.38389 | J57: 0.79656389 | K57: 67.90234 | M57: =IF(MAX(C57:D57,H57:I57)<=T_maxV,"✔ ja","✘ nein") | N57: =IF(MIN(E57,J57)>=Z_lit,"✔ ja","✘ nein")
B58: 50 | C58: 57.10272 | D58: 93.414852 | E58: 0.74756944 | F58: 62.756562 | H58: 57.499984 | I58: 94.005279 | J58: 0.76957371 | K58: 65.823678 | M58: =IF(MAX(C58:D58,H58:I58)<=T_maxV,"✔ ja","✘ nein") | N58: =IF(MIN(E58,J58)>=Z_lit,"✔ ja","✘ nein")
B59: 55 | C59: 65.427615 | D59: 84.142709 | E59: 0.71481144 | F59: 61.316191 | H59: 65.899089 | I59: 84.713427 | J59: 0.74124743 | K59: 64.45601 | M59: =IF(MAX(C59:D59,H59:I59)<=T_maxV,"✔ ja","✘ nein") | N59: =IF(MIN(E59,J59)>=Z_lit,"✔ ja","✘ nein")
B60: 60 | C60: 73.155392 | D60: 75.748058 | E60: 0.67946731 | F60: 60.460437 | H60: 73.69577 | I60: 76.330109 | J60: 0.71136843 | K60: 63.674712 | M60: =IF(MAX(C60:D60,H60:I60)<=T_maxV,"✔ ja","✘ nein") | N60: =IF(MIN(E60,J60)>=Z_lit,"✔ ja","✘ nein")
B62: Literaturrichtwert Z (Q-017 S. 37 / S. 44): | E62: 0.7 | F62: – darf zum Vergleich geändert werden (Hersteller: 0,65)
B63: Gewählt 55 bar (fett): höchster runder Druck, der beide Prüfungen besteht. Mit 50 bar läge Stufe 2 bei 93–94 °C (knapp unter 95 °C), mit 60 bar wäre Z beim reinen CO₂ unter 0,7.
B65: 3) Temperatur nach dem Zwischenkühler (Zwischendruck 55 bar)
C66: reines CO₂ | H66: Worst-Case-Gemisch
B67: T_ZK [°C] | C67: Z Eintritt Stufe 2 | D67: T Stufe 2 aus [°C] | E67: w Verdichter [kJ/kg] | F67: q Zwischenkühler [kJ/kg] | H67: Z Eintritt Stufe 2 | I67: T Stufe 2 aus [°C] | J67: w Verdichter [kJ/kg] | K67: q Zwischenkühler [kJ/kg] | M67: Z > Z_min (0,65)? | N67: Z ≥ 0,7?
B68: 20 | C68: 0.57427492 | D68: 58.857774 | E68: 54.57624 | F68: 78.618299 | H68: 0.63246323 | I68: 60.543161 | J68: 58.657087 | K68: 71.367547 | M68: =IF(MIN(C68,H68)>Z_min,"✔ ja","✘ nein") | N68: =IF(MIN(C68,H68)>=Z_lit,"✔ ja","✘ nein")
B69: 26 | C69: 0.63233981 | D69: 67.103832 | E69: 57.103436 | F69: 62.595805 | H69: 0.67380298 | I69: 68.111687 | J69: 60.661946 | K69: 58.912804 | M69: =IF(MIN(C69,H69)>Z_min,"✔ ja","✘ nein") | N69: =IF(MIN(C69,H69)>=Z_lit,"✔ ja","✘ nein")
B70: 30 | C70: 0.66082293 | D70: 72.157429 | E70: 58.459114 | F70: 54.112918 | H70: 0.69623463 | I70: 72.962263 | J70: 61.840601 | K70: 51.619086 | M70: =IF(MIN(C70,H70)>Z_min,"✔ ja","✘ nein") | N70: =IF(MIN(C70,H70)>=Z_lit,"✔ ja","✘ nein")
B71: 35 | C71: 0.6901789 | D71: 78.233296 | E71: 59.959395 | F71: 44.756595 | H71: 0.72037303 | I71: 78.89034 | J71: 63.19659 | K71: 43.225813 | M71: =IF(MIN(C71,H71)>Z_min,"✔ ja","✘ nein") | N71: =IF(MIN(C71,H71)>=Z_lit,"✔ ja","✘ nein")
B72: 40 | C72: 0.71481144 | D72: 84.142709 | E72: 61.316191 | F72: 36.291982 | H72: 0.74124743 | I72: 84.713427 | J72: 64.45601 | K72: 35.410349 | M72: =IF(MIN(C72,H72)>Z_min,"✔ ja","✘ nein") | N72: =IF(MIN(C72,H72)>=Z_lit,"✔ ja","✘ nein")
...

Sheet Massenströme
B1: Massenströme – ein Massenstrom, viele Volumenströme
B2: Besprechung K. Vosbeck 15.10.2026, Pkt. 4 · Rechnung: Einspeicherung/Begleitstoffe_CO2/Prozesskette/06_massenstrom_volumenstroeme.py
B3: ← zur Übersicht
B4: GRUNDSATZ: Die Volumenströme der verschiedenen Phasen dürfen nicht gleichgesetzt werden – verknüpft wird über einen Massenstrom, der entlang der ganzen Kette gleich bleibt (keine Abzweigung, kein Speicher). RECHENWEG: ṁ = V_n · ρ_n / 3600 mit dem Normvolumenstrom V_n (0 °C, 1,01325 bar, DIN 1343). An jedem Zustandspunkt ist der tatsächliche Volumenstrom V̇ = ṁ / ρ(p, T) · 3600 in m³/h. FOLGE: Bei gleichem ṁ fördert Verdichter 1 rund 12-mal so viel Volumen wie die Pumpe (2.888 gegenüber 250 m³/h bei 100.000 Nm³/h). Maschinen und Rohre werden am Zustand ausgelegt, nicht am Normvolumenstrom (Nm³/h ≠ m³/h).
B6: 1) Massenstrom aus dem Normvolumenstrom
B7: Größe | C7: unterer Fall | D7: oberer Fall | E7: Einheit
B8: Normvolumenstrom V_n | C8: =V_min | D8: =V_max | E8: Nm³/h
B9: Normdichte ρ_n (CoolProp, DIN 1343) | C9: =rho_n | D9: =rho_n | E9: kg/m³
B10: Massenstrom ṁ = V_n · ρ_n / 3600 | C10: =Szen1_mmin | D10: =Szen1_mmax | E10: kg/s
B11: Massenstrom | C11: =C10*3.6 | D11: =D10*3.6 | E11: t/h
B12: Massenstrom | C12: =C10*86.4 | D12: =D10*86.4 | E12: t/d
B15: 2) Volumenströme an den Zustandspunkten – reines CO₂ (diese Mappe; ṁ aus Tabelle 1)
B16: Zustandspunkt | C16: p [bar] | D16: T [°C] | E16: ρ [kg/m³] | F16: Phase | G16: V̇ bei 50.000 Nm³/h [m³/h] | H16: V̇ bei 100.000 Nm³/h [m³/h] | I16: Vielfaches des Pumpeneintritts
B17: S2 – gasförmige Anlieferung
B18: Netzübergabe S2 = Verdichter 1 ein | C18: 30 | D18: 15 | E18: 68.444351 | F18: gasförmig | G18: =$C$10/E18*3600 | H18: =$D$10/E18*3600 | I18: =H18/$H$22
B19: Verdichter 1 aus | C19: 55 | D19: 65.427615 | E19: 107.40888 | F19: überkritisch (gasähnlich) | G19: =$C$10/E19*3600 | H19: =$D$10/E19*3600 | I19: =H19/$H$22
B20: Zwischenkühler aus = Verdichter 2 ein | C20: 55 | D20: 40 | E20: 130.05634 | F20: überkritisch (gasähnlich) | G20: =$C$10/E20*3600 | H20: =$D$10/E20*3600 | I20: =H20/$H$22
B21: Verdichter 2 aus | C21: 91 | D21: 84.142709 | E21: 186.0123 | F21: überkritisch | G21: =$C$10/E21*3600 | H21: =$D$10/E21*3600 | I21: =H21/$H$22
B22: Kühler aus = Pumpe ein | C22: 91 | D22: 26 | E22: 791.91673 | F22: dicht (überkritisch) | G22: =$C$10/E22*3600 | H22: =$D$10/E22*3600 | I22: =H22/$H$22
B23: Pumpe aus = Bohrlochkopf | C23: 114.63416 | D23: 29.589764 | E23: 803.64153 | F23: dicht (überkritisch) | G23: =$C$10/E23*3600 | H23: =$D$10/E23*3600 | I23: =H23/$H$22
B24: LCCS (Kaverne voll) | C24: 210 | D24: 40.718353 | E24: 845.15671 | F24: überkritisch | G24: =$C$10/E24*3600 | H24: =$D$10/E24*3600 | I24: =H24/$H$22
B25: S1 – dichte Anlieferung
B26: Netzübergabe S1 | C26: 91 | D26: 15 | E26: 880.96005 | F26: dicht (überkritisch) | G26: =$C$10/E26*3600 | H26: =$D$10/E26*3600 | I26: =H26/$H$22
B27: Pumpe aus = Bohrlochkopf | C27: 105.4411 | D27: 16.571862 | E27: 885.38971 | F27: dicht (überkritisch) | G27: =$C$10/E27*3600 | H27: =$D$10/E27*3600 | I27: =H27/$H$22
B28: LCCS (Kaverne voll) | C28: 210 | D28: 25.574241 | E28: 917.9393 | F28: dicht (überkritisch) | G28: =$C$10/E28*3600 | H28: =$D$10/E28*3600 | I28: =H28/$H$22
B31: 3) Zum Vergleich: Worst-Case-Gemisch (eigener Massenstrom, da andere Normdichte)
B32: Zustandspunkt | C32: p [bar] | D32: T [°C] | E32: ρ [kg/m³] | F32: Phase | G32: V̇ bei 50.000 Nm³/h [m³/h] | H32: V̇ bei 100.000 Nm³/h [m³/h] | I32: Vielfaches des Pumpeneintritts | K32: ṁ unten [kg/s] | L32: ṁ oben [kg/s]
B33: S2 – gasförmige Anlieferung | K33: 26.865069 | L33: 53.730139
B34: Netzübergabe S2 = Verdichter 1 ein | C34: 30 | D34: 15 | E34: 65.761928 | F34: gasförmig | G34: =$K$33/E34*3600 | H34: =$L$33/E34*3600 | I34: =H34/$H$38
B35: Verdichter 1 aus | C35: 55 | D35: 65.899089 | E35: 102.75644 | F35: gasförmig | G35: =$K$33/E35*3600 | H35: =$L$33/E35*3600 | I35: =H35/$H$38
B36: Zwischenkühler aus = Verdichter 2 ein | C36: 55 | D36: 40 | E36: 122.76791 | F36: gasförmig | G36: =$K$33/E36*3600 | H36: =$L$33/E36*3600 | I36: =H36/$H$38
B37: Verdichter 2 aus | C37: 91 | D37: 84.713427 | E37: 175.05614 | F37: gasförmig | G37: =$K$33/E37*3600 | H37: =$L$33/E37*3600 | I37: =H37/$H$38
B38: Kühler aus = Pumpe ein | C38: 91 | D38: 26 | E38: 660.42105 | F38: dicht (flüssig) | G38: =$K$33/E38*3600 | H38: =$L$33/E38*3600 | I38: =H38/$H$38
B39: Pumpe aus = Bohrlochkopf | C39: 127.2718 | D39: 34.406495 | E39: 691.97463 | F39: dicht (flüssig) | G39: =$K$33/E39*3600 | H39: =$L$33/E39*3600 | I39: =H39/$H$38
B40: LCCS (Kaverne voll) | C40: 210 | D40: 48.115197 | E40: 744.04801 | F40: dicht (flüssig) | G40: =$K$33/E40*3600 | H40: =$L$33/E40*3600 | I40: =H40/$H$38
B41: S1 – dichte Anlieferung
B42: Netzübergabe S1 | C42: 91 | D42: 15 | E42: 796.78462 | F42: dicht (flüssig) | G42: =$K$33/E42*3600 | H42: =$L$33/E42*3600 | I42: =H42/$H$38
B43: Pumpe aus = Bohrlochkopf | C43: 114.2738 | D43: 18.305735 | E43: 807.33708 | F43: dicht (flüssig) | G43: =$K$33/E43*3600 | H43: =$L$33/E43*3600 | I43: =H43/$H$38
B44: LCCS (Kaverne voll) | C44: 210 | D44: 28.789554 | E44: 846.41705 | F44: dicht (flüssig) | G44: =$K$33/E44*3600 | H44: =$L$33/E44*3600 | I44: =H44/$H$38
B45: Graue Zustandswerte aus 06_massenstrom_volumenstroeme.py (Betrieb bei 100.000 Nm³/h: Kopfdruck und LCCS-Temperatur aus der strömenden Säule). V̇ und Vielfaches rechnen live mit dem Massenstrom.
...

Sheet Phasendiagramm
B1: Phasendiagramm – Prozesspfade der Einspeicherung und Betriebsfenster von Bohrloch und Kaverne
B2: Reines CO₂ · Stoffdaten CoolProp (Span & Wagner 1996) · Sublimations- und Schmelzlinie nach Span & Wagner (1996)
B3: ← zur Übersicht
B4: Diagramm 1 – Einspeicherung: von der Netzübergabe bis zum Bohrlochkopf
B36: DIAGRAMM 1: Farbflächen = Phasengebiete von reinem CO₂. Grüne Linie = S1 (nur Pumpe, bleibt dicht). Blaue Linie = S2 (2 Verdichterstufen 30 → 55 → 91 bar mit Zwischenkühler 40 °C, Kühler bei 91 bar auf 26 °C, Pumpe) – überkritisch gekühlt, ohne die Sättigungslinie zu kreuzen. Hellblau gepunktet = Vergleich A: verflüssigen bei 60 bar / 20 °C (nur mit Kühlwasser ≤ 14 °C). Violett gestrichelt = Vergleich Durchverdichten (2 Stufen bis 114,6 bar). ENDPUNKT: Die Pfade enden am Bohrlochkopf im Betrieb (100.000 Nm³/h): S1 bei 105,4 bar, S2 bei 114,6 bar (Stillstand 107,6 bar). Diagramm 2 zeigt Bohrloch und Kaverne – nur im Stillstand.
B39: Diagramm 2 – Bohrloch und Kaverne im Stillstand: Betriebsfenster (nur Stillstand, 3 Füllstände nach Q-028)
B40: NUR STILLSTAND: Die Gassäulen gelten für ruhendes CO₂ mit Gebirgstemperatur und für die drei Füllstände nach Q-028 (Buzogany & Kruck 2022, Fig. 3: voll, Grenzfall, leer). Was Injektion und Ausspeicherung für das Fenster bedeuten (Reibungsdruckverlust im Strang, Wärmeaustausch mit dem Gebirge, Erwärmung bzw. Abkühlung in der Kaverne, Drosselung beim Ausspeichern), ist hier NICHT dargestellt.
B72: DIAGRAMM 2: Jede gestrichelte Linie ist eine Gassäule – ein Füllstand der Kaverne im Stillstand. Sie läuft vom Bohrlochkopf (grauer Balken, 0 m, 10 °C) bis zur Kaverne (dunkelblauer Balken, 1200 m, 46 °C). Jeder Punkt auf der Linie ist eine Teufe: oben kalt und niedriger Druck, unten warm und hoher Druck. BETRIEBSFENSTER IM STILLSTAND: Der Bereich zwischen der Linie „voll“ (oben) und der Linie „leer“ (unten), links begrenzt durch den Kopf-Balken und rechts durch den Kavernen-Balken. Jeder Zwischen-Füllstand ergibt eine eigene Linie in diesem Band (Beispiel: Grenzfall). Die Kaverne selbst liegt nur auf dem dunkelblauen Balken – der Bereich dazwischen ist das Bohrloch. WICHTIG BEI LEERER KAVERNE: 70 bar unten ergeben oben nur 45,0 bar – das ist genau der Dampfdruck von CO₂ bei 10 °C. Das obere Bohrloch (0–236 m) liegt dann im Mehrphasengebiet. Erst ab ca. 171,7 bar Kavernendruck (Grenzfall) bleibt das ganze Bohrloch überkritisch bzw. dicht. KAVERNE SELBST: Bei 46 °C liegt sie immer über T_krit. Über 73,8 bar ist das CO₂ überkritisch, bei 70 bar (knapp darunter) gasförmig. Beim Ein- und Ausspeichern weicht die Temperatur ab – Kavernenzyklus in der Kaverne-Mappe. STILLSTAND VS. BETRIEB: Die Gassäulen sind mit Gebirgstemperatur gerechnet (Kopf 10 °C) und gelten nur, solange nichts fließt. Beim Einspeichern kommt das CO₂ wärmer aus der Pumpe (S1 16,6 °C, S2 29,6 °C) – Zieldrücke im Betrieb: Blatt „Kaverne & Gassäule“ unten; Kopfdruckfenster über den ganzen Zyklus: Kaverne-Mappe.

Sheet Annahmen & Begründung
B1: Annahmen & Begründung – woher jede Zahl kommt
B2: Stand 15.10.2026 (nach der Besprechung mit K. Vosbeck) · reines CO₂ · gleiche Annahmen wie im Python-Code (Einspeicherung/Begleitstoffe_CO2/Grundlagen/einspeicherung_bausteine.py, Kaverne/Grundlagen/kaverne_bausteine.py)
B3: ← zur Übersicht
B4: SO IST DIE TABELLE AUFGEBAUT: Jede Annahme mit Wert, Quelle (ID wie in der Quellen- und Wissensmatrix, Blatt „Quellen“) und Fundstelle (Seite S., Folie, Tabelle oder Kapitel) – damit jede Zahl nachgelesen werden kann. „Begründung“ sagt, was in der Quelle steht und warum der Wert so gewählt ist. „Code“ nennt die Konstante im Python-Code mit demselben Wert. WERTE: weiß = verknüpft mit der Übersicht (ändert sich mit), grau = fester Wert im Code. Geändert wird nur auf der Übersicht. STATUS: ✔ belegt = steht so in der Quelle · ◐ abgeleitet = aus Quellen hergeleitet · ○ eigene Annahme · ? = noch zu klären (Quelle offen bzw. mit Hersteller bestätigen, Messe Hamburg 20.–22.10.2026).
B6: Nr. | C6: Größe | D6: Symbol | E6: Wert | F6: Einheit | G6: Quelle | H6: Fundstelle | I6: Inhalt der Quelle / Begründung | J6: Code | K6: Status
B7: A Anlieferung (Netzübergabe)
B8: 1 | C8: Übergabedruck S1 (dicht) | D8: p_S1 | E8: =p_S1 | F8: bar | G8: OGE | H8: Notizen 16.09.2026, Pkt. 6 | I8: mind. 91 bar (vorher 85 bar), Worst Case mit Begleitstoffen. Beim Gemisch 8,8 bar über der Cricondenbar (82,2 bar) → dichte, einphasige Übergabe. | J8: eb.p_S1 | K8: ✔ belegt
B9: 2 | C9: Übergabetemperatur S1 | D9: T_S1 | E9: =T_S1 | F9: °C | G9: eigene Annahme | H9: – | I9: Medientemperatur der erdverlegten Fernleitung (nicht Gebirgstemperatur) – mit OGE abzustimmen. | J9: eb.T_S1 | K9: ○ eigene Annahme
B10: 3 | C10: Übergabedruck S2 (gasförmig) | D10: p_S2 | E10: =p_S2 | F10: bar | G10: Vorarbeit | H10: – | I10: aus der eigenen Vorarbeit; alte Annahmentabelle nennt ISO 27913 (Q-040) – dort noch nicht ausgewertet. | J10: eb.p_S2 | K10: ? Quelle offen
B11: 4 | C11: Übergabetemperatur S2 | D11: T_S2 | E11: =T_S2 | F11: °C | G11: eigene Annahme | H11: – | I11: Medientemperatur wie S1. | J11: eb.T_S2 | K11: ○ eigene Annahme
B12: B Verdichtung S2 (2 Stufen 30 → 55 → 91 bar)
B13: 5 | C13: Zwischendruck | D13: p_zw | E13: =p_zw | F13: bar | G13: eigene Herleitung (Q-017, Q-016) | H13: Blatt „Kühlung“, Tabelle 2 | I13: höchster runder Zwischendruck, bei dem am Eintritt Stufe 2 (40 °C) Z ≥ 0,7 für reines CO₂ UND Gemisch gilt (rein 0,715, Gemisch 0,741). Beide Stufen bleiben dann unter 95 °C (Stufe 2: rein 84,1 °C, Gemisch 84,7 °C). Mit 50 bar läge Stufe 2 bei 93–94 °C, mit 60 bar wäre Z beim reinen CO₂ < 0,7. | J13: eb.P_ZW | K13: ◐ abgeleitet
B14: 6 | C14: Druck nach Verdichtung = Kühldruck = Pumpeneintritt | D14: p_ük | E14: =p_uek | F14: bar | G14: eigene Festlegung | H14: Span & Wagner 1996 (p_krit 73,8 bar) | I14: über der Cricondenbar des Gemischs (82,2 bar) + 3 bar Unsicherheit bzw. über p_krit (73,8 bar): der Kühler kreuzt kein Zweiphasengebiet. = Übergabedruck S1 → eine Pumpenbauart für S1 und S2. | J14: eb.P_UEK | K14: ◐ abgeleitet
B15: 7 | C15: Höchste Austrittstemperatur je Stufe | D15: T_max | E15: =T_maxV | F15: °C | G15: Q-016 | H15: S. 4, Kap. 2.3 (dort Lit. [24]) | I15: „… might not be higher than the assumed value of 95 °C“ – legt die Zahl der Stufen fest. | J15: eb.T_MAX_STUFE | K15: ✔ belegt
B16: 8 | C16: Isentroper Wirkungsgrad Stufe 1 | D16: η_V1 | E16: =eta_V1 | F16: – | G16: Q-016 | H16: S. 4, Kap. 2.3 | I16: „efficiency of compressors … for the first stage is 84 %“ | J16: eb.eta_V1 | K16: ✔ belegt
B17: 9 | C17: Isentroper Wirkungsgrad Stufe 2 | D17: η_V2 | E17: =eta_V2 | F17: – | G17: Q-016 | H17: S. 4, Kap. 2.3 | I17: „… for subsequent stages, it is successively reduced by 2 %“ → 82 % | J17: eb.eta_V2 | K17: ✔ belegt
B18: 10 | C18: Realgasfaktor am Stufeneintritt mindestens (Hersteller) | D18: Z_min | E18: =Z_min | F18: – | G18: Siemens Energy | H18: E-Mail-Auskunft 08/2026 | I18: „Damit die Berechnung der Laufräder in unseren Berechnungsprogrammen zuverlässig ausgeführt wird, bleiben wir bei einem Z-Wert von > 0,65.“ Gilt nur für Verdichter, nicht für die Pumpe. | J18: eb.Z_MIN | K18: ✔ persönliche Mitteilung
B19: 11 | C19: Realgasfaktor Literaturrichtwert | D19: Z | E19: 0.7 | F19: – | G19: Q-017 | H19: S. 37 (Tab. 3: Z_min 0,7); S. 44 | I19: „Als Grenzwert des Z-Faktors wird durch verschiedenste Hersteller 0,7 angegeben.“ Bei kleinerem Z steigen die Grenzschichtverluste (S. 44). Grundlage für den Zwischendruck. | J19: eb.Z_Q017 | K19: ✔ belegt
B20: C Kühlung – zwei Kühler, zwei Zwecke
B21: 12 | C21: CO₂ nach dem Zwischenkühler | D21: T_ZK | E21: =T_ZK | F21: °C | G21: Q-017; Q-063 | H21: Q-017 S. 37 (Tab. 3), S. 61; Q-063 Kap. 5.1 (PDF-S. 22) | I21: Q-017: „Soll-Kühltemperatur CO₂ 40 °C“ (Auslegung Kingsnorth), S. 61 Siemens-Konzept „Eingangstemperatur 40 °C“. Q-063: CO₂ „no more than about 40 °C. Cooling is therefore required between and after compressor stages“. Zweck: Verdichterarbeit senken, Stufe 2 < 95 °C. Kälter ist nicht besser: Z sinkt (Q-017 S. 44) – bei 26 °C wäre Z = 0,63 (rein) < 0,65. | J21: eb.T_ZK | K21: ✔ belegt
B22: 13 | C22: nicht übernommen: Kühlung auf 20 °C | D22: – | E22: 20 | F22: °C | G22: Q-016 | H22: S. 9 und S. 14 | I22: Die 20 °C dienen in Q-016 der Wasserabscheidung vor der TEG-Trocknung (nasses CO₂ direkt aus der Abscheidung) – das CO₂ aus dem Netz ist bereits trocken. Deshalb nicht übertragbar. | J22: – | K22: – nicht übertragbar
B23: 14 | C23: Kühlwasser (Auslegung) | D23: T_KW | E23: =T_KW | F23: °C | G23: eigene Annahme | H23: – | I23: Standortwert, mit Hersteller/Standort zu bestätigen (Messe Hamburg 20.–22.10.2026). Wirkung von 15 und 25 °C: Blatt „Kühlung“, Tabelle 4. | J23: eb.T_KW | K23: ? bestätigen
B24: 15 | C24: Temperaturabstand Kühler (Grädigkeit) | D24: ΔT | E24: 6 | F24: K | G24: Q-120 | H24: Folie 24 | I24: „Final CO₂ temperature is seldom lower than 6 deg. C (11 deg F) warmer than the air or water.“ | J24: eb.DT_KUEHLER | K24: ✔ belegt
B25: 16 | C25: CO₂ nach dem Kühler vor der Pumpe | D25: T_K | E25: =T_K | F25: °C | G25: Q-120; Q-121 | H25: Q-120 Folie 32; Q-121 S. 2–3 | I25: T_K = T_KW + ΔT = 26 °C. Q-120: für Pumpen „cool to 80 to 90 °F (27 to 32 °C) if at all practical to maximize density“, über 38 °C deutlich mehr Förderhöhe. Q-121: Wirkungsgrad sinkt mit steigender Saugtemperatur. 26 °C liegt unter der pseudokritischen Linie bei 91 bar (Gemisch 32,8 °C, rein 40,5 °C). | J25: eb.T_K | K25: ✔ belegt
B26: D Pumpe
B27: 17 | C27: Isentroper Wirkungsgrad Pumpe | D27: η_P | E27: =eta | F27: – | G27: eigene Annahme | H27: Q-016 S. 4 (nur Glykolpumpe 70 %) | I27: keine Quelle für CO₂-Pumpen – Herstellerwert einholen (Messe Hamburg 20.–22.10.2026). | J27: eb.eta_P | K27: ? Hersteller fragen
B28: 18 | C28: Mindestdichte am Pumpeneintritt | D28: ρ_min | E28: =rho_min | F28: kg/m³ | G28: Q-121; Q-001 | H28: Q-121 S. 2; Q-001 Kap. 5.2 | I28: „The value of the minimum operating density, between 500 and 400 kg/m³, depends on rotor-dynamics of the pump“ → 500 kg/m³ (oberer, sicherer Wert). | J28: eb.RHO_MIN | K28: ✔ belegt
B29: E Durchsatz
B30: 19 | C30: Normvolumenstrom unterer / oberer Fall | D30: V_n | E30: 50.000 / 100.000 | F30: Nm³/h | G30: Abstimmung M. Wall (Uniper) | H30: – | I30: Bandbreite der Anlage. Zieldruck der Pumpe wird bei 100.000 Nm³/h ausgelegt (höchste Reibung). | J30: eb.V_NORM_MIN / V_NORM_MAX | K30: ✔ abgestimmt
B31: 20 | C31: Normzustand | D31: p_n, T_n | E31: 1,01325 bar / 0 °C | F31: – | G31: DIN 1343 | H31: – | I31: Normdichte aus CoolProp: Gemisch 1,934 kg/m³, rein 1,977 kg/m³ → gleicher Normvolumenstrom ergibt beim Gemisch 2 % weniger Masse. | J31: stoff.rho_norm() | K31: ✔ belegt
B32: F Kaverne und Bohrloch
B33: 21 | C33: Teufe LCCS (Referenzkaverne) | D33: z | E33: =z_V1 | F33: m | G33: Q-030 | H33: Tab. 1, Option 2 | I33: Uniper-Bestandskaverne; mit M. Wall abgestimmt. | J33: eb.TEUFE | K33: ✔ belegt
B34: 22 | C34: Flache Kaverne | D34: – | E34: entfällt | F34: – | G34: Q-030 | H34: S. 17 (Kap. 1.2.1.2) | I34: DBI verwirft die flache Option selbst: „almost immediate phase transition into liquid in the cavern, respectively, at the wellhead“. Festgelegt in der Besprechung mit K. Vosbeck (15.10.2026). | J34: kb.KAVERNEN = (TIEF,) | K34: ✔ belegt
B35: 23 | C35: Gebirgstemperatur Oberfläche / Gradient | D35: T₀ / grad T | E35: 10 °C / 0,03 K/m | F35: – | G35: Q-028 | H35: Kap. 3 (S. 5), Fig. 3 | I35: „surface temperature of 10 °C (50 °F) and a temperature gradient of 0.03 K/m“ | J35: eb.T_OBERFLAECHE, eb.GRADIENT | K35: ✔ belegt
B36: 24 | C36: Maximaldruck an der LCCS | D36: p_max | E36: =pmax_V1 | F36: bar | G36: M. Wall; Q-028; Q-030 | H36: Q-028 Tab. 1 (200 bar); Q-030 Tab. 1 (240 bar) | I36: Zwischenwert der beiden Quellen, Vorgabe M. Wall (Uniper). | J36: eb.P_MAX_LCCS | K36: ✔ abgestimmt
B37: 25 | C37: Minimaldruck an der LCCS | D37: p_min | E37: =pmin_V1 | F37: bar | G37: Q-028 | H37: Tab. 1 | I37: geomechanisches Minimum. | J37: eb.P_MIN_LCCS | K37: ✔ belegt
B38: 26 | C38: Förderstrang (Innendurchmesser) | D38: D_i | E38: 198.8 | F38: mm | G38: Q-030 | H38: Tab. 1; Kap. 1.2.1 (S. 12) | I38: 8 5/8" 36# J55 im 11 ¾"-LCCS („possible tubing sizes 8 5/8” and 5 ½”“). | J38: kb.D_STRANG | K38: ✔ belegt
B39: 27 | C39: Rohrreibungszahl (Darcy) | D39: f | E39: 0.016 | F39: – | G39: Q-003 | H39: Kap. 6.2 | I39: 0,015–0,017 für neues Stahlrohr – Mittelwert. | J39: kb.F_DARCY | K39: ✔ belegt
B40: 28 | C40: Strömung im Strang beim Einspeisen | D40: – | E40: adiabat | F40: – | G40: Besprechung K. Vosbeck 15.10.2026 | H40: – | I40: schnelle Förderung, kein Wärmeaustausch mit dem Gebirge: h + g·z = konst., Kopftemperatur = Pumpenaustritt. Grenze: homogen, einphasig – genauer nur mit Mehrphasen-Bohrlochmodell (Q-028 S. 11). | J40: kb.strang() | K40: ◐ Modellannahme
B41: 29 | C41: Stillstandsdauer zwischen den Phasen | D41: t_still | E41: 21.67 | F41: d | G41: Q-028 | H41: S. 10 (Kap. 4) | I41: Betriebsszenario der Simulation in Q-028: „Standstill phase (21.67 d)“ nach Aus- und nach Einspeisen. Gleiche Begründung wie in der Quelle; an dieser Simulation ist auch der Wärmeübergang UA kalibriert. Vergleich „kontinuierlich (0 d)“ in der Kaverne-Mappe. | J41: kb.T_STILLSTAND | K41: ✔ belegt
...

Sheet Quellen
B1: Quellen
B2: Herkunft der Annahmen und Stoffdaten dieser Mappe (IDs wie in der Quellen- und Wissensmatrix). Fundstellen je Annahme: Blatt „Annahmen & Begründung“.
B3: ← zur Übersicht
B4: ID | C4: Quelle | D4: Verwendet für
B5: Q-001 | C5: DVGW (2024): C 260 (A) – Properties of Carbon Dioxide and Carbon Dioxide Streams. Entwurf. | D5: Kritischer Punkt, Stoffeigenschaften CO₂
B6: Q-016 | C6: Bielka, P.; Kuczyński, S.; Nagy, S.: CO₂ Compression and Dehydration for Transport and Geological Storage. | D6: Wirkungsgrade Verdichter 84 % (Stufe 1) / 82 % (Stufe 2) und höchstens 95 °C je Stufe (S. 4, Kap. 2.3). Nicht übernommen: Kühlung auf 20 °C (S. 9, S. 14) – dient dort der Wasserabscheidung vor der TEG-Trocknung; Glykolpumpe 70 % (S. 4) nicht auf die CO₂-Pumpe übertragbar.
B7: Q-028 | C7: Buzogany, R.; Kruck, O. (2022): CO₂ – Storage in Salt Caverns: Thermodynamic Analysis and Challenges. SMRI Fall 2022. | D7: Oberflächentemperatur 10 °C, Gradient 0,03 K/m (Kap. 3, S. 5), Minimaldruck 70 bar (Tab. 1), Darstellung Gassäule (Fig. 3), Stillstand 21,67 d (S. 10), Grenze des homogenen Bohrlochmodells (S. 11)
B8: Q-029 | C8: DBI für Uniper: CCUS-P2 – CO₂-Storage for CCU/S, Phase 2 – Detailing Study, Final Report V08. | D8: Offener Punkt: gewählte Option 1 ist die tiefe Kaverne (1400 m, 260 bar)
B9: Q-030 | C9: DBI für Uniper: CCUS-P1 – CO₂-Storage for CCU/S, Phase 1 – Initial Concept Study, Final Report. | D9: Tab. 1: Teufe 1200 m (Option 2), Anhalt für p_max (240 bar), Förderstrang 8 5/8" (Kap. 1.2.1); S. 17: flache Option verworfen (fast sofort Flüssigphase) → keine Kaverne V2
B10: Q-038 | C10: Baumgärtel, L.; Körner, F.; Leuger, B.; Zapf, D. (2023): Energiespeicherung in Salzkavernen. Poster, Tag der Energieforschung, LU Hannover. | D10: Zu prüfen: alte Annahmentabelle leitet daraus p_max ≈ 85 % des lithostatischen Drucks ab – in der Matrix nur Geometriedaten erfasst
B11: Q-040 | C11: DIN EN ISO 27913: Abscheidung, Transport und geologische Speicherung von CO₂ – Rohrleitungstransportsysteme (dt. Fassung 2025). | D11: Zu prüfen: alte Annahmentabelle nennt Q-040 für die gasförmige Anlieferung mit 30 bar – Norm in der Matrix noch nicht ausgewertet
B12: OGE | C12: Gesprächsnotiz Austausch OGE / Uniper, 16.09.2026 (Notizen S. Maxara). | D12: Übergabedruck S1 mind. 91 bar; Durchsatz-Bandbreite (mit M. Wall)
B13: — | C13: Span, R.; Wagner, W. (1996): A New Equation of State for Carbon Dioxide Covering the Fluid Region from the Triple-Point Temperature to 1100 K at Pressures up to 800 MPa. J. Phys. Chem. Ref. Data 25(6), 1509–1596. | D13: Zustandsgleichung CO₂ (über CoolProp); Sublimations- und Schmelzdruck
B14: — | C14: Bell, I. H.; Wronski, J.; Quoilin, S.; Lemort, V. (2014): Pure and Pseudo-pure Fluid Thermophysical Property Evaluation and the Open-Source Thermophysical Property Library CoolProp. Ind. Eng. Chem. Res. 53(6), 2498–2508. | D14: Stoffdatenbibliothek CoolProp, Version 8.0.0
B15: Vorarbeit | C15: Python-Skripte der eigenen Vorarbeit (ObertageAnlageRechner: gaspfad_vergleich.py, pfadentscheidung.py). | D15: Nur noch der Übergabedruck S2 (30 bar) stammt aus der Vorarbeit – Quelle zu prüfen. Frühere Annahmen (Verflüssigung, Kühlung auf 20 °C) sind ersetzt.
... B23: Doku | C23: Dokumentation_Stoffmodelle_Validierung.docx (eigene Arbeit). | D23: Unsicherheit der Phasengrenze ±3 bar (Kap. 9)

Sheet Diagrammdaten
B1: Diagrammdaten – Hilfstabellen (nicht ändern)
B2: Grundlage für das Phasendiagramm. Farbflächen: gestapelte Druckbereiche je Temperatur. Linien: Punkte mit T, p und Position im Diagramm.
B3: ← zur Übersicht
B4: T_min [°C] | C4: -80 | D4: Position im Diagramm = (T − T_min) / Schritt + 1 (die Farbflächen haben eine Kategorie je 0,5 K)
B5: Schritt [K] | C5: 0.5
B7: T [°C] | C7: Achsenbeschriftung | D7: gasförmig [bar] | E7: flüssig [bar] | F7: überkritisch [bar] | G7: fest [bar] | I7: Linie / Punkt | J7: T [°C] | K7: p [bar] | L7: Position
B8: -80 | C8: =IF(MOD(B8,20)=0,TEXT(B8,"0"),"") | D8: 0.8924 | E8: 0 | F8: 0 | G8: 249.1076 | I8: Sättigungslinie | J8: -56.558 | K8: 5.1796 | L8: =(J8-Diagramm_Tmin)/Diagramm_dT+1
B9: -79.5 | C9: =IF(MOD(B9,20)=0,TEXT(B9,"0"),"") | D9: 0.9303 | E9: 0 | F9: 0 | G9: 249.0697 | J9: -55.2894 | K9: 5.4714 | L9: =(J9-Diagramm_Tmin)/Diagramm_dT+1
B10: -79 | C10: =IF(MOD(B10,20)=0,TEXT(B10,"0"),"") | D10: 0.9696 | E10: 0 | F10: 0 | G10: 249.0304 | J10: -54.0207 | K10: 5.7754 | L10: =(J10-Diagramm_Tmin)/Diagramm_dT+1
B11: -78.5 | C11: =IF(MOD(B11,20)=0,TEXT(B11,"0"),"") | D11: 1.0103 | E11: 0 | F11: 0 | G11: 248.9897 | J11: -52.7521 | K11: 6.092 | L11: =(J11-Diagramm_Tmin)/Diagramm_dT+1
B12: -78 | C12: =IF(MOD(B12,20)=0,TEXT(B12,"0"),"") | D12: 1.0526 | E12: 0 | F12: 0 | G12: 248.9474 | J12: -51.4834 | K12: 6.4214 | L12: =(J12-Diagramm_Tmin)/Diagramm_dT+1
B13: -77.5 | C13: =IF(MOD(B13,20)=0,TEXT(B13,"0"),"") | D13: 1.0964 | E13: 0 | F13: 0 | G13: 248.9036 | J13: -50.2148 | K13: 6.7641 | L13: =(J13-Diagramm_Tmin)/Diagramm_dT+1
B14: -77 | C14: =IF(MOD(B14,20)=0,TEXT(B14,"0"),"") | D14: 1.1418 | E14: 0 | F14: 0 | G14: 248.8582 | J14: -48.9462 | K14: 7.1203 | L14: =(J14-Diagramm_Tmin)/Diagramm_dT+1
B15: -76.5 | C15: =IF(MOD(B15,20)=0,TEXT(B15,"0"),"") | D15: 1.1888 | E15: 0 | F15: 0 | G15: 248.8112 | J15: -47.6775 | K15: 7.4903 | L15: =(J15-Diagramm_Tmin)/Diagramm_dT+1
B16: -76 | C16: =IF(MOD(B16,20)=0,TEXT(B16,"0"),"") | D16: 1.2375 | E16: 0 | F16: 0 | G16: 248.7625 | J16: -46.4089 | K16: 7.8746 | L16: =(J16-Diagramm_Tmin)/Diagramm_dT+1
B17: -75.5 | C17: =IF(MOD(B17,20)=0,TEXT(B17,"0"),"") | D17: 1.288 | E17: 0 | F17: 0 | G17: 248.712 | J17: -45.1402 | K17: 8.2734 | L17: =(J17-Diagramm_Tmin)/Diagramm_dT+1
B18: -75 | C18: =IF(MOD(B18,20)=0,TEXT(B18,"0"),"") | D18: 1.3403 | E18: 0 | F18: 0 | G18: 248.6597 | J18: -43.8716 | K18: 8.687 | L18: =(J18-Diagramm_Tmin)/Diagramm_dT+1
B19: -74.5 | C19: =IF(MOD(B19,20)=0,TEXT(B19,"0"),"") | D19: 1.3944 | E19: 0 | F19: 0 | G19: 248.6056 | J19: -42.603 | K19: 9.1159 | L19: =(J19-Diagramm_Tmin)/Diagramm_dT+1
B20: -74 | C20: =IF(MOD(B20,20)=0,TEXT(B20,"0"),"") | D20: 1.4505 | E20: 0 | F20: 0 | G20: 248.5495 | J20: -41.3343 | K20: 9.5604 | L20: =(J20-Diagramm_Tmin)/Diagramm_dT+1
... B77: -45.5 | C77: =IF(MOD(B77,20)=0,TEXT(B77,"0"),"") | D77: 8.1588 | E77: 241.8412 | F77: 0 | G77: 0 | J77: 30.9782 | K77: 73.773 | L77: =(J77-Diagramm_Tmin)/Diagramm_dT+1
B78: -45 | C78: =IF(MOD(B78,20)=0,TEXT(B78,"0"),"") | D78: 8.3184 | E78: 241.6816 | F78: 0 | G78: 0
