Workbook
Name Diagramm_dT: Diagrammdaten!$C$5
Name Diagramm_Tmin: Diagrammdaten!$C$4
Name Dv_h1a: 'Einspeicherung S2'!$E$76
Name Dv_h1s: 'Einspeicherung S2'!$E$75
Name Dv_h2a: 'Einspeicherung S2'!$E$87
Name Dv_h2s: 'Einspeicherung S2'!$E$86
Name Dv_hN: 'Einspeicherung S2'!$E$93
Name Dv_hZK1: 'Einspeicherung S2'!$E$81
Name Dv_p1: 'Einspeicherung S2'!$E$72
Name Dv_Pmax: 'Einspeicherung S2'!$E$98
Name Dv_q_ges: 'Einspeicherung S2'!$E$97
Name Dv_qN: 'Einspeicherung S2'!$E$94
Name Dv_qZK1: 'Einspeicherung S2'!$E$82
Name Dv_T1a: 'Einspeicherung S2'!$E$77
Name Dv_T2a: 'Einspeicherung S2'!$E$88
Name Dv_w1: 'Einspeicherung S2'!$E$78
Name Dv_w2: 'Einspeicherung S2'!$E$90
Name Dv_w_ges: 'Einspeicherung S2'!$E$96
Name eta: Übersicht!$F$67
Name eta_V1: Übersicht!$F$65
Name eta_V2: Übersicht!$F$66
Name grad_V1: Übersicht!$F$55
Name Kopf_grenz: 'Kaverne & Gassäule'!$D$19
Name Kopf_leer: 'Kaverne & Gassäule'!$D$20
Name Kopf_voll: 'Kaverne & Gassäule'!$D$18
Name MV_Kopf_CH4: Medienvergleich!$D$11
Name MV_Kopf_CO2: Medienvergleich!$C$11
Name MV_Kopf_H2: Medienvergleich!$E$11
Name p_blase_TK: 'Gemisch & Grenzen'!$H$15
Name p_cricondenbar: 'Gemisch & Grenzen'!$H$11
Name p_grenz: 'Kaverne & Gassäule'!$C$19
Name p_lith_V1: Übersicht!$F$71
Name p_S1: Übersicht!$F$43
Name p_S2: Übersicht!$F$46
Name p_tau_TK: 'Gemisch & Grenzen'!$H$16
Name p_verfl: Übersicht!$F$50
Name p_zw: Übersicht!$F$51
Name pmax_V1: Übersicht!$F$56
Name pmin_V1: Übersicht!$F$57
Name rho_n: 'Einspeicherung S1'!$E$19
Name rhoSalz_V1: Übersicht!$F$58
Name Stand_ok: Übersicht!$Q$39
Name Szen1_eta: 'Einspeicherung S1'!$E$14
Name Szen1_h1: 'Einspeicherung S1'!$E$10
Name Szen1_h2: 'Einspeicherung S1'!$E$15
Name Szen1_h2s: 'Einspeicherung S1'!$E$13
Name Szen1_mmax: 'Einspeicherung S1'!$E$21
Name Szen1_mmin: 'Einspeicherung S1'!$E$20
Name Szen1_p1: 'Einspeicherung S1'!$E$8
Name Szen1_p2: 'Einspeicherung S1'!$E$12
Name Szen1_Pmax: 'Einspeicherung S1'!$E$23
Name Szen1_Pmin: 'Einspeicherung S1'!$E$22
Name Szen1_s1: 'Einspeicherung S1'!$E$11
Name Szen1_T1: 'Einspeicherung S1'!$E$9
Name Szen1_T2: 'Einspeicherung S1'!$E$16
Name Szen1_w: 'Einspeicherung S1'!$E$18
Name Szen2_h1: 'Einspeicherung S2'!$E$12
Name Szen2_h1a: 'Einspeicherung S2'!$E$15
Name Szen2_h1s: 'Einspeicherung S2'!$E$14
Name Szen2_hPa: 'Einspeicherung S2'!$E$29

Sheet Übersicht
B1: CO₂-Zwischenspeicherung in Salzkavernen – Obertageanlage · Worst-Case-Gemisch
B2: Rechenübersicht Einspeicherung · Masterarbeit Sarah Maxara · TH Köln / Uniper Energy Storage
B3: Stand: 30.09.2026 · Stoffdaten: CoolProp 8.0.0, Mehrfluid-Helmholtz-Modell (GERG-2008-Mischungsregel, Reinstoffe u. a. Span & Wagner 1996) · Worst-Case-Gemisch 95 % CO₂, 2,4 % N₂, 1 % Ar, 1 % CH₄, 0,5 % H₂, 0,1 % CO (mol-%)
B5: Worum geht es? | J5: Farblegende der Zellen
B6: Diese Mappe zeigt Schritt für Schritt, wie die Obertageanlage für die Einspeicherung berechnet wird: 1. Welcher Druck muss am Bohrlochkopf anliegen? → das gibt die Kaverne über die Gassäule vor. 2. Wie bringt die Anlage das CO₂ auf diesen Druck? → Pumpe (dichte Anlieferung, S1) bzw. Verdichter, Kühler und Pumpe (gasförmige Anlieferung, S2). 3. Wo liegen alle Zustände im Phasendiagramm – und wo liegt das Betriebsfenster von Bohrloch und Kaverne? Diese Mappe rechnet das Worst-Case-Gemisch mit 5 % Begleitstoffen – gleicher Aufbau wie die Mappe für reines CO₂. Was sich an den Grenzen ändert und warum: Blatt „Gemisch & Grenzen“. | J6: 91 | K6: Annahme – darf geändert werden
J7: 246.6 | K7: Stoffwert aus CoolProp – fest
J8: 100 | K8: Excel-Formel – rechnet sofort mit
J9: 114.9 | K9: wichtiges Ergebnis
J10: rot | K10: Stoffwert passt nicht mehr zu den Annahmen
B12: Inhalt
B13: → Kaverne & Gassäule | E13: Welchen Kopfdruck gibt die Kaverne vor? Gassäule im Stillstand für drei Füllstände (wie Q-028, Fig. 3).
B14: → Medienvergleich | E14: Warum braucht CO₂ oben weniger Druck als Erdgas oder Wasserstoff?
B15: → Einspeicherung S1 | E15: Anlieferung dicht: Pumpe – jeder Rechenschritt einzeln.
B16: → Einspeicherung S2 | E16: Anlieferung gasförmig: Verdichtung (2 Stufen), Zwischenkühlung, Kühlung in der dichten Phase, Pumpe.
B17: → Phasendiagramm | E17: Diagramm 1: Prozesspfade bis zum Bohrlochkopf. Diagramm 2: Betriebsfenster von Bohrloch und Kaverne (nur Stillstand).
B18: → Quellen | E18: Herkunft aller Annahmen und Stoffdaten.
B19: → Diagrammdaten | E19: Hilfstabellen für die Diagramme (nicht ändern).
B20: → Gemisch & Grenzen | E20: Was die Begleitstoffe ändern: Zweiphasengebiet, Unsicherheit ±3 bar, neue Grenzen der Anlage.
B21: Prozesskette Einspeicherung – Szenarien
B37: Szenarien & Annahmen
B38: Blaue Werte dürfen geändert werden. Weiße Formelwerte rechnen sofort mit. Graue Stoffwerte (CoolProp) kann Excel nicht selbst berechnen – ändert sich eine Annahme, zeigt der Status, welche Werte neu berechnet werden müssen.
B39: Status | E39: =IF(Stand_ok,"✔ Alle grauen Stoffwerte passen zu den Annahmen.","⚠ Mindestens eine Annahme wurde geändert – rot markierte Stoffwerte sind veraltet und müssen neu berechnet werden.") -> ✔ Alle grauen Stoffwerte passen zu den Annahmen. | Q39: =COUNTIF($N$42:$N$67,"⚠*")=0 -> 1
B41: Größe | E41: Symbol | F41: Wert | G41: Einheit | H41: Quelle / Begründung | M41: gerechnet mit | N41: Status
B42: Anlieferszenario S1 – dichte Phase (Pipeline OGE)
B43: Übergabedruck | E43: p_S1 | F43: 91 | G43: bar | H43: OGE-Notizen 16.09.2026, Pkt. 6: mind. 91 bar (vorher 85 bar), Worst Case mit Begleitstoffen | M43: 91 | N43: =IF(ABS(F43-M43)<0.000000001,"✔ passt","⚠ geändert – neu rechnen") -> ✔ passt
B44: Übergabetemperatur | E44: T_S1 | F44: 15 | G44: °C | H44: Annahme: Medientemperatur der Fernleitung (nicht Gebirgstemperatur) | M44: 15 | N44: =IF(ABS(F44-M44)<0.000000001,"✔ passt","⚠ geändert – neu rechnen") -> ✔ passt
B45: Anlieferszenario S2 – gasförmig
B46: Übergabedruck | E46: p_S2 | F46: 30 | G46: bar | H46: Annahme aus Vorarbeit; alte Tabelle nennt Q-040 (ISO 27913) – dort noch nicht ausgewertet, zu prüfen | M46: 30 | N46: =IF(ABS(F46-M46)<0.000000001,"✔ passt","⚠ geändert – neu rechnen") -> ✔ passt
B47: Übergabetemperatur | E47: T_S2 | F47: 15 | G47: °C | H47: Annahme: Medientemperatur | M47: 15 | N47: =IF(ABS(F47-M47)<0.000000001,"✔ passt","⚠ geändert – neu rechnen") -> ✔ passt
B48: Kühltemperatur nach jeder Stufe | E48: T_K | F48: 20 | G48: °C | H48: Q-016 (S. 4, Kap. 2.3): Kühlung nach jeder Verdichterstufe auf 20 °C; setzt Kühlwasser voraus | M48: 20 | N48: =IF(ABS(F48-M48)<0.000000001,"✔ passt","⚠ geändert – neu rechnen") -> ✔ passt
B49: Max. Austrittstemperatur je Verdichterstufe | E49: T_max | F49: 95 | G49: °C | H49: Q-016 (S. 4, Kap. 2.3): höchstens 95 °C nach jeder Stufe → legt die Zahl der Stufen fest | M49: 95 | N49: =IF(ABS(F49-M49)<0.000000001,"✔ passt","⚠ geändert – neu rechnen") -> ✔ passt
B50: Enddruck Verdichtung = Kühlerdruck | E50: p_V | F50: 90 | G50: bar | H50: Gemisch: ≥ Cricondenbar 82,2 + 3 bar → Kühlen ohne Zweiphasengebiet (rein: 60 bar, verflüssigen) | M50: 90 | N50: =IF(ABS(F50-M50)<0.000000001,"✔ passt","⚠ geändert – neu rechnen") -> ✔ passt
B51: Zwischendruck (nur Vergleich Durchverdichten) | E51: p_zw | F51: 50 | G51: bar | H51: Gemisch: ≤ Taudruck(T_K) − 3 bar = 60,4 bar; Stufe 2 ≤ 95 °C ab 48,1 bar → zulässig ca. 48–60 bar | M51: 50 | N51: =IF(ABS(F51-M51)<0.000000001,"✔ passt","⚠ geändert – neu rechnen") -> ✔ passt
B52: Kaverne V1 – tief (Basisfall)
B53: Teufe (LCCS) | E53: z | F53: 1200 | G53: m | H53: Q-030 Option 2; abgestimmt mit Martina Wall (Uniper) | M53: 1200 | N53: =IF(ABS(F53-M53)<0.000000001,"✔ passt","⚠ geändert – neu rechnen") -> ✔ passt
B54: Gebirgstemperatur an der Oberfläche | E54: T₀ | F54: 10 | G54: °C | H54: Q-028 (Buzogany & Kruck 2022) | M54: 10 | N54: =IF(ABS(F54-M54)<0.000000001,"✔ passt","⚠ geändert – neu rechnen") -> ✔ passt
B55: Geothermischer Gradient | E55: grad T | F55: 0.03 | G55: K/m | H55: Q-028 | M55: 0.03 | N55: =IF(ABS(F55-M55)<0.000000001,"✔ passt","⚠ geändert – neu rechnen") -> ✔ passt
B56: Maximaldruck an der LCCS | E56: p_max | F56: 210 | G56: bar | H56: Zwischenwert aus Q-028 (200 bar) und Q-030 Opt. 2 (240 bar) | M56: 210 | N56: =IF(ABS(F56-M56)<0.000000001,"✔ passt","⚠ geändert – neu rechnen") -> ✔ passt
B57: Minimaldruck an der LCCS | E57: p_min | F57: 70 | G57: bar | H57: Q-028: geomechanisches Minimum | M57: 70 | N57: =IF(ABS(F57-M57)<0.000000001,"✔ passt","⚠ geändert – neu rechnen") -> ✔ passt
B58: Dichte Salzgestein | E58: ρ_Salz | F58: 2200 | G58: kg/m³ | H58: Q-028; nur für den lithostatischen Druck (Formel unten) | M58: 2200 | N58: =IF(ABS(F58-M58)<0.000000001,"✔ passt","⚠ geändert – neu rechnen") -> ✔ passt
...

Sheet Gemisch & Grenzen
B1: Gemisch & Grenzen – was die Begleitstoffe am Phasendiagramm ändern
B2: Worst-Case-Gemisch Anlieferung · Stoffdaten CoolProp 8.0.0 (GERG-2008-Mischungsregel) · Vergleich mit der Mappe für reines CO₂
B3: ← zur Übersicht
B5: Kurz gesagt
B6: Reines CO₂ hat eine Dampfdrucklinie: bei jeder Temperatur genau ein Druck, bei dem es siedet. Das Gemisch hat stattdessen ein Zweiphasengebiet zwischen Taulinie (erster Tropfen) und Blasenlinie (letzte Blase). Die leichtflüchtigen Begleitstoffe (vor allem H₂ und N₂) schieben die Blasenlinie nach oben – für „sicher flüssig“ braucht man mehr Druck. Weil die Phasengrenze eines Gemischs unsicherer ist als die von reinem CO₂, gilt ein Sicherheitsabstand von ±3 bar (Modellvergleich, Dokumentation Kap. 9).
B8: Zusammensetzung (mol-%) | F8: Kennpunkte der Phasengrenze
B9: Komponente | C9: mol-% | D9: Beleg | F9: Kennpunkt | G9: T [°C] | H9: p [bar] | I9: reines CO₂ | J9: Bedeutung
B10: CO₂ | C10: 95 | D10: DIN EN 18397 / ISO 27913 | F10: Kritischer Punkt | G10: 27.954721 | H10: 81.455056 | I10: 31,0 °C / 73,8 bar | J10: Tau- und Blasenlinie treffen sich
B11: N₂ | C11: 2.4 | D11: Porthos-Grenzwert | F11: Cricondenbar | G11: 27.213118 | H11: 82.177594 | I11: = krit. Punkt | J11: darüber bei jeder Temperatur einphasig
B12: Ar | C12: 1 | D12: ca. Oxyfuel-Zusammensetzung | F12: Cricondentherm | G12: 28.093324 | H12: 80.896474 | I12: = krit. Punkt | J12: darüber bei jedem Druck einphasig
B13: CH₄ | C13: 1 | D13: Porthos-Grenzwert
B14: H₂ | C14: 0.5 | D14: DIN EN 18397 / DVGW C 260 | F14: Unsicherheit der Phasengrenze | H14: 3 | I14: bar | J14: Dokumentation Kap. 9: Modellstreuung 1 bar + Modellfehler 1–3 %
B15: CO | C15: 0.1 | D15: DIN EN 18397 (1000 ppm) | F15: Blasendruck bei T_K | G15: 20 | H15: 76.650851 | I15: 57,3 (p_sat) | J15: darüber vollständig flüssig
B16: Σ Begleitstoffe | C16: =SUM(C11:C15) -> 5 | D16: = Grenze DIN EN 18397 | F16: Taudruck bei T_K | G16: 20 | H16: 63.370088 | I16: 57,3 (p_sat) | J16: darunter vollständig gasförmig
B18: Tau- und Blasendruck über der Temperatur
B19: T [°C] | C19: p_sat reines CO₂ [bar] | D19: Taudruck Gemisch [bar] | E19: Blasendruck Gemisch [bar] | F19: sicher gasförmig unter [bar] | G19: sicher flüssig über [bar]
B20: -50 | C20: 6.8234161 | D20: 7.2245097 | E20: 48.12601 | F20: =D20-U_PG -> 4.2245097 | G20: =E20+U_PG -> 51.12601
B21: -40 | C21: 10.044957 | D21: 10.657067 | E21: 46.018104 | F21: =D21-U_PG -> 7.6570674 | G21: =E21+U_PG -> 49.018104
B22: -30 | C22: 14.277617 | D22: 15.186693 | E22: 46.414444 | F22: =D22-U_PG -> 12.186693 | G22: =E22+U_PG -> 49.414444
B23: -20 | C23: 19.69628 | D23: 21.019382 | E23: 48.909095 | F23: =D23-U_PG -> 18.019382 | G23: =E23+U_PG -> 51.909095
B24: -10 | C24: 26.486767 | D24: 28.387878 | E24: 53.310212 | F24: =D24-U_PG -> 25.387878 | G24: =E24+U_PG -> 56.310212
B25: 0 | C25: 34.851408 | D25: 37.573277 | E25: 59.51839 | F25: =D25-U_PG -> 34.573277 | G25: =E25+U_PG -> 62.51839
B26: 5 | C26: 39.694653 | D26: 42.961015 | E26: 63.272176 | F26: =D26-U_PG -> 39.961015 | G26: =E26+U_PG -> 66.272176
B27: 10 | C27: 45.021829 | D27: 48.964344 | E27: 67.428739 | F27: =D27-U_PG -> 45.964344 | G27: =E27+U_PG -> 70.428739
B28: 15 | C28: 50.871474 | D28: 55.683743 | E28: 71.932696 | F28: =D28-U_PG -> 52.683743 | G28: =E28+U_PG -> 74.932696
B29: 20 | C29: 57.290526 | D29: 63.370088 | E29: 76.650851 | F29: =D29-U_PG -> 60.370088 | G29: =E29+U_PG -> 79.650851
B30: 25 | C30: 64.342443 | D30: 72.32523 | E30: 81.055196 | F30: =D30-U_PG -> 69.32523 | G30: =E30+U_PG -> 84.055196
B31: 27 | C31: 67.361486 | D31: 76.817923 | E31: 82.152582 | F31: =D31-U_PG -> 73.817923 | G31: =E31+U_PG -> 85.152582
B32: Unter −56,6 °C bildet sich Trockeneis (nicht im Modell). Oberhalb von 28,1 °C gibt es beim Gemisch kein Zweiphasengebiet mehr.
B34: Neue Grenzen der Einspeicherung – wo sie sich ergeben
B35: Grenze | D35: reines CO₂ | E35: Gemisch | F35: Folge für die Anlage | G35: Blatt
B36: Mindestdruck dichte Anlieferung bei 15 °C | D36: 50,9 bar | E36: 71,9 + 3 bar | F36: S1 mit 91 bar sicher dicht (8,8 bar über der Cricondenbar) | G36: Einspeicherung S1
B37: Enddruck Verdichtung = Kühlerdruck bei 20 °C | D37: > 57,3 bar (gewählt 60, verflüssigen) | E37: ≥ 85,2 bar (gewählt 90) | F37: über der Cricondenbar kühlen: kein Zweiphasengebiet, Gemisch wird stetig dicht | G37: Einspeicherung S2
B38: Verdichtung 30 bar → p_V in einer Stufe | D38: 73,2 °C ✔ | E38: 111,6 °C ✘ (> 95 °C) | F38: zwei Verdichterstufen mit Zwischenkühlung nötig | G38: Einspeicherung S2
B39: Zwischendruck (gasförmig bei 20 °C) | D39: < 57,3 bar | E39: ≤ 60,4 bar | F39: zulässig ca. 48–60 bar (95-°C-Grenze Stufe 2) | G39: Einspeicherung S2
B40: Kopfdruck bei voller Kaverne | D40: 107,6 bar | E40: 114,9 bar | F40: Pumpe muss 7,3 bar mehr liefern; Gemisch ist leichter | G40: Kaverne & Gassäule
B41: Bohrloch ganz einphasig (Grenzfall) | D41: Kopf ≥ 73,8 bar (p_krit) | E41: Kopf ≥ 82,2 bar (Cricondenbar) | F41: Kavernendruck ab 171,2 bar (rein: 171,7 bar) | G41: Kaverne & Gassäule
B42: Leere Kaverne (70 bar unten) | D42: Kopf 45,0 bar, 0–236 m zweiphasig | E42: Kopf 50,7 bar, 0–82 m zweiphasig | F42: Zweiphasengebiet im oberen Bohrloch kleiner, aber vorhanden | G42: Kaverne & Gassäule
B43: Kritische Temperatur | D43: 31,0 °C | E43: 28,0 °C | F43: Kühlung unter 28 °C nötig, sonst ist das Gemisch vor der Pumpe überkritisch | G43: Einspeicherung S2
B44: Dichte am Kavernenboden (210 bar, 46 °C) | D44: 817,6 kg/m³ | E44: 756,0 kg/m³ | F44: -7,5 % Masse je m³ Kavernenvolumen | G44: Kaverne & Gassäule
...

Sheet Kaverne & Gassäule
B1: Kaverne & Gassäule – welcher Druck muss am Bohrlochkopf anliegen?
B2: Einspeicherung, Kaverne V1 (tief) · Stillstand: Temperatur = Gebirgstemperatur · Worst-Case-Gemisch
B3: ← zur Übersicht
B4: WAS WIRD BERECHNET? Die Kaverne legt fest, welcher Druck unten an der LCCS (letzte zementierte Rohrtour) höchstens anliegen darf: 210 bar. Gesucht ist der Druck, den die Anlage dafür oben am Bohrlochkopf liefern muss. WARUM? Zwischen Kopf und Kaverne steht eine 1200 m hohe Säule aus dem CO₂-Gemisch. Ihr Gewicht erhöht den Druck nach unten: dp/dz = ρ(p,T) · g. WIE WIRD GERECHNET? Die Dichte ρ hängt selbst von Druck und Temperatur ab – deshalb wird die Säule in 600 Schritten à 2 m gerechnet, in jedem Schritt mit neuer Dichte aus CoolProp (Gemisch). Temperatur = Gebirgstemperatur T(z) = T₀ + grad T · z (Stillstand). Gerechnet wird von unten (bekannter Kavernendruck) nach oben – das Ergebnis ist direkt der Kopfdruck. GRENZFALL: Mit dem Sekantenverfahren wird der Kavernendruck gesucht, bei dem der Kopfdruck genau die Cricondenbar des Gemischs ist (82,2 bar = höchster Druck des Zweiphasengebiets; bei reinem CO₂ war es p_krit = 73,8 bar). Darüber bleibt das ganze Bohrloch einphasig, darunter kann sich im oberen Bohrloch eine Gasphase bilden. ERGEBNIS: Für 210 bar unten sind 114,9 bar am Kopf nötig – die Säule liefert rund 95 bar (reines CO₂: 107,6 bar bzw. 102 bar). Das Gemisch ist leichter, deshalb muss die Anlage oben mehr Druck aufbringen.
B6: Kavernenparameter
B7: Größe | C7: Kaverne V1 (tief) | D7: Kaverne V2 (flach) | E7: Einheit
B8: Teufe (LCCS) | C8: =z_V1 -> 1200 | E8: m
B9: Gebirgstemperatur Oberfläche | C9: =Tober_V1 -> 10 | E9: °C
B10: Geothermischer Gradient | C10: =grad_V1 -> 0.03 | E10: K/m
B11: Kavernentemperatur | C11: =T_Kav_V1 -> 46 | E11: °C
B12: Maximaldruck an der LCCS | C12: =pmax_V1 -> 210 | E12: bar
B13: Minimaldruck an der LCCS | C13: =pmin_V1 -> 70 | E13: bar
B14: Werte kommen von der Übersicht. Spalte V2 bleibt frei, bis die flache Kaverne festgelegt ist.
B16: Ergebnis: drei Füllstände der Kaverne
B17: Fall | C17: Druck unten (LCCS) [bar] | D17: Kopfdruck [bar] | E17: T am Kopf [°C] | F17: ρ Kopf [kg/m³] | G17: ρ unten [kg/m³] | H17: Säulengewinn [bar] | I17: Bedeutung
B18: voll (p_max) | C18: 210 | D18: 114.9313 | E18: 10 | F18: 865.00462 | G18: 755.95384 | H18: =C18-D18 -> 95.068698 | I18: Zieldruck für die Einspeicherung
B19: Grenzfall | C19: 171.19473 | D19: 82.177594 | E19: 10 | F19: 825.29682 | G19: 695.90622 | H19: =C19-D19 -> 89.017136 | I19: Kopfdruck = Cricondenbar (82,2 bar): ab hier ist das Bohrloch ganz einphasig
B20: leer (p_min) | C20: 70 | D20: 50.705459 | E20: 10 | F20: 208.63402 | G20: 166.94226 | H20: =C20-D20 -> 19.294541 | I20: Kopf 50,7 bar → zweiphasig 0–82 m (reines CO₂: 45,0 bar, 0–236 m)
B22: Diagramme – Darstellung nach Buzogany & Kruck (2022), Fig. 3 (dort 1150 m Teufe, hier Kaverne V1 mit 1200 m)
B23: HIER ZUM STILLSTAND: Die Gassäulen gelten für ruhendes CO₂ mit Gebirgstemperatur und für die drei Füllstände nach Q-028 (Buzogany & Kruck 2022, Fig. 3: voll, Grenzfall, leer). Was Injektion und Ausspeicherung für das Fenster bedeuten (Reibungsdruckverlust im Strang, Wärmeaustausch mit dem Gebirge, Erwärmung bzw. Abkühlung in der Kaverne, Drosselung beim Ausspeichern), ist hier NICHT dargestellt.
B47: Tiefenprofile (gerechnet in 2-m-Schritten, dargestellt alle 50 m)
B48: Teufe z [m] | C48: T [°C] | D48: p voll [bar] | E48: ρ voll [kg/m³] | F48: p Grenzfall [bar] | G48: ρ Grenzfall [kg/m³] | H48: p leer [bar] | I48: ρ leer [kg/m³]
B49: 0 | C49: 10 | D49: 114.9313 | E49: 865.00462 | F49: 82.177594 | G49: 825.29682 | H49: 50.705459 | I49: 208.63402
B50: 50 | C50: 11.5 | D50: 119.16101 | E50: 859.85865 | F50: 86.209692 | G50: 819.03601 | H50: 51.65963 | I50: 180.45339
B51: 100 | C51: 13 | D51: 123.36557 | E51: 854.75081 | F51: 90.211177 | G51: 812.81436 | H51: 52.470045 | I51: 158.26745
B52: 150 | C52: 14.5 | D52: 127.54518 | E52: 849.68334 | F52: 94.182258 | G52: 806.63793 | H52: 53.247139 | I52: 158.58157
B53: 200 | C53: 16 | D53: 131.70005 | E53: 844.65845 | F53: 98.123172 | G53: 800.51281 | H53: 54.025824 | I53: 158.91436
B54: 250 | C54: 17.5 | D54: 135.83037 | E54: 839.67828 | F54: 102.03419 | G54: 794.4451 | H54: 54.806181 | I54: 159.26271
B55: 300 | C55: 19 | D55: 139.93639 | E55: 834.74497 | F55: 105.9156 | G55: 788.4408 | H55: 55.588282 | I55: 159.62407
B56: 350 | C56: 20.5 | D56: 144.01834 | E56: 829.86064 | F56: 109.76773 | G56: 782.50579 | H56: 56.372183 | I56: 159.9963
B57: 400 | C57: 22 | D57: 148.07646 | E57: 825.0274 | F57: 113.59095 | G57: 776.64564 | H57: 57.157934 | I57: 160.37761
B58: 450 | C58: 23.5 | D58: 152.111 | E58: 820.24733 | F58: 117.38562 | G58: 770.86559 | H58: 57.945576 | I58: 160.76647
B59: 500 | C59: 25 | D59: 156.12224 | E59: 815.52247 | F59: 121.15215 | G59: 765.17044 | H59: 58.735141 | I59: 161.1616
B60: 550 | C60: 26.5 | D60: 160.11045 | E60: 810.85475 | F60: 124.89098 | G60: 759.56449 | H60: 59.526657 | I60: 161.5619
... B73: 1200 | C73: 46 | D73: 210 | E73: 755.95384 | F73: 171.19473 | G73: 695.90622 | H73: 70 | I73: 166.94226
B74: Schraffierte Felder: Zweiphasengebiet des Gemischs (Q-028: „multiphase region“). Beim leeren Fall liegt das Bohrloch von 0 bis ca. 82 m zwischen Tau- und Blasenlinie. Anders als bei reinem CO₂ ist der Druck dort nicht auf eine Linie festgelegt – ein Gemisch verdampft über ein Druckband. Die Dichte ist die Gleichgewichtsdichte bei homogen verteilten Phasen; im Stillstand würden sich Gas und Flüssigkeit trennen, die Werte sind dort Richtwerte.
B76: Hinweis: Das Arbeitsgas (nutzbare CO₂-Menge zwischen voll und leer) wird bewusst erst später betrachtet.

Sheet Medienvergleich
B1: Medienvergleich – warum CO₂ oben weniger Druck braucht
B2: Gleiche Kaverne (Ziel 210 bar unten, Gebirge 10 °C + 0,03 K/m), gleiche Rechnung – nur das Medium ist anders
B3: ← zur Übersicht
B4: IDEE: Je schwerer die Säule im Bohrloch, desto mehr Druck liefert sie und desto weniger muss die Anlage oben aufbringen. Das CO₂-Gemisch ist unter diesen Bedingungen dicht (756–865 kg/m³; reines CO₂ 820–930 kg/m³), Erdgas und Wasserstoff bleiben Gase (Erdgas ~150 kg/m³, Wasserstoff ~15 kg/m³). FOLGE: Für das CO₂-Gemisch reicht eine Pumpe auf ~115 bar (reines CO₂ ~108 bar). Erdgas- und Wasserstoffspeicher brauchen Verdichter fast bis zum vollen Kavernendruck. Rechnung wie auf Blatt „Kaverne & Gassäule“: dp/dz = ρ(p,T) · g, von unten nach oben, Dichte aus CoolProp (CO₂: Worst-Case-Gemisch, Methan als Erdgas-Ersatz, reiner Wasserstoff). Der Zieldruck unten bleibt für alle Teufen bewusst bei 210 bar, damit nur der Effekt der Säule sichtbar wird.
B6: 1) Nötiger Kopfdruck über der Teufe (210 bar unten)
B7: Teufe [m] | C7: CO₂-Gemisch [bar] | D7: Erdgas CH₄ [bar] | E7: Wasserstoff H₂ [bar] | F7: Ziel unten [bar]
B8: 600 | C8: 158.49008 | D8: 200.16601 | E8: 209.09501 | F8: =pmax_V1 -> 210
B9: 800 | C9: 142.98603 | D9: 197.20927 | E9: 208.805 | F9: =pmax_V1 -> 210
B10: 1000 | C10: 128.4373 | D10: 194.39268 | E10: 208.52047 | F10: =pmax_V1 -> 210
B11: 1200 | C11: 114.9313 | D11: 191.70534 | E11: 208.24119 | F11: =pmax_V1 -> 210
B12: 1400 | C12: 102.56219 | D12: 189.13736 | E12: 207.96699 | F12: =pmax_V1 -> 210
B13: 1600 | C13: 91.42468 | D13: 186.67971 | E13: 207.69769 | F13: =pmax_V1 -> 210
B14: CO₂-Gemisch: 67 bar weniger Kopfdruck zwischen 600 und 1600 m (reines CO₂: 74 bar) – Erdgas und Wasserstoff profitieren kaum von der Teufe.
B16: 2) Kennzahlen bei 1200 m Teufe
B17: Medium | C17: Kopfdruck [bar] | D17: Säulengewinn [bar] | E17: ρ Kopf [kg/m³] | F17: ρ unten [kg/m³] | G17: Übertagetechnik
B18: CO₂-Gemisch | C18: 114.9313 | D18: =pmax_V1-C18 -> 95.068698 | E18: 865.00462 | F18: 755.95384 | G18: Pumpe (91 → 115 bar)
B19: Erdgas (CH₄) | C19: 191.70534 | D19: =pmax_V1-C19 -> 18.294657 | E19: 167.47194 | F19: 145.17947 | G19: Verdichter bis ~192 bar
B20: Wasserstoff (H₂) | C20: 208.24119 | D20: =pmax_V1-C20 -> 1.7588088 | E20: 15.728831 | F20: 14.210688 | G20: Verdichter bis ~208 bar
B21: Bei Erdgas und Wasserstoff ist die Dichte unten kleiner als oben: der Temperaturanstieg überwiegt den Druckanstieg.
B23: 3) Druck- und Dichteprofile über die Teufe (Kaverne V1, 1200 m – gerechnet in 2-m-Schritten, dargestellt alle 50 m)
B24: Teufe z [m] | C24: p CO₂-Gemisch [bar] | D24: ρ CO₂-Gemisch [kg/m³] | E24: p CH₄ [bar] | F24: ρ CH₄ [kg/m³] | G24: p H₂ [bar] | H24: ρ H₂ [kg/m³]
B25: 0 | C25: 114.9313 | D25: 865.00462 | E25: 191.70534 | F25: 167.47194 | G25: 208.24119 | H25: 15.728831
B26: 50 | C26: 119.16101 | D26: 859.85865 | E26: 192.5238 | F26: 166.30248 | G26: 208.31816 | H26: 15.658526
B27: 100 | C27: 123.36557 | D27: 854.75081 | E27: 193.33659 | F27: 165.15879 | G27: 208.39479 | H27: 15.588903
B28: 150 | C28: 127.54518 | D28: 849.68334 | E28: 194.14383 | F28: 164.0401 | G28: 208.47108 | H28: 15.519951
B29: 200 | C29: 131.70005 | D29: 844.65845 | E29: 194.94564 | F29: 162.94567 | G29: 208.54703 | H29: 15.451659
B30: 250 | C30: 135.83037 | D30: 839.67828 | E30: 195.74215 | F30: 161.87476 | G30: 208.62264 | H30: 15.384018
B31: 300 | C31: 139.93639 | D31: 834.74497 | E31: 196.53346 | F31: 160.82667 | G31: 208.69793 | H31: 15.317018
B32: 350 | C32: 144.01834 | D32: 829.86064 | E32: 197.31969 | F32: 159.80073 | G32: 208.77289 | H32: 15.25065
B33: 400 | C33: 148.07646 | D33: 825.0274 | E33: 198.10094 | F33: 158.79625 | G33: 208.84753 | H33: 15.184904
B34: 450 | C34: 152.111 | D34: 820.24733 | E34: 198.87732 | F34: 157.81261 | G34: 208.92184 | H34: 15.119771
B35: 500 | C35: 156.12224 | D35: 815.52247 | E35: 199.64893 | F35: 156.84918 | G35: 208.99584 | H35: 15.055243
B36: 550 | C36: 160.11045 | D36: 810.85475 | E36: 200.41586 | F36: 155.90536 | G36: 209.06952 | H36: 14.99131
... B49: 1200 | C49: 210 | D49: 755.95384 | E49: 210 | F49: 145.17947 | G49: 210 | H49: 14.210688
B50: Gleiche Rechnung wie auf Blatt „Kaverne & Gassäule“ (Fall voll): von 210 bar unten nach oben integriert, Gebirge 10 °C + 0,03 K/m.

Sheet Einspeicherung S1
B1: Einspeicherung S1 – Anlieferung in dichter Phase: Pumpe (Worst-Case-Gemisch)
B2: Netzübergabe → Messtechnik/Filtration → Pumpe → Bohrlochkopf
B3: ← zur Übersicht
B4: AUSGANGSLAGE: Das CO₂-Gemisch kommt dicht (flüssigkeitsähnlich) aus der Fernleitung: 91 bar, 15 °C. Es liegt 19 bar über der Blasenlinie und 8,8 bar über der Cricondenbar – sicher außerhalb der Unsicherheit der Phasengrenze (±3 bar). ZIEL: 114,9 bar am Bohrlochkopf – vorgegeben durch die Kaverne (Blatt „Kaverne & Gassäule“). WARUM EINE PUMPE? Das Gemisch ist bereits dicht und kaum kompressibel. Eine Pumpe genügt, ein Verdichter wäre nur für Gas nötig. RECHENWEG: (1) Zustand am Eintritt → Enthalpie h₁, Entropie s₁. (2) Idealfall: isentrope Druckerhöhung (Entropie bleibt gleich) → h₂s. (3) Realfall mit Verlusten über den isentropen Wirkungsgrad: h₂ = h₁ + (h₂s − h₁) / η. (4) Aus p₂ und h₂ → Austrittstemperatur T₂. (5) Spezifische Arbeit w = h₂ − h₁, Leistung P = ṁ · w. BEGRIFF: isentrop = Entropie konstant (Pumpe, Verdichter). Nicht verwechseln mit isenthalp = Enthalpie konstant (Drossel bei der Ausspeicherung). ANNAHMEN: η = 0,80 (eigene Annahme, vgl. Q-016: Verdichter 84–76 %, Glykolpumpe 70 %); kein Druckverlust in Messtechnik und Filtration; Worst-Case-Gemisch (Enthalpien haben einen anderen Nullpunkt als bei reinem CO₂ – vergleichbar sind nur Differenzen).
B6: Rechenschritte
B7: Nr. | C7: Rechenschritt | D7: Formel / Funktion | E7: Wert | F7: Einheit | G7: Art des Werts
B8: 1 | C8: Eintrittsdruck | D8: = Übergabedruck S1 | E8: =p_S1 -> 91 | F8: bar | G8: aus anderem Blatt
B9: 2 | C9: Eintrittstemperatur | D9: = Übergabetemperatur S1 | E9: =T_S1 -> 15 | F9: °C | G9: aus anderem Blatt
B10: 3 | C10: Enthalpie Eintritt h₁ | D10: CoolProp: H(p₁, T₁) | E10: 246.62641 | F10: kJ/kg | G10: CoolProp (fest)
B11: 4 | C11: Entropie Eintritt s₁ | D11: CoolProp: S(p₁, T₁) | E11: 1.2726354 | F11: kJ/(kg·K) | G11: CoolProp (fest)
B12: 5 | C12: Austrittsdruck p₂ (= Kopfdruck) | D12: aus Blatt „Kaverne & Gassäule“ | E12: =Kopf_voll -> 114.9313 | F12: bar | G12: aus anderem Blatt
B13: 6 | C13: Enthalpie isentrop h₂s | D13: CoolProp: H(p₂, s = s₁) | E13: 249.60522 | F13: kJ/kg | G13: CoolProp (fest)
B14: 7 | C14: Isentroper Wirkungsgrad η | D14: Annahme (Übersicht) | E14: =eta -> 0.8 | F14: – | G14: aus anderem Blatt
B15: 8 | C15: Enthalpie real h₂ | D15: h₂ = h₁ + (h₂s − h₁) / η | E15: =Szen1_h1+(Szen1_h2s-Szen1_h1)/eta -> 250.34992 | F15: kJ/kg | G15: Excel-Formel
B16: 9 | C16: Austrittstemperatur T₂ | D16: CoolProp: T(p₂, h₂) | E16: 18.395619 | F16: °C | G16: CoolProp (fest)
B17: 10 | C17: Phase am Austritt | D17: CoolProp: Phase(p₂, h₂) | E17: dicht (flüssig) | F17: – | G17: CoolProp (fest)
B18: 11 | C18: Spezifische Arbeit w | D18: w = h₂ − h₁ | E18: =Szen1_h2-Szen1_h1 -> 3.7235121 | F18: kJ/kg | G18: Ergebnis (Formel)
B19: 12 | C19: Normdichte Gemisch (0 °C; 1,01325 bar) | D19: CoolProp: D(p_n, T_n), DIN 1343 | E19: 1.934285 | F19: kg/m³ | G19: CoolProp (fest)
B20: 13 | C20: Massenstrom, unterer Fall | D20: ṁ = V_n,min · ρ_n / 3600 | E20: =V_min*rho_n/3600 -> 26.865069 | F20: kg/s | G20: Excel-Formel
B21: 14 | C21: Massenstrom, oberer Fall | D21: ṁ = V_n,max · ρ_n / 3600 | E21: =V_max*rho_n/3600 -> 53.730139 | F21: kg/s | G21: Excel-Formel
B22: 15 | C22: Pumpenleistung, unterer Fall | D22: P = ṁ · w | E22: =Szen1_mmin*Szen1_w -> 100.03241 | F22: kW | G22: Ergebnis (Formel)
B23: 16 | C23: Pumpenleistung, oberer Fall | D23: P = ṁ · w | E23: =Szen1_mmax*Szen1_w -> 200.06482 | F23: kW | G23: Ergebnis (Formel)
B24: Wird η auf der Übersicht geändert, rechnen h₂, w und P sofort mit. T₂ kommt aus CoolProp und färbt sich dann rot (veraltet).
B26: Zustandspunkte
C27: Punkt | D27: p [bar] | E27: T [°C] | F27: h [kJ/kg] | G27: Phase
C28: Netzübergabe / Pumpe ein | D28: 91 | E28: 15 | F28: 246.62641 | G28: dicht (flüssig)
C29: Pumpe aus / Bohrlochkopf | D29: 114.9313 | E29: 18.395619 | F29: 250.34992 | G29: dicht (flüssig)

Sheet Einspeicherung S2
B1: Einspeicherung S2 – gasförmige Anlieferung: verdichten, dicht kühlen, pumpen (Worst-Case-Gemisch)
B2: Netzübergabe → Messtechnik/Filtration → Verdichter → Kühler (dicht) → Pumpe → Bohrlochkopf
B3: ← zur Übersicht
B4: AUSGANGSLAGE: Das CO₂-Gemisch kommt gasförmig an: 30 bar, 15 °C (Annahme). Q-016: Bielka, Kuczyński, Nagy (2023): CO₂ Compression and Dehydration for Transport and Geological Storage. Energies 16, 1804 (AGH Krakau). Übersichtsarbeit zu Abscheidung, Trocknung, Transport und Speicherstandortwahl – plus eine eigene Prozesssimulation (BR&E ProMax, Peng-Robinson): CO₂ aus einer Rauchgasabscheidung (1,51 bar, 35 °C, 2,45 Mio. t/a ≈ 78 kg/s) wird in 5 Stufen auf 100 bar verdichtet, mit TEG getrocknet und auf 20 °C gekühlt – flüssig für den Pipelinetransport zu einer Speicherstätte in 30 km Entfernung (S. 5: 74 bar sind das Minimum, üblich 100 bar als Reserve für Druckverluste). Annahmen aus Q 16 (S. 4, Kap. 2.3): Kühlung auf 20 °C nach jeder Stufe · höchstens 95 °C nach jeder Stufe · Wirkungsgrad 84 % in Stufe 1, je weitere Stufe −2 % · zum Schluss Kühlung auf 20 °C → flüssig. Q-016 verdichtet für die Pipeline, hier für den Bohrlochkopf – das Druckniveau (100 bzw. 114,9 bar) und der Massenstrom (78 bzw. 27–54 kg/s) sind vergleichbar. NICHT übernommen: 45 bar Zwischendruck (für die TEG-Trocknung gewählt, Glykol schließt OGE aus). NEUE VERDICHTUNG BEIM GEMISCH: Reines CO₂ wird bei 60 bar und 20 °C verflüssigt (Dampfdruck 57,3 bar). Das Gemisch hat bei 20 °C ein Zweiphasengebiet von 63,4 bar (Taulinie) bis 76,7 bar (Blasenlinie) – bei 60 bar bliebe es gasförmig (alte Verdichtung, Blatt „Gemisch & Grenzen“). Deshalb wird über die Cricondenbar (82,2 bar = höchster Druck des Zweiphasengebiets) + 3 bar Unsicherheit verdichtet: p_V = 90 bar. Dort kühlt der Kühler von der Verdichteraustrittstemperatur auf 20 °C, ohne das Zweiphasengebiet zu berühren – das Gemisch geht stetig in die dichte Phase über, es wird nichts kondensiert (wie Q-016: Endstufe 100 bar, dann 20 °C). Danach bringt die Pumpe das dichte Gemisch auf 114,9 bar. ZAHL DER STUFEN: Eine Stufe bis 90 bar erreicht 111,6 °C und überschreitet die 95-°C-Grenze aus Q-016 (reines CO₂ bis 60 bar: 73,2 °C). Die zweistufige Variante unten ist deshalb Pflicht – sie spart außerdem 13% Arbeit. RECHENWEG: Verdichter und Pumpe wie in S1: isentrop + Wirkungsgrad, h_aus = h_ein + (h_s − h_ein) / η. Kühler: abgeführte Wärme je kg q = h_vor − h_nach. GRENZEN: 20 °C setzen Kühlwasser voraus. Mit Luftkühlung (ca. 35 °C) läge die Kühltemperatur über der kritischen Temperatur des Gemischs (28,0 °C): das Gemisch wäre dann vor der Pumpe überkritisch und deutlich weniger dicht.
B6: Rechenschritte
B7: Nr. | C7: Rechenschritt | D7: Formel / Funktion | E7: Wert | F7: Einheit | G7: Art des Werts
B8: Verdichter
B9: 1 | C9: Eintrittsdruck | D9: = Übergabe S2 | E9: =p_S2 -> 30 | F9: bar | G9: aus anderem Blatt
B10: 2 | C10: Eintrittstemperatur | D10: = Übergabe S2 | E10: =T_S2 -> 15 | F10: °C | G10: aus anderem Blatt
B11: 3 | C11: Austrittsdruck = Kühlerdruck p_V | D11: Annahme (Übersicht) | E11: =p_verfl -> 90 | F11: bar | G11: aus anderem Blatt
B12: 4 | C12: Enthalpie Eintritt | D12: CoolProp: H(p, T) | E12: 460.1284 | F12: kJ/kg | G12: CoolProp (fest)
B13: 5 | C13: Wirkungsgrad η_V1 | D13: Annahme (Übersicht), Q-016 | E13: =eta_V1 -> 0.84 | F13: – | G13: aus anderem Blatt
B14: 6 | C14: Enthalpie isentrop bei p_V | D14: CoolProp: H(p_V, s₁) | E14: 516.92152 | F14: kJ/kg | G14: CoolProp (fest)
B15: 7 | C15: Enthalpie real Austritt | D15: h = h_ein + (h_s − h_ein) / η_V1 | E15: =Szen2_h1+(Szen2_h1s-Szen2_h1)/eta_V1 -> 527.73926 | F15: kJ/kg | G15: Excel-Formel
B16: 8 | C16: Austrittstemperatur | D16: CoolProp: T(p_V, h) | E16: 111.64303 | F16: °C | G16: CoolProp (fest)
B17: 9 | C17: Prüfung 95-°C-Grenze (Q-016) | D17: T_aus ≤ T_max ? | E17: =IF(Szen2_T1a<=T_maxV,"✔ eingehalten – eine Stufe reicht","⚠ überschritten – weitere Stufe nötig") -> ⚠ überschritten – weitere Stufe nötig | F17: – | G17: Excel-Formel
B18: 10 | C18: Spezifische Arbeit Verdichter | D18: w_V = h_aus − h_ein | E18: =Szen2_h1a-Szen2_h1 -> 67.610855 | F18: kJ/kg | G18: Ergebnis (Formel)
B19: Kühler (dichte Phase)
B20: 11 | C20: Cricondenbar Gemisch | D20: CoolProp: höchster Druck der Phasengrenze | E20: 82.177594 | F20: bar | G20: CoolProp (fest)
B21: 12 | C21: Abstand p_V − Cricondenbar | D21: muss ≥ 3 bar sein, dann kein Zweiphasengebiet beim Kühlen | E21: =p_verfl-Szen2_psatK -> 7.8224057 | F21: bar | G21: Excel-Formel
B22: 13 | C22: Blasendruck bei T_K | D22: CoolProp: p(Q = 0, T_K) – Taudruck 63,4 bar | E22: 76.650851 | F22: °C | G22: CoolProp (fest)
B23: 14 | C23: Enthalpie nach Kühler | D23: CoolProp: H(p_V, T_K) | E23: 263.11082 | F23: kJ/kg | G23: CoolProp (fest)
B24: 15 | C24: Phase nach Kühler | D24: CoolProp: Phase(p_V, T_K) | E24: dicht (flüssig) | F24: – | G24: CoolProp (fest) | I24: S2 (2 Stufen) braucht rund 17-mal so viel Arbeit wie S1 – und rund 14% weniger als Durchverdichten. Beim Gemisch ist die zweite Verdichterstufe Pflicht (1 Stufe: 111,6 °C > 95 °C) und spart gegenüber einer Stufe 13%.
B25: 16 | C25: Abgeführte Wärme | D25: q = h_vor − h_nach | E25: =Szen2_h1a-Szen2_hV -> 264.62844 | F25: kJ/kg | G25: Excel-Formel
B26: Pumpe
B27: 17 | C27: Wirkungsgrad Pumpe η_P | D27: Annahme (Übersicht) | E27: =eta -> 0.8 | F27: – | G27: aus anderem Blatt
B28: 18 | C28: Enthalpie isentrop bei Kopfdruck | D28: CoolProp: H(p_Kopf, s(p_V, T_K)) | E28: 266.42357 | F28: kJ/kg | G28: CoolProp (fest)
B29: 19 | C29: Enthalpie real Austritt | D29: h = h_ein + (h_s − h_ein) / η_P | E29: =Szen2_hV+(Szen2_hPs-Szen2_hV)/eta -> 267.25176 | F29: kJ/kg | G29: Excel-Formel
B30: 20 | C30: Austrittstemperatur | D30: CoolProp: T(p_Kopf, h) | E30: 24.356423 | F30: °C | G30: CoolProp (fest)
B31: 21 | C31: Spezifische Arbeit Pumpe | D31: w_P = h_aus − h_ein | E31: =Szen2_hPa-Szen2_hV -> 4.1409405 | F31: kJ/kg | G31: Ergebnis (Formel)
B32: Summe
B33: 22 | C33: Spezifische Arbeit gesamt | D33: w = w_V + w_P | E33: =Szen2_w1+Szen2_wP -> 71.751796 | F33: kJ/kg | G33: Ergebnis (Formel)
B34: 23 | C34: Antriebsleistung, unterer Fall | D34: P = ṁ_min · w | E34: =Szen1_mmin*Szen2_w_ges -> 1927.617 | F34: kW | G34: Ergebnis (Formel)
B35: 24 | C35: Antriebsleistung, oberer Fall | D35: P = ṁ_max · w | E35: =Szen1_mmax*Szen2_w_ges -> 3855.234 | F35: kW | G35: Ergebnis (Formel)
B36: 25 | C36: Kühlleistung Kühler, oberer Fall | D36: Q = ṁ_max · q_V | E36: =Szen1_mmax*Szen2_qV -> 14218.523 | F36: kW | G36: Ergebnis (Formel)
B37: Massenstrom wie in S1 (gleicher Normvolumenstrom). Wird η geändert, rechnen alle weißen Werte mit; graue Stoffwerte färben sich rot.
B39: Variante: zweistufige Verdichtung bis zum Kühlerdruck p_V (sonst wie Basisfall)
B40: AUFBAU: Stufe 1 30 → 52,0 bar, Zwischenkühlung auf 20 °C (das Gemisch bleibt gasförmig: Taudruck bei 20 °C = 63,4 bar), Stufe 2 → 90 bar. Zwischendruck mit gleichem Druckverhältnis in beiden Stufen: p_zw = √(p_ein · p_V). Wirkungsgrade 84 / 82 % (Q-016). Kühler und Pumpe wie im Basisfall. Beim Gemisch ist diese Variante Pflicht (95-°C-Grenze).
B41: Nr. | C41: Rechenschritt | D41: Formel / Funktion | E41: Wert | F41: Einheit | G41: Art des Werts
B42: Verdichter 1. Stufe
...

Sheet Phasendiagramm
B1: Phasendiagramm – Prozesspfade der Einspeicherung und Betriebsfenster von Bohrloch und Kaverne (Worst-Case-Gemisch)
B2: Worst-Case-Gemisch (95 % CO₂ + 5 % Begleitstoffe) · Stoffdaten CoolProp (GERG-2008-Mischungsregel) · Fest-Gebiet, Sublimations- und Schmelzlinie: Näherung reines CO₂ (Span & Wagner 1996)
B3: ← zur Übersicht
B4: Diagramm 1 – Einspeicherung: von der Netzübergabe bis zum Bohrlochkopf
B36: DIAGRAMM 1: Farbflächen = Phasengebiete des Gemischs, rot = Zweiphasengebiet (reines CO₂ hat nur eine Linie, grau zum Vergleich). Rot gestrichelt = ±3 bar Unsicherheit der Phasengrenze. Grün = S1 (Pumpe). Blau = S2 Basisfall (1 Stufe bis 90 bar, 111,6 °C > 95 °C, Kühler dicht auf 20 °C, Pumpe). Grau gestrichelt = alte Verdichtung wie reines CO₂ (60 bar) – bleibt beim Gemisch gasförmig, die Pumpe könnte nicht fördern. Hellblau gepunktet = S2-Variante mit 2 Stufen (beim Gemisch Pflicht). Violett gestrichelt = Durchverdichten (2 Stufen bis 114,9 bar, dann Nachkühler). ENDPUNKT: Alle Pfade enden am Bohrlochkopf bei 114,9 bar (reines CO₂: 107,6 bar). Diagramm 2 zeigt Bohrloch und Kaverne – nur im Stillstand.
B39: Diagramm 2 – Bohrloch und Kaverne im Stillstand: Betriebsfenster (nur Stillstand, 3 Füllstände nach Q-028)
B40: NUR STILLSTAND: Die Gassäulen gelten für ruhendes CO₂ mit Gebirgstemperatur und für die drei Füllstände nach Q-028 (Buzogany & Kruck 2022, Fig. 3: voll, Grenzfall, leer). Was Injektion und Ausspeicherung für das Fenster bedeuten (Reibungsdruckverlust im Strang, Wärmeaustausch mit dem Gebirge, Erwärmung bzw. Abkühlung in der Kaverne, Drosselung beim Ausspeichern), ist hier NICHT dargestellt.
B72: DIAGRAMM 2: Jede gestrichelte Linie ist eine Gassäule – ein Füllstand der Kaverne im Stillstand. Sie läuft vom Bohrlochkopf (grauer Balken, 0 m, 10 °C) bis zur Kaverne (dunkelblauer Balken, 1200 m, 46 °C). Jeder Punkt auf der Linie ist eine Teufe: oben kalt und niedriger Druck, unten warm und hoher Druck. BETRIEBSFENSTER IM STILLSTAND: Der Bereich zwischen der Linie „voll“ (oben) und der Linie „leer“ (unten), links begrenzt durch den Kopf-Balken und rechts durch den Kavernen-Balken. WICHTIG BEI LEERER KAVERNE: 70 bar unten ergeben oben 50,7 bar (reines CO₂: 45,0 bar). Das obere Bohrloch (0–82 m) liegt dann im Zweiphasengebiet des Gemischs. Erst ab ca. 171,2 bar Kavernendruck (Grenzfall: Kopf = Cricondenbar 82,2 bar) bleibt das ganze Bohrloch einphasig. KAVERNE SELBST: Bei 46 °C liegt sie immer über der Cricondentherm des Gemischs (28,1 °C) – dort gibt es keine Flüssigphase. Über 81,5 bar ist das Gemisch überkritisch, bei 70 bar gasförmig. STILLSTAND VS. BETRIEB: Die Gassäulen sind mit Gebirgstemperatur gerechnet (Kopf 10 °C) und gelten nur, solange nichts fließt. Beim Einspeichern kommt das Gemisch wärmer aus der Pumpe (S1 18,4 °C, S2 24,4 °C).

Sheet Quellen
B1: Quellen
B2: Herkunft der Annahmen und Stoffdaten dieser Mappe (IDs wie in der Quellen- und Wissensmatrix)
B3: ← zur Übersicht
B4: ID | C4: Quelle | D4: Verwendet für
B5: Q-001 | C5: DVGW (2024): C 260 (A) – Properties of Carbon Dioxide and Carbon Dioxide Streams. Entwurf. | D5: Kritischer Punkt, Stoffeigenschaften CO₂
B6: Q-016 | C6: Bielka, P.; Kuczyński, S.; Nagy, S.: CO₂ Compression and Dehydration for Transport and Geological Storage. | D6: Grundlage der S2-Kette (S. 4, Kap. 2.3): Kühlung auf 20 °C nach jeder Stufe, höchstens 95 °C nach jeder Stufe, Wirkungsgrad 84 % in Stufe 1 und je weitere Stufe −2 % (Vergleich Durchverdichten: Stufe 2 mit 82 %), zum Schluss Kühlung auf 20 °C → flüssig. Nicht übernommen: 45 bar Zwischendruck (dort für die TEG-Trocknung gewählt; OGE schließt Glykol aus). Für Pumpen nennt Q-016 nur eine Glykolpumpe (70 %) – η_P = 0,80 ist eigene Annahme.
B7: Q-028 | C7: Buzogany, R.; Kruck, O. (2022): CO₂ – Storage in Salt Caverns: Thermodynamic Analysis and Challenges. SMRI Fall 2022. | D7: Oberflächentemperatur 10 °C, Gradient 0,03 K/m, Minimaldruck 70 bar, Darstellung Gassäule (Fig. 3), Begriff „multiphase region“
B8: Q-029 | C8: DBI für Uniper: CCUS-P2 – CO₂-Storage for CCU/S, Phase 2 – Detailing Study, Final Report V08. | D8: Offener Punkt: gewählte Option 1 ist die tiefe Kaverne (1400 m, 260 bar)
B9: Q-030 | C9: DBI für Uniper: CCUS-P1 – CO₂-Storage for CCU/S, Phase 1 – Initial Concept Study, Final Report. | D9: Teufe 1200 m (Option 2), Anhalt für p_max; Option 3 (700 m) als Anhalt für Kaverne V2
B10: Q-038 | C10: Baumgärtel, L.; Körner, F.; Leuger, B.; Zapf, D. (2023): Energiespeicherung in Salzkavernen. Poster, Tag der Energieforschung, LU Hannover. | D10: Zu prüfen: alte Annahmentabelle leitet daraus p_max ≈ 85 % des lithostatischen Drucks ab – in der Matrix nur Geometriedaten erfasst
B11: Q-040 | C11: DIN EN ISO 27913: Abscheidung, Transport und geologische Speicherung von CO₂ – Rohrleitungstransportsysteme (dt. Fassung 2025). | D11: Zu prüfen: alte Annahmentabelle nennt Q-040 für die gasförmige Anlieferung mit 30 bar – Norm in der Matrix noch nicht ausgewertet
B12: OGE | C12: Gesprächsnotiz Austausch OGE / Uniper, 16.09.2026 (Notizen S. Maxara). | D12: Übergabedruck S1 mind. 91 bar; Durchsatz-Bandbreite (mit M. Wall)
B13: — | C13: Span, R.; Wagner, W. (1996): A New Equation of State for Carbon Dioxide Covering the Fluid Region from the Triple-Point Temperature to 1100 K at Pressures up to 800 MPa. J. Phys. Chem. Ref. Data 25(6), 1509–1596. | D13: Zustandsgleichung CO₂ (über CoolProp); Sublimations- und Schmelzdruck
B14: — | C14: Bell, I. H.; Wronski, J.; Quoilin, S.; Lemort, V. (2014): Pure and Pseudo-pure Fluid Thermophysical Property Evaluation and the Open-Source Thermophysical Property Library CoolProp. Ind. Eng. Chem. Res. 53(6), 2498–2508. | D14: Stoffdatenbibliothek CoolProp, Version 8.0.0
B15: Vorarbeit | C15: Python-Skripte der eigenen Vorarbeit (ObertageAnlageRechner: gaspfad_vergleich.py, pfadentscheidung.py). | D15: Nur noch der Übergabedruck S2 (30 bar) stammt aus der Vorarbeit – Quelle zu prüfen. Die früheren Annahmen (Zwischendruck 49 bar, 40 °C, Verflüssigung 80 bar / 25 °C) sind durch Q-016 ersetzt.
... B19: Doku | C19: Dokumentation_Stoffmodelle_Validierung.docx (eigene Arbeit): Gleichungen, Modellvergleich mit thermopack (GERG-2008, Peng-Robinson, SRK), Unsicherheit der Phasengrenze. | D19: Unsicherheit der Phasengrenze ±3 bar; Validierung der Stoffwerte

Sheet Diagrammdaten
B1: Diagrammdaten – Hilfstabellen (nicht ändern)
B2: Grundlage für das Phasendiagramm. Farbflächen: gestapelte Druckbereiche je Temperatur (Gemisch: gasförmig bis Taulinie, zweiphasig bis Blasenlinie, darüber flüssig; oberhalb des kritischen Punkts des Gemischs überkritisch; fest als Näherung reines CO₂). Linien: Punkte mit T, p und Position im Diagramm.
B3: ← zur Übersicht
B4: T_min [°C] | C4: -80 | D4: Position im Diagramm = (T − T_min) / Schritt + 1 (die Farbflächen haben eine Kategorie je 0,5 K)
B5: Schritt [K] | C5: 0.5
B7: T [°C] | C7: Achsenbeschriftung | D7: gasförmig [bar] | E7: flüssig [bar] | F7: überkritisch [bar] | G7: fest [bar] | H7: zweiphasig [bar] | I7: Linie / Punkt | J7: T [°C] | K7: p [bar] | L7: Position
B8: -80 | C8: =IF(MOD(B8,20)=0,TEXT(B8,"0"),"") -> -80 | D8: 0.89241568 | E8: 0 | F8: 0 | G8: 249.10758 | H8: 0 | I8: Phasengrenze Gemisch (Tau-/Blasenlinie) | J8: -56.558 | K8: 5.4780051 | L8: =(J8-Diagramm_Tmin)/Diagramm_dT+1 -> 47.884
B9: -79.5 | C9: =IF(MOD(B9,20)=0,TEXT(B9,"0"),"") | D9: 0.93029797 | E9: 0 | F9: 0 | G9: 249.0697 | H9: 0 | J9: -53.501973 | K9: 6.2465284 | L9: =(J9-Diagramm_Tmin)/Diagramm_dT+1 -> 53.996053
B10: -79 | C10: =IF(MOD(B10,20)=0,TEXT(B10,"0"),"") | D10: 0.96958837 | E10: 0 | F10: 0 | G10: 249.03041 | H10: 0 | J10: -50.445947 | K10: 7.0940267 | L10: =(J10-Diagramm_Tmin)/Diagramm_dT+1 -> 60.108107
B11: -78.5 | C11: =IF(MOD(B11,20)=0,TEXT(B11,"0"),"") | D11: 1.0103319 | E11: 0 | F11: 0 | G11: 248.98967 | H11: 0 | J11: -47.38992 | K11: 8.0255579 | L11: =(J11-Diagramm_Tmin)/Diagramm_dT+1 -> 66.22016
B12: -78 | C12: =IF(MOD(B12,20)=0,TEXT(B12,"0"),"") | D12: 1.0525749 | E12: 0 | F12: 0 | G12: 248.94743 | H12: 0 | J12: -44.333893 | K12: 9.046305 | L12: =(J12-Diagramm_Tmin)/Diagramm_dT+1 -> 72.332214
B13: -77.5 | C13: =IF(MOD(B13,20)=0,TEXT(B13,"0"),"") | D13: 1.0963649 | E13: 0 | F13: 0 | G13: 248.90364 | H13: 0 | J13: -41.277866 | K13: 10.16158 | L13: =(J13-Diagramm_Tmin)/Diagramm_dT+1 -> 78.444267
B14: -77 | C14: =IF(MOD(B14,20)=0,TEXT(B14,"0"),"") | D14: 1.1417507 | E14: 0 | F14: 0 | G14: 248.85825 | H14: 0 | J14: -38.22184 | K14: 11.376832 | L14: =(J14-Diagramm_Tmin)/Diagramm_dT+1 -> 84.556321
B15: -76.5 | C15: =IF(MOD(B15,20)=0,TEXT(B15,"0"),"") | D15: 1.1887825 | E15: 0 | F15: 0 | G15: 248.81122 | H15: 0 | J15: -35.165813 | K15: 12.697656 | L15: =(J15-Diagramm_Tmin)/Diagramm_dT+1 -> 90.668374
B16: -76 | C16: =IF(MOD(B16,20)=0,TEXT(B16,"0"),"") | D16: 1.2375117 | E16: 0 | F16: 0 | G16: 248.76249 | H16: 0 | J16: -32.109786 | K16: 14.129805 | L16: =(J16-Diagramm_Tmin)/Diagramm_dT+1 -> 96.780427
B17: -75.5 | C17: =IF(MOD(B17,20)=0,TEXT(B17,"0"),"") | D17: 1.2879913 | E17: 0 | F17: 0 | G17: 248.71201 | H17: 0 | J17: -29.05376 | K17: 15.679235 | L17: =(J17-Diagramm_Tmin)/Diagramm_dT+1 -> 102.89248
B18: -75 | C18: =IF(MOD(B18,20)=0,TEXT(B18,"0"),"") | D18: 1.3402755 | E18: 0 | F18: 0 | G18: 248.65972 | H18: 0 | J18: -25.997733 | K18: 17.352407 | L18: =(J18-Diagramm_Tmin)/Diagramm_dT+1 -> 109.00453
B19: -74.5 | C19: =IF(MOD(B19,20)=0,TEXT(B19,"0"),"") | D19: 1.3944201 | E19: 0 | F19: 0 | G19: 248.60558 | H19: 0 | J19: -22.941706 | K19: 19.155354 | L19: =(J19-Diagramm_Tmin)/Diagramm_dT+1 -> 115.11659
B20: -74 | C20: =IF(MOD(B20,20)=0,TEXT(B20,"0"),"") | D20: 1.4504823 | E20: 0 | F20: 0 | G20: 248.54952 | H20: 0 | J20: -19.885679 | K20: 21.0947 | L20: =(J20-Diagramm_Tmin)/Diagramm_dT+1 -> 121.22864
... B77: -45.5 | C77: =IF(MOD(B77,20)=0,TEXT(B77,"0"),"") | D77: 8.6457793 | E77: 203.17265 | F77: 0 | G77: 0 | H77: 38.181574 | J77: -56.558 | K77: 51.249179 | L77: =(J77-Diagramm_Tmin)/Diagramm_dT+1 -> 47.884
B78: -45 | C78: =IF(MOD(B78,20)=0,TEXT(B78,"0"),"") | D78: 8.8157704 | E78: 203.27988 | F78: 0 | G78: 0 | H78: 37.904345
B79: -44.5 | C79: =IF(MOD(B79,20)=0,TEXT(B79,"0"),"") | D79: 8.9882611 | E79: 203.38011 | F79: 0 | G79: 0 | H79: 37.631624 | I79: Sublimationslinie | J79: -80 | K79: 0.8924 | L79: =(J79-Diagramm_Tmin)/Diagramm_dT+1 -> 1
B80: -44 | C80: =IF(MOD(B80,20)=0,TEXT(B80,"0"),"") | D80: 9.1632748 | E80: 203.47344 | F80: 0 | G80: 0 | H80: 37.36329 | J80: -79.0232 | K80: 0.9677 | L80: =(J80-Diagramm_Tmin)/Diagramm_dT+1 -> 2.9536
B81: -43.5 | C81: =IF(MOD(B81,20)=0,TEXT(B81,"0"),"") | D81: 9.3408352 | E81: 203.55994 | F81: 0 | G81: 0 | H81: 37.099224 | J81: -78.0465 | K81: 1.0486 | L81: =(J81-Diagramm_Tmin)/Diagramm_dT+1 -> 4.907
B82: -43 | C82: =IF(MOD(B82,20)=0,TEXT(B82,"0"),"") | D82: 9.5209659 | E82: 203.63972 | F82: 0 | G82: 0 | H82: 36.839312 | J82: -77.0697 | K82: 1.1353 | L82: =(J82-Diagramm_Tmin)/Diagramm_dT+1 -> 6.8606
B83: -42.5 | C83: =IF(MOD(B83,20)=0,TEXT(B83,"0"),"") | D83: 9.7036908 | E83: 203.71287 | F83: 0 | G83: 0 | H83: 36.583442 | J83: -76.093 | K83: 1.2283 | L83: =(J83-Diagramm_Tmin)/Diagramm_dT+1 -> 8.814
B84: -42 | C84: =IF(MOD(B84,20)=0,TEXT(B84,"0"),"") | D84: 9.8890338 | E84: 203.77946 | F84: 0 | G84: 0 | H84: 36.331507 | J84: -75.1162 | K84: 1.328 | L84: =(J84-Diagramm_Tmin)/Diagramm_dT+1 -> 10.7676
B85: -41.5 | C85: =IF(MOD(B85,20)=0,TEXT(B85,"0"),"") | D85: 10.077019 | E85: 203.83958 | F85: 0 | G85: 0 | H85: 36.083399 | J85: -74.1395 | K85: 1.4346 | L85: =(J85-Diagramm_Tmin)/Diagramm_dT+1 -> 12.721
B86: -41 | C86: =IF(MOD(B86,20)=0,TEXT(B86,"0"),"") | D86: 10.26767 | E86: 203.89331 | F86: 0 | G86: 0 | H86: 35.839018 | J86: -73.1627 | K86: 1.5488 | L86: =(J86-Diagramm_Tmin)/Diagramm_dT+1 -> 14.6746
B87: -40.5 | C87: =IF(MOD(B87,20)=0,TEXT(B87,"0"),"") | D87: 10.461011 | E87: 203.94073 | F87: 0 | G87: 0 | H87: 35.598263 | J87: -72.186 | K87: 1.6709 | L87: =(J87-Diagramm_Tmin)/Diagramm_dT+1 -> 16.628
B88: -40 | C88: =IF(MOD(B88,20)=0,TEXT(B88,"0"),"") -> -40 | D88: 10.657067 | E88: 203.9819 | F88: 0 | G88: 0 | H88: 35.361037 | J88: -71.2092 | K88: 1.8014 | L88: =(J88-Diagramm_Tmin)/Diagramm_dT+1 -> 18.5816
B89: -39.5 | C89: =IF(MOD(B89,20)=0,TEXT(B89,"0"),"") | D89: 10.855863 | E89: 204.01689 | F89: 0 | G89: 0 | H89: 35.127245 | J89: -70.2325 | K89: 1.9408 | L89: =(J89-Diagramm_Tmin)/Diagramm_dT+1 -> 20.535
B90: -39 | C90: =IF(MOD(B90,20)=0,TEXT(B90,"0"),"") | D90: 11.057421 | E90: 204.04578 | F90: 0 | G90: 0 | H90: 34.896797 | J90: -69.2557 | K90: 2.0897 | L90: =(J90-Diagramm_Tmin)/Diagramm_dT+1 -> 22.4886
B91: -38.5 | C91: =IF(MOD(B91,20)=0,TEXT(B91,"0"),"") | D91: 11.261768 | E91: 204.06863 | F91: 0 | G91: 0 | H91: 34.669601 | J91: -68.279 | K91: 2.2485 | L91: =(J91-Diagramm_Tmin)/Diagramm_dT+1 -> 24.442
... B103: -32.5 | C103: =IF(MOD(B103,20)=0,TEXT(B103,"0"),"") | D103: 13.940533 | E103: 203.89231 | F103: 0 | G103: 0 | H103: 32.167156 | J103: -56.558 | K103: 5.1796 | L103: =(J103-Diagramm_Tmin)/Diagramm_dT+1 -> 47.884
B104: -32 | C104: =IF(MOD(B104,20)=0,TEXT(B104,"0"),"") | D104: 14.183352 | E104: 203.84158 | F104: 0 | G104: 0 | H104: 31.975072
B105: -31.5 | C105: =IF(MOD(B105,20)=0,TEXT(B105,"0"),"") | D105: 14.429454 | E105: 203.7855 | F105: 0 | G105: 0 | H105: 31.785049 | I105: Schmelzlinie | J105: -56.558 | K105: 5.1796 | L105: =(J105-Diagramm_Tmin)/Diagramm_dT+1 -> 47.884
B106: -31 | C106: =IF(MOD(B106,20)=0,TEXT(B106,"0"),"") | D106: 14.678659 | E106: 203.72411 | F106: 0 | G106: 0 | H106: 31.597231 | J106: -56.1931 | K106: 22.274 | L106: =(J106-Diagramm_Tmin)/Diagramm_dT+1 -> 48.6138
B107: -30.5 | C107: =IF(MOD(B107,20)=0,TEXT(B107,"0"),"") | D107: 14.931063 | E107: 203.65745 | F107: 0 | G107: 0 | H107: 31.411485 | J107: -55.8282 | K107: 39.4288 | L107: =(J107-Diagramm_Tmin)/Diagramm_dT+1 -> 49.3436
B108: -30 | C108: =IF(MOD(B108,20)=0,TEXT(B108,"0"),"") | D108: 15.186693 | E108: 203.58556 | F108: 0 | G108: 0 | H108: 31.227751 | J108: -55.4633 | K108: 56.644 | L108: =(J108-Diagramm_Tmin)/Diagramm_dT+1 -> 50.0734
...
