Workbook

Sheet Anlagenkonzept
A1: Anlagenkonzept: dualer Betrieb – dichte Phase (Hauptfall) und gasförmige Pipeline (Zusatzmodule)
A2: Alle Zustandspunkte aus co2_kaverne.py (CoolProp, Span-Wagner) – bei Änderung der Annahmen dort neu erzeugen. Szenario D beschreibt ZONE I; darunter siehe Zonentabelle unten.
A4: SZENARIO D – DICHTE PHASE (OGE-Pipeline 74–200 bar, 5–25 °C) – HAUPTFALL
A5: D1 Einspeichern
A6: Nr. | B6: Komponente / Ort | C6: p [bar] | D6: T [°C] | E6: Phase | F6: Anmerkung
A7: 1 | B7: Anlieferung OGE-Fernleitung | C7: 85 | D7: 15 | E7: dicht (flüssig) | F7: Spec 74–200 bar / 5–25 °C
A8: 2 | B8: nach Pumpe (mehrstufige Radialpumpe, η=0,8) | C8: 110.8 | D8: 17.9 | E8: dicht (flüssig) | F8: w = 3.66 kJ/kg; P = 101–201 kW; einspeicherseitig kein Kühler
A9: 3 | B9: Bohrloch abwärts – Übergang flüssig→überkritisch bei 533 m | C9: 111→210 | D9: 18→51 | E9: flüssig → überkritisch | F9: homogen, KEINE Phasengrenze
A10: 4 | B10: Kaverne (unten) | C10: 210 | D10: 51 | E10: überkritisch | F10: Betriebsbereich 70–210 bar
A12: D2 Ausspeichern
A13: Nr. | B13: Komponente / Ort | C13: p [bar] | D13: T [°C] | E13: Phase | F13: Anmerkung
A14: 1 | B14: Kaverne | C14: 210 | D14: 51 | E14: überkritisch | F14: identisch mit D1 – vorher inkonsistent (217 bar/56 °C)
A15: 2 | B15: Bohrlochkopf | C15: 120 | D15: 37.9 | E15: dicht (flüssig) | F15: AUSLEGUNG Nennrate (adiabat: h+g·z=konst.); Teillast bis ~15 °C
A16: 3 | B16: nach Drossel (Regelventil, 1 Stufe) | C16: 85 | D16: 32 | E16: dicht (flüssig) | F16: JT; über OGE-Spec (5–25 °C) → Nachkühler
A17: 4 | B17: Nachkühler (Standard-Equipment) | C17: 85 | D17: → ≤25 | E17: dicht (flüssig) | F17: 0.8–1.5 MW; hält OGE-Spec; bei Teillast ggf. Bypass
A18: 5 | B18: Rücklieferung OGE-Fernleitung | C18: 85 | D18: ≤25 | E18: dicht (flüssig) | F18: in Spec; Ende der Ausspeicherung: Pumpe boostet
A20: → ZONE I (pLCCS 167–210 bar): Bohrloch durchgehend dicht, Kopfdruck ≥ pkrit. Nur hier gilt Szenario D unverändert.
A21: → ZONE II (pLCCS 137–167 bar): Kopf unterkritisch, CO2 bleibt aber flüssig (Case 1 im SMRI-Paper) – noch einphasig.
A22: → ZONE III (pLCCS 70–137 bar): Zweiphasengebiet im oberen Bohrloch, instabile Schichtung (Case 2). Zusatzmodule aus Szenario G nötig.
A23: G1 Einspeichern (Verdichter-Modul → mündet in Kernstrang)
A24: Nr. | B24: Komponente / Ort | C24: p [bar] | D24: T [°C] | E24: Phase | F24: Anmerkung
A25: 1 | B25: Anlieferung Gas-Pipeline | C25: 30 | D25: 15 | E25: gasförmig | F25: Spec 25–35 bar / 5–25 °C
A26: 2 | B26: nach Verdichterstufe 1 (η=0,8) | C26: 49 | D26: 56.4 | E26: gasförmig | F26: r ≈ 1,63
A27: 3 | B27: nach Zwischenkühler | C27: 49 | D27: 40 | E27: gasförmig
A28: 4 | B28: nach Verdichterstufe 2 | C28: 80 | D28: 83.8 | E28: gasförmig (T>Tk) | F28: nur bis knapp über pkrit!
A29: 5 | B29: nach Nachkühler – VERFLÜSSIGUNG | C29: 80 | D29: 25 | E29: dicht (flüssig) | F29: ρ = 777 kg/m³, homogen (p>pkrit)
A30: 6 | B30: gemeinsame Pumpe (Kernstrang) | C30: 111 | D30: 30 | E30: dicht (flüssig) | F30: w = 4,9 kJ/kg – ab hier wie Szenario D
A32: G2 Ausspeichern (Vorwärmer-Modul)
A33: Nr. | B33: Komponente / Ort | C33: p [bar] | D33: T [°C] | E33: Phase | F33: Anmerkung
A34: 1 | B34: Bohrlochkopf | C34: 120 | D34: 41 | E34: dicht (flüssig) | F34: Auslegung wie D2; Teillast bis ~20 °C
A35: 2 | B35: nach Vorwärmer 1 | C35: 120 | D35: 75 | E35: überkritisch | F35: von 41 °C; Leistung 3,7–7,5 MW
A36: 3 | B36: nach Drossel 1 | C36: 60 | D36: 32 | E36: gasförmig (T>Tk) | F36: 10 K über Tsat
A37: 4 | B37: nach Vorwärmer 2 | C37: 60 | D37: 46 | E37: gasförmig
A38: 5 | B38: nach Drossel 2 → Gas-Pipeline | C38: 30 | D38: 15 | E38: gasförmig | F38: in Spec 25–35 bar / 5–25 °C
A39: – | B39: VERGLEICH: ohne Vorwärmung direkt auf 30 bar | C39: 30 | D39: -5.6 | E39: ZWEIPHASIG q=0,21 | F39: Tröpfchen, außerhalb Spec – nicht zulässig
A41: → Einstufige Alternative: eine Vorwärmung auf 86,7 °C statt zwei moderater Stufen (75/46 °C). Energie identisch, Stufen entlasten die Heizflächen.
A42: → In Szenario G werden die kritischen Grenzen gekreuzt: hier sind die Bohrloch-Phasenwechselpfade Case 1/2 (SMRI Fig. 6) und die
A43: Messtechnik-/Inventarthemen des Niederdruckbereichs relevant (Kopfdruck ≠ Füllstandsindikator).
A45: Verunreinigungen (vgl. DVGW-Abbildung): reale CO2-Gemische haben ein aufgeweitetes Zweiphasen-Band statt einer Linie –
A46: Sicherheitszuschlag auf die 73,8-bar-Grenze einplanen; Zusammensetzungs-Spec bei OGE erfragen (Fragenkatalog Körber).
...

Sheet Annahmen
A1: Einspeicherung CO2 in Salzkaverne – Druckbilanz der Gassäule
A2: Statische CO2-Säule in der Bohrung: der Druck steigt mit der Teufe durch das Eigengewicht (ρ·g·h).
A3: Frage: Welchen Kopfdruck braucht man oben, damit unten in der Kaverne der Zieldruck erreicht wird?
A5: Eingaben (blau = frei wählbar)
A6: Zieldruck Kaverne (unten) | B6: 210 | C6: bar
A7: Teufe (Länge der Säule) | B7: 1200 | C7: m
A8: Gebirgstemperatur an Oberfläche (ungestört) | B8: 15 | C8: °C | D8: ≈ Jahresmittel; NICHT Lufttemperatur, NICHT Medium. SMRI-Paper nutzt 10 °C.
A9: Geothermischer Gradient | B9: 3 | C9: °C/100 m
A10: Erdbeschleunigung | B10: 9.81 | C10: m/s²
A11: Anzahl Tiefenschritte | B11: 24 | C11: –
A13: Abgeleitete Größen
A14: Schrittweite Δz | B14: =B7/B11 -> 50 | C14: m
A15: Kopfdruck oben (iterativ bestimmt) | B15: 110.78539 | C15: bar
A16: ↑ so gewählt, dass die Integration unten genau p_ziel erreicht (siehe Blatt 'Berechnung').
A18: Methode
A19: • Die Dichte von CO2 hängt von Druck und Temperatur ab – beide ändern sich mit der Teufe.
A20: • Daher wird dp/dz = ρ(p,T)·g schrittweise nach unten integriert, statt ρ·g·h mit festem ρ.
A21: • ρ pro Schritt stammt aus CoolProp (Zustandsgleichung Span-Wagner), Spalte 'Dichte' im Blatt 'Berechnung'.
A22: • Die Druckaufsummierung selbst erfolgt hier per Excel-Formel und ist Zeile für Zeile nachvollziehbar.
A24: Legende & Quellen-Dokumentation (gilt für die gesamte Arbeitsmappe)
A25: Blaue Schrift | B25: eingetragener Zahlenwert: entweder freie Annahme ODER Stoffwert aus CoolProp – Herkunft steht jeweils in Anmerkung/Fußnote des Blatts
A26: Schwarze Schrift | B26: Excel-Formel, rechnet bei Änderung der Annahmen mit
A27: Gelbe Füllung | B27: frei änderbare Eingabe bzw. hervorgehobenes Schlüsselergebnis
A28: Stoffdaten-Quelle | B28: CoolProp (Open Source), Zustandsgleichung Span & Wagner (1996) für CO2; CH4/H2: jeweilige Referenz-EOS in CoolProp
A30: CoolProp-Werte je Blatt (blau):
A31: • Berechnung: Spalte 'Dichte ρ' (Zeilen 5–29) sowie h- und T-Werte der 41-°C-Herleitung (Zeilen 42/45)
A32: • Sensitivität & Medienvergleich: alle Kopfdrücke, Dichten und Profilwerte (CO2/CH4/H2)
A33: • Einspeichern Stufen / Ausspeichern Drossel: alle T-, h- und Phasenangaben der Prozesspfade
A34: • Phasendiagramm / p-h / gasförmig: Sättigungslinie, Dom, kritischer Punkt und alle Pfad-Datenpunkte
A36: Wichtige Begriffstrennung: 'Gebirgstemperatur Oberfläche' (15 °C, geothermisches Profil) und 'Anliefertemperatur Medium'
A37: (15 °C, aus OGE-Fenster 5–25 °C gewählt) sind UNABHÄNGIGE Annahmen mit zufällig gleichem Zahlenwert.

Sheet Berechnung
A1: Integration der Gassäule (von oben nach unten)
A2: Pro Zeile: T aus Gradient · ρ aus CoolProp · Δp = ρ·g·Δz · p_neu = p_alt + Δp
A4: Schritt | B4: Teufe z [m] | C4: Temperatur [°C] | D4: Dichte ρ [kg/m³] | E4: Δp = ρ·g·Δz [bar] | F4: Druck p [bar]
A5: 0 | B5: =A5*Annahmen!$B$14 -> 0 | C5: =Annahmen!$B$8+Annahmen!$B$9/100*B5 -> 15 | D5: 900.03 | E5: =D5*Annahmen!$B$10*Annahmen!$B$14/100000 -> 4.4146471 | F5: =Annahmen!$B$15 -> 110.78539
A6: 1 | B6: =A6*Annahmen!$B$14 -> 50 | C6: =Annahmen!$B$8+Annahmen!$B$9/100*B6 -> 16.5 | D6: 894.96 | E6: =D6*Annahmen!$B$10*Annahmen!$B$14/100000 -> 4.3897788 | F6: =F5+E5 -> 115.20004
A7: 2 | B7: =A7*Annahmen!$B$14 -> 100 | C7: =Annahmen!$B$8+Annahmen!$B$9/100*B7 -> 18 | D7: 889.92 | E7: =D7*Annahmen!$B$10*Annahmen!$B$14/100000 -> 4.3650576 | F7: =F6+E6 -> 119.58982
A8: 3 | B8: =A8*Annahmen!$B$14 -> 150 | C8: =Annahmen!$B$8+Annahmen!$B$9/100*B8 -> 19.5 | D8: 884.91 | E8: =D8*Annahmen!$B$10*Annahmen!$B$14/100000 -> 4.3404836 | F8: =F7+E7 -> 123.95488
A9: 4 | B9: =A9*Annahmen!$B$14 -> 200 | C9: =Annahmen!$B$8+Annahmen!$B$9/100*B9 -> 21 | D9: 879.94 | E9: =D9*Annahmen!$B$10*Annahmen!$B$14/100000 -> 4.3161057 | F9: =F8+E8 -> 128.29536
A10: 5 | B10: =A10*Annahmen!$B$14 -> 250 | C10: =Annahmen!$B$8+Annahmen!$B$9/100*B10 -> 22.5 | D10: 875.01 | E10: =D10*Annahmen!$B$10*Annahmen!$B$14/100000 -> 4.2919241 | F10: =F9+E9 -> 132.61147
A11: 6 | B11: =A11*Annahmen!$B$14 -> 300 | C11: =Annahmen!$B$8+Annahmen!$B$9/100*B11 -> 24 | D11: 870.12 | E11: =D11*Annahmen!$B$10*Annahmen!$B$14/100000 -> 4.2679386 | F11: =F10+E10 -> 136.90339
A12: 7 | B12: =A12*Annahmen!$B$14 -> 350 | C12: =Annahmen!$B$8+Annahmen!$B$9/100*B12 -> 25.5 | D12: 865.27 | E12: =D12*Annahmen!$B$10*Annahmen!$B$14/100000 -> 4.2441493 | F12: =F11+E11 -> 141.17133
A13: 8 | B13: =A13*Annahmen!$B$14 -> 400 | C13: =Annahmen!$B$8+Annahmen!$B$9/100*B13 -> 27 | D13: 860.46 | E13: =D13*Annahmen!$B$10*Annahmen!$B$14/100000 -> 4.2205563 | F13: =F12+E12 -> 145.41548
A14: 9 | B14: =A14*Annahmen!$B$14 -> 450 | C14: =Annahmen!$B$8+Annahmen!$B$9/100*B14 -> 28.5 | D14: 855.7 | E14: =D14*Annahmen!$B$10*Annahmen!$B$14/100000 -> 4.1972085 | F14: =F13+E13 -> 149.63603
A15: 10 | B15: =A15*Annahmen!$B$14 -> 500 | C15: =Annahmen!$B$8+Annahmen!$B$9/100*B15 -> 30 | D15: 850.98 | E15: =D15*Annahmen!$B$10*Annahmen!$B$14/100000 -> 4.1740569 | F15: =F14+E14 -> 153.83324
A16: 11 | B16: =A16*Annahmen!$B$14 -> 550 | C16: =Annahmen!$B$8+Annahmen!$B$9/100*B16 -> 31.5 | D16: 846.31 | E16: =D16*Annahmen!$B$10*Annahmen!$B$14/100000 -> 4.1511506 | F16: =F15+E15 -> 158.0073
A17: 12 | B17: =A17*Annahmen!$B$14 -> 600 | C17: =Annahmen!$B$8+Annahmen!$B$9/100*B17 -> 33 | D17: 841.7 | E17: =D17*Annahmen!$B$10*Annahmen!$B$14/100000 -> 4.1285385 | F17: =F16+E16 -> 162.15845
... A28: 23 | B28: =A28*Annahmen!$B$14 -> 1150 | C28: =Annahmen!$B$8+Annahmen!$B$9/100*B28 -> 49.5 | D28: 794.65 | E28: =D28*Annahmen!$B$10*Annahmen!$B$14/100000 -> 3.8977583 | F28: =F27+E27 -> 206.38654
A29: 24 | B29: =A29*Annahmen!$B$14 -> 1200 | C29: =Annahmen!$B$8+Annahmen!$B$9/100*B29 -> 51 | D29: 790.74 | E29: – | F29: =F28+E28 -> 210.2843
A31: Kontrolle: | E31: Druck unten = | F31: =F29 -> 210.2843
E32: Zieldruck = | F32: =Annahmen!$B$6 -> 210
E33: Druckgewinn Säule = | F33: =F29-F5 -> 99.498906
A34: Der Kopfdruck (Blatt Annahmen, B15) ist so gewählt, dass 'Druck unten' = Zieldruck ist.
A36: Herleitung: Kopftemperatur beim Ausspeichern (adiabater Grenzfall, ~41 °C)
A37: Energiebilanz für stationäre, adiabate Strömung im Bohrloch (kinetische Energie vernachlässigt): h + g·z = konstant.
A38: D.h. beim Aufstieg um Δz sinkt die spezifische Enthalpie um g·Δz – das Gas 'bezahlt' den Höhengewinn aus seiner Enthalpie.
A40: Größe | B40: Wert | C40: Einheit | D40: Quelle / Formel
A41: Zustand unten (Kaverne) | B41: 217 bar / 56 °C | D41: Annahme: Kavernendruck bei Ausspeicherbeginn
A42: h unten = h(217 bar, 56 °C) | B42: 311.2 | C42: kJ/kg | D42: CoolProp (Span-Wagner) – blauer Eingabewert
A43: g · Δz | B43: =Annahmen!B10*Annahmen!B7/1000 -> 11.772 | C43: kJ/kg | D43: Formel: 9,81 m/s² · 1200 m = 11,77
A44: h oben = h unten − g·Δz | B44: =B42-B43 -> 299.428 | C44: kJ/kg | D44: Formel – wird unten gesetzt
A45: T am Kopf = T(120 bar, h oben) | B45: 41 | C45: °C | D45: CoolProp-Rückrechnung – blauer Eingabewert
A47: Kontrolle: 311,20 − 11,77 = 299,43 kJ/kg → T(120 bar; 299,43 kJ/kg) = 41,0 °C. Die eingezeichnete Amber-Kurve
A48: im Blatt 'Phasendiagramm' (Spalten AQ/AR) ist dieselbe Bilanz schrittweise über 24 Tiefenschritte ausgewertet.
A49: Gegenstück langsamer Grenzfall: Gas folgt dem Gebirgsprofil → ~20 °C am Kopf (Pfad 'Bohrloch hoch', hellgrün).
A50: Reale Kopftemperatur liegt ratenabhängig dazwischen; exakt nur per transientem Bohrlochmodell (SMRI-Paper, offener Punkt).
A53: Teufenprofile: Temperatur, Druck und Dichte für drei Druckbereiche (Darstellung nach Buzogany & Kruck 2022, Fig. 3)
A54: Eigene Berechnung mit CoolProp für UNSERE Kavernenannahmen (1200 m, 15 °C Oberfläche, 0,03 K/m). Statische Säule, dp/dz = ρ·g von der LCCS aufwärts integriert.
A55: Druckbereiche analog Quelle: pkrit = 73,8 bar als Grenze. Hoch = Kopfdruck ≥ pkrit · Grenzfall = Kopfdruck genau pkrit · Niedrig = pLCCS < pkrit.
A56: → Die drei Diagramme stehen rechts neben der Tabelle: Temperatur ab Spalte J, Druck ab Spalte R, Dichte ab Spalte Z.
A57: Teufe z [m] | B57: T geologisch [°C] | C57: p [bar] hoch (pLCCS 210) | D57: p [bar] Grenzfall (pLCCS 166,5) | E57: p [bar] niedrig (pLCCS 70) | F57: ρ [kg/m³] hoch | G57: ρ [kg/m³] Grenzfall | H57: ρ [kg/m³] niedrig
...

Sheet Sensitivität & Medienvergleich
A1: Sensitivität Teufe & Medienvergleich: CO2 vs. Erdgas (CH4) vs. Wasserstoff (H2)
A2: Gleiche Rechnung (dp/dz = ρ·g integriert), gleiches Ziel (210 bar unten), gleiches Temperaturprofil – nur das Medium ändert sich.
A4: 1) Benötigter Kopfdruck in Abhängigkeit der Teufe (Ziel: 210 bar unten)
A5: Teufe [m] | B5: Kopfdruck CO2 [bar] | C5: Kopfdruck CH4 [bar] | D5: Kopfdruck H2 [bar] | E5: Zieldruck unten [bar]
A6: 600 | B6: 156.5 | C6: 200.5 | D6: 209.1 | E6: 210
A7: 800 | B7: 140.3 | C7: 197.6 | D7: 208.8 | E7: 210
A8: 1000 | B8: 125 | C8: 194.9 | D8: 208.5 | E8: 210
A9: 1200 | B9: 110.8 | C9: 192.2 | D9: 208.3 | E9: 210
A10: 1400 | B10: 97.6 | C10: 189.7 | D10: 208 | E10: 210
A11: 1600 | B11: 85.7 | C11: 187.3 | D11: 207.7 | E11: 210
A13: CO2 profitiert massiv von der Teufe (−71 bar Kopfdruck zwischen 600 und 1600 m). CH4 kaum (−13 bar), H2 praktisch gar nicht (−1,4 bar).
A14: Je tiefer die Kaverne, desto größer der Vorteil der dichten CO2-Säule – für H2 ist die Teufe druckseitig fast irrelevant.
A16: 2) Kennzahlen bei 1200 m Teufe
A17: Medium | B17: Kopfdruck [bar] | C17: Säulengewinn [bar] | D17: ρ Kopf [kg/m³] | E17: ρ unten [kg/m³] | F17: Übertagetechnik
A18: CO2 (dicht) | B18: 110.8 | C18: 99.2 | D18: 900 | E18: 790.7 | F18: Pumpe (85→111 bar)
A19: Erdgas (CH4) | B19: 192.2 | C19: 17.8 | D19: 162.1 | E19: 141.4 | F19: Verdichter bis ~200–230 bar
A20: Wasserstoff (H2) | B20: 208.3 | C20: 1.7 | D20: 15.5 | E20: 14 | F20: Verdichter bis ~210+ bar
A22: Erdgas/H2: Dichte unten < oben (Temperaturanstieg überkompensiert Druckanstieg) → instabile Schichtung/Konvektion, vgl. SMRI-Paper.
A24: 3) Druck- und Dichteprofile über die Teufe (1200 m, 24 Schritte à 50 m)
A25: CO2 | E25: Erdgas (CH4) | I25: Wasserstoff (H2)
A26: Teufe [m] | B26: p [bar] | C26: ρ [kg/m³] | E26: Teufe [m] | F26: p [bar] | G26: ρ [kg/m³] | I26: Teufe [m] | J26: p [bar] | K26: ρ [kg/m³]
A27: 0 | B27: 110.8 | C27: 900 | E27: 0 | F27: 192.2 | G27: 162.1 | I27: 0 | J27: 208.3 | K27: 15.5
A28: 50 | B28: 115.2 | C28: 895 | E28: 50 | F28: 193 | G28: 161 | I28: 50 | J28: 208.3 | K28: 15.4
A29: 100 | B29: 119.6 | C29: 889.9 | E29: 100 | F29: 193.8 | G29: 159.9 | I29: 100 | J29: 208.4 | K29: 15.3
A30: 150 | B30: 124 | C30: 884.9 | E30: 150 | F30: 194.6 | G30: 158.9 | I30: 150 | J30: 208.5 | K30: 15.3
A31: 200 | B31: 128.3 | C31: 879.9 | E31: 200 | F31: 195.4 | G31: 157.9 | I31: 200 | J31: 208.6 | K31: 15.2
A32: 250 | B32: 132.6 | C32: 875 | E32: 250 | F32: 196.2 | G32: 156.9 | I32: 250 | J32: 208.6 | K32: 15.1
A33: 300 | B33: 136.9 | C33: 870.1 | E33: 300 | F33: 196.9 | G33: 155.9 | I33: 300 | J33: 208.7 | K33: 15.1
A34: 350 | B34: 141.2 | C34: 865.3 | E34: 350 | F34: 197.7 | G34: 155 | I34: 350 | J34: 208.8 | K34: 15
A35: 400 | B35: 145.4 | C35: 860.5 | E35: 400 | F35: 198.5 | G35: 154.1 | I35: 400 | J35: 208.9 | K35: 15
A36: 450 | B36: 149.6 | C36: 855.7 | E36: 450 | F36: 199.2 | G36: 153.1 | I36: 450 | J36: 208.9 | K36: 14.9
A37: 500 | B37: 153.8 | C37: 851 | E37: 500 | F37: 200 | G37: 152.3 | I37: 500 | J37: 209 | K37: 14.8
A38: 550 | B38: 158 | C38: 846.3 | E38: 550 | F38: 200.7 | G38: 151.4 | I38: 550 | J38: 209.1 | K38: 14.8
... A51: 1200 | B51: 210.3 | C51: 790.7 | E51: 1200 | F51: 210.1 | G51: 141.4 | I51: 1200 | J51: 210 | K51: 14

Sheet Arbeitsgas & Regime
A1: Arbeitsgas / Kissengas und die zwei Betriebsregime
A2: Methode: Massenbilanz im festen Kavernenvolumen. Inventar m = ρ(p,T) · V. Arbeitsgas = m(p_max) − m(p_min), Kissengas = m(p_min).
A3: WICHTIG: Bei CO2 NICHT über das Druckverhältnis rechnen! ρ ist nahe dem kritischen Punkt stark nichtlinear (73,8→80 bar: 295→586 kg/m³).
A4: Bei Erdgas wäre die Näherung 'Arbeitsgas ∝ Druckdifferenz' brauchbar – bei CO2 führt sie zu groben Fehlern.
A6: Eingaben
A7: Kavernenvolumen V | B7: 650000 | C7: m³ | D7: Beispielwert nach Buzogany & Kruck (2022)
A8: Maximaldruck p_max | B8: 210 | C8: bar | D8: ≈ 80 % des lithostatischen Drucks
A9: Temperatur isotherm | B9: 50 | C9: °C | D9: vereinfachte Näherung
A10: T-Modell mit Abkühlung | B10: 33,1 °C @ 77,6 bar … 55 °C @ 210 bar | D10: linear interpoliert aus der Simulation der Quelle
A12: pLCCS [bar] | B12: T isotherm [°C] | C12: ρ [kg/m³] | D12: Inventar [kt] | E12: Arbeitsgas ab hier [%] | F12: T mit Abkühlung [°C] | G12: ρ [kg/m³] | H12: Inventar [kt] | I12: Arbeitsgas ab hier [%]
A13: 70 | B13: 50 | C13: 172 | D13: 111.8 | E13: =($D$27-D13)/$D$27*100 -> 78.39196 | F13: 31.8 | G13: 243.2 | H13: 158 | I13: =($H$27-H13)/$H$27*100 -> 68.343017
A14: 73.8 | B14: 50 | C14: 188.4 | D14: 122.5 | E14: =($D$27-D14)/$D$27*100 -> 76.323927 | F14: 32.5 | G14: 295.5 | H14: 192.1 | I14: =($H$27-H14)/$H$27*100 -> 61.510719
A15: 80 | B15: 50 | C15: 219.2 | D15: 142.5 | E15: =($D$27-D15)/$D$27*100 -> 72.458446 | F15: 33.5 | G15: 586.3 | H15: 381.1 | I15: =($H$27-H15)/$H$27*100 -> 23.642557
A16: 90 | B16: 50 | C16: 285 | D16: 185.2 | E16: =($D$27-D16)/$D$27*100 -> 64.205644 | F16: 35.2 | G16: 658.8 | H16: 428.2 | I16: =($H$27-H16)/$H$27*100 -> 14.20557
A17: 100 | B17: 50 | C17: 384.3 | D17: 249.8 | E17: =($D$27-D17)/$D$27*100 -> 51.720139 | F17: 36.8 | G17: 686.5 | H17: 446.2 | I17: =($H$27-H17)/$H$27*100 -> 10.599078
A18: 110 | B18: 50 | C18: 502.6 | D18: 326.7 | E18: =($D$27-D18)/$D$27*100 -> 36.857364 | F18: 38.5 | G18: 703.9 | H18: 457.5 | I18: =($H$27-H18)/$H$27*100 -> 8.335003
A19: 120 | B19: 50 | C19: 584.7 | D19: 380.1 | E19: =($D$27-D19)/$D$27*100 -> 26.536529 | F19: 40.1 | G19: 716.5 | H19: 465.7 | I19: =($H$27-H19)/$H$27*100 -> 6.6920457
A20: 130 | B20: 50 | C20: 636.1 | D20: 413.5 | E20: =($D$27-D20)/$D$27*100 -> 20.081175 | F20: 41.8 | G20: 726.4 | H20: 472.2 | I20: =($H$27-H20)/$H$27*100 -> 5.3897015
A21: 140 | B21: 50 | C21: 672.2 | D21: 436.9 | E21: =($D$27-D21)/$D$27*100 -> 15.558562 | F21: 43.4 | G21: 734.5 | H21: 477.5 | I21: =($H$27-H21)/$H$27*100 -> 4.32779
A22: 150 | B22: 50 | C22: 699.8 | D22: 454.8 | E22: =($D$27-D22)/$D$27*100 -> 12.098956 | F22: 45.1 | G22: 741.4 | H22: 481.9 | I22: =($H$27-H22)/$H$27*100 -> 3.4462032
A23: 166.5 | B23: 50 | C23: 734.6 | D23: 477.5 | E23: =($D$27-D23)/$D$27*100 -> 7.7116351 | F23: 47.8 | G23: 750.6 | H23: 487.9 | I23: =($H$27-H23)/$H$27*100 -> 2.2440393
A24: 180 | B24: 50 | C24: 757.1 | D24: 492.1 | E24: =($D$27-D24)/$D$27*100 -> 4.8898338 | F24: 50 | G24: 756.9 | H24: 492 | I24: =($H$27-H24)/$H$27*100 -> 1.4225606
... A27: 210 | B27: 50 | C27: 795.9 | D27: 517.4 | E27: =($D$27-D27)/$D$27*100 -> 0 | F27: 55 | G27: 767.9 | H27: 499.1 | I27: =($H$27-H27)/$H$27*100 -> 0
A29: Die drei möglichen Minimaldrücke im Vergleich
A30: Variante | B30: Kriterium | C30: p_min [bar] | D30: Arbeitsgas isotherm [%] | E30: Arbeitsgas mit Abkühlung [%] | F30: Bewertung
A31: A | B31: gesamtes Bohrloch bleibt dicht (Kopfdruck ≥ 73,8 bar) | C31: 166.5 | D31: 7.7 | E31: 2.2 | F31: wirtschaftlich ausgeschlossen
A32: B | B32: nur die Kaverne bleibt überkritisch (pLCCS ≥ 73,8 bar) | C32: 73.8 | D32: 76.3 | E32: 61.5 | F32: praktikabel; Phasenwechsel im Bohrloch werden in Kauf genommen
A33: C | B33: geomechanisches Minimum (Salzkriechen) | C33: 70 | D33: 78.4 | E33: 68.3 | F33: untere Grenze aus dem Betriebsplan
A34: Kernaussage: Der Unterschied zwischen A und B ist NICHT geomechanisch, sondern eine Prozessentscheidung.
A35: Variante A würde nur ~2–8 % des Inventars nutzbar machen – der Preis dafür, dass im Bohrloch nirgends ein Phasenübergang auftritt.
A36: Variante B/C nutzt das Betriebsfenster aus und akzeptiert, dass der Bohrlochkopf im unteren Druckbereich unterkritisch wird.
A38: Daraus folgen ZWEI BETRIEBSREGIME – die Übertageanlage muss beide beherrschen
A39: Regime | B39: pLCCS-Bereich | C39: Zustand im Bohrloch | D39: Anlagentechnik | E39: Besonderheit
A40: I – dichter Betrieb | B40: 166,5 – 210 bar | C40: durchgehend dicht/überkritisch, Kopfdruck ≥ 73,8 bar | D40: Pumpe + eine Drosselstufe (+ Nachkühler) | E40: thermodynamisch harmlos, Kopfdruck = Füllstandsindikator
A41: II – unterkritischer Kopf | B41: 70 – 166,5 bar | C41: Kopf unterkritisch; Phasenwechsel im oberen Bohrloch (Case 1/2) | D41: zusätzlich Vorwärmung, mehrphasenfähige Messtechnik, ggf. Verdichter/Pumpe zum Boosten | E41: Kopfdruck sagt nichts mehr über den Füllstand → Inventar über Mengenbilanz
A43: Der überwiegende Teil des Arbeitsgases liegt in Regime II – deshalb ist es kein Sonderfall, sondern Normalbetrieb.
A45: Grenzen dieser Abschätzung (ehrlich)
A46: • Beide Spalten sind vereinfacht: isotherm ist zu optimistisch, das lineare T(p)-Modell ebenfalls (es bildet die Ratenabhängigkeit nicht ab).
A47: • Die Vollsimulation der Quelle liefert 68–78 % KISSENGAS, also nur 22–32 % Arbeitsgas – deutlich weniger als unsere 61–68 %.
A48: • Ursache: Beim Ausspeichern kühlt die Kaverne ab, das CO2 bleibt nahe dem kritischen Punkt dicht, und die max. Druckänderungsrate (6 bar/d) begrenzt zusätzlich.
...

Sheet Zyklus & Inventar
A1: Zyklussimulation und Inventarmessung
A2: Massen- und Energiebilanz der Kaverne über einen kompletten Zyklus (zyklus.py). Ergänzt die statischen Betrachtungen der übrigen Blätter.
A3: Modell: dm/dt = ṁ · dU/dt = ṁ·h + UA·(T_Gebirge − T_Kaverne). Zustand aus (ρ, u) via CoolProp. Vereinfacht: Kaverne ideal durchmischt, Bohrloch nicht modelliert.
A5: 1) Einfluss der Ausspeicherrate — das zentrale Ergebnis
A6: Szenario | B6: Rate [kg/s] | C6: Dauer Ausspeicherung [d] | D6: T Kaverne am Ende [°C] | E6: Inventar min [kt] | F6: Arbeitsgas [%]
A7: Nennrate ~100 kNm³/h (55 kg/s) | B7: 55 | C7: 56.8 | D7: 45.5 | E7: 118.2 | F7: 74.2
A8: Maximalrate 6 bar/d (234 kg/s) | B8: 234 | C8: 14.3 | D8: 28.7 | E8: 226.9 | F8: 50.4
A9: Quelle (Maximalraten-Szenario): Kissengas 68–78 %, Kavernentemperatur am Ende 33,1 °C
A10: → Langsameres Ausspeichern lässt dem Gebirge Zeit nachzuheizen. Die Kaverne bleibt wärmer, das CO2 weniger dicht,
A11: dadurch kommt mehr Masse heraus: 74 % Arbeitsgas statt 50 %. Die Quelle vermutet genau diesen Effekt (Kap. 5).
A12: → Für euren Fall günstig: Bei 50–100 kNm³/h liegt ihr weit unter der 6-bar/d-Grenze (die erlaubt bei 135 bar ~234 kg/s).
A13: Die Ratengrenze bindet also gar nicht — begrenzend ist die Übertageanlage, nicht die Kaverne.
A14: → Vorbehalt: Der Wärmeübergang UA ist eine Annahme. Unsere Werte liegen optimistischer als die Vollsimulation der Quelle.
A16: 2) Inventarmessung — warum der Druck unterhalb p_krit versagt
A17: Zustand | B17: Druck | C17: Aussage über das Inventar | D17: Messverfahren
A18: einphasig (p > 73,8 bar) | B18: eindeutig von ρ abhängig | C18: ρ = ρ(p,T) → Inventar = ρ·V exakt | D18: Druck + Temperatur genügen
A19: zweiphasig (p < 73,8 bar) | B19: p = p_sat(T), nur temperaturabhängig | C19: KEINE — bei 20 °C/57,3 bar sind 126 bis 503 kt möglich | D19: Mengenbilanz oder Füllstandsmessung
A21: 3) Messverfahren im Vergleich
A22: Verfahren | B22: Prinzip | C22: Stärke | D22: Schwäche
A23: Druckmessung am Kopf | B23: p → ρ → Inventar | C23: Standard bei Erdgas, einfach | D23: fällt im Zweiphasengebiet komplett aus
A24: Mengenbilanz (Coriolis) | B24: alle Ein-/Ausströme aufsummieren | C24: funktioniert in jedem Zustand | D24: Drift: ±0,5 % Messfehler ≈ ±0,4 kt je 30 d Dauerbetrieb
A25: Downhole p/T-Sensoren | B25: Zustand direkt in der Kaverne | C25: kein Bohrlochmodell nötig | D25: im Zweiphasengebiet ebenfalls nicht eindeutig
A26: Füllstands-/Echometrie | B26: Lage der Flüssigkeitsoberfläche | C26: liefert im Zweiphasengebiet die fehlende Größe | D26: Verfügbarkeit für CO2 laut Quelle offen
A27: Rückkalibrierung | B27: Mengenbilanz bei p > p_krit zurücksetzen | C27: begrenzt die Drift auf einen Zyklus | D27: setzt voraus, dass die Kaverne regelmäßig überkritisch wird
A29: Empfehlung: Mengenbilanz als laufendes Verfahren, kombiniert mit Rückkalibrierung im überkritischen Zustand.
A30: Bei ±0,5 % Messgenauigkeit bleibt der Fehler mit ~0,07 % des Inventars unkritisch — Voraussetzung ist ein Zyklus, der regelmäßig über p_krit führt.
A33: 4) Zeitreihe der Nennraten-Simulation (jeder 20. Schritt)
A34: t [d] | B34: p [bar] | C34: T [°C] | D34: Inventar [kt]
A35: 0 | B35: 135 | C35: 55 | D35: 387.9
A36: 0.2 | B36: 133.8 | C36: 54.7 | D36: 387
A37: 0.4 | B37: 132.6 | C37: 54.3 | D37: 386.1
A38: 0.6 | B38: 131.4 | C38: 54 | D38: 385.1
A39: 0.8 | B39: 130.3 | C39: 53.6 | D39: 384.2
A40: 1 | B40: 129.2 | C40: 53.3 | D40: 383.2
A41: 1.2 | B41: 128.2 | C41: 53 | D41: 382.3
A42: 1.4 | B42: 127.1 | C42: 52.7 | D42: 381.3
A43: 1.6 | B43: 126.1 | C43: 52.4 | D43: 380.4
A44: 1.8 | B44: 125.2 | C44: 52.1 | D44: 379.4
A45: 2 | B45: 124.2 | C45: 51.9 | D45: 378.5
A46: 2.2 | B46: 123.3 | C46: 51.6 | D46: 377.5
...

Sheet Einspeichern Stufen
A1: Einspeichern ab OGE-Anlieferung (dichte Phase) – plus Vergleich gasförmige Anlieferung
A3: Hauptfall: OGE liefert dicht an (80–90 bar, 5–25 °C) → nur PUMPE auf Kopfdruck nötig
A4: Anlieferdruck (OGE, dicht) | B4: 85 | C4: bar
A5: Anliefertemperatur | B5: 15 | C5: °C
A6: Kopfdruck Ziel (aus Blatt Annahmen) | B6: 111 | C6: bar
A7: isentroper Wirkungsgrad Pumpe | B7: 0.8 | C7: –
A9: Austrittstemperatur Pumpe | B9: 17.9 | C9: °C
A10: spezifische Pumparbeit | B10: 3.7 | C10: kJ/kg
A11: Dichte am Eintritt | B11: 874 | C11: kg/m³
A12: Phase durchgehend | B12: dicht (p>pk)
A13: → Verdichtung entfällt praktisch: dichte Phase wird GEPUMPT (874 kg/m³), nur +2,9 K. Einspeicherseitig kein Kühler; ausspeicherseitig Nachkühler bei Nennrate (s. Anlagenkonzept).
A14: Werte aus CoolProp; h-basiert mit η=0,8. Ankunft variiert im OGE-Fenster 80–90 bar / 5–25 °C – Ergebnis ändert sich nur marginal.
A17: Vergleichsfall: gasförmige Anlieferung 10 bar (illustrativ, z.B. Direktanschluss Abscheider)
A18: Stufe | B18: p_ein [bar] | C18: T_ein [°C] | D18: p_aus [bar] | E18: T_aus isentrop [°C] | F18: T_aus real (η=0,8) [°C] | G18: Phase Austritt | H18: Quellen!
A19: 1 | B19: 10 | C19: 15 | D19: 22.3 | E19: 73.2 | F19: 84.5 | G19: gasförmig (T>Tk)
A20: 2 | B20: 22.3 | C20: 40 | D20: 49.8 | E20: 103.7 | F20: 114.2 | G20: gasförmig (T>Tk)
A21: 3 | B21: 49.8 | C21: 40 | D21: 111 | E21: 107.2 | F21: 113.6 | G21: überkritisch
A23: 3 Stufen mit Zwischenkühlung auf 40 °C: max. 114 °C. EINSTUFIG läge der Austritt bei ~263 °C – nicht machbar.
A24: Dieser Fall zeigt, warum Pipeline-Anlieferung in dichter Phase die Verdichtung des Einspeicherpfads massiv vereinfacht.

Sheet Ausspeichern Drossel
A1: Ausspeichern: Szenario 1 Fernleitung (dicht) vs. Szenario 2 Gasnetz (40 bar)
A3: Szenario 1 (Hauptfall): Rücklieferung an OGE-Fernleitung – AUSLEGUNG: Ankunft 41 °C bei Nennrate 50–100 kNm³/h
A4: Druck [bar] | B4: T [°C] | C4: Phase
A5: 120 | B5: 41 | C5: überkritisch
A6: 115 | B6: 40.2 | C6: überkritisch
A7: 110 | B7: 39.3 | C7: überkritisch
A8: 105 | B8: 38.4 | C8: überkritisch
A9: 100 | B9: 37.3 | C9: überkritisch
A10: 95 | B10: 36.3 | C10: überkritisch
A11: 90 | B11: 35.1 | C11: überkritisch
A12: 85 | B12: 33.8 | C12: überkritisch
A14: Auslegungsfall: Drossel 120 bar/41 °C → 85 bar ergibt 33,8 °C (über OGE-Spec) → NACHKÜHLER auf ≤25 °C (1,1–2,1 MW).
A15: Weiterhin: EINE Drosselstufe, KEIN Vorwärmer – oberhalb pkrit = 73,8 bar existiert kein Zweiphasengebiet.
A16: Gegen Ende der Ausspeicherung (Kopfdruck < ~85 bar) übernimmt eine Pumpe die Anhebung auf Fernleitungsdruck.
A17: Teillast-Grenzfall (sehr langsame Rate): Ankunft ~20 °C → Drossel endet bei 17,9 °C, Nachkühler im Bypass.
A18: Szenario 2 (Vergleich): Abgabe an Gasnetz/Verbraucher bei 40 bar – hier wird die 73,8-bar-Grenze gekreuzt
A19: Druck [bar] | B19: A: T [°C] ohne Vorw. | C19: A: Phase | D19: A: Dampfanteil q | E19: B: T [°C] mit Vorw. 79 °C | F19: B: Phase
A20: 120 | B20: 20 | C20: dicht (p>pk) | D20: – | E20: 79.2 | F20: nach Vorwärmer
A21: 115 | B21: 19.7 | C21: dicht (p>pk) | D21: – | E21: 76.5 | F21: überkritisch
A22: 110 | B22: 19.5 | C22: dicht (p>pk) | D22: – | E22: 73.8 | F22: überkritisch
A23: 105 | B23: 19.2 | C23: dicht (p>pk) | D23: – | E23: 70.9 | F23: überkritisch
A24: 100 | B24: 18.9 | C24: dicht (p>pk) | D24: – | E24: 67.8 | F24: überkritisch
A25: 95 | B25: 18.6 | C25: dicht (p>pk) | D25: – | E25: 64.6 | F25: überkritisch
A26: 90 | B26: 18.3 | C26: dicht (p>pk) | D26: – | E26: 61.2 | F26: überkritisch
A27: 85 | B27: 17.9 | C27: dicht (p>pk) | D27: – | E27: 57.7 | F27: überkritisch
A28: 80 | B28: 17.5 | C28: dicht (p>pk) | D28: – | E28: 53.9 | F28: überkritisch
A29: 75 | B29: 17.2 | C29: dicht (p>pk) | D29: – | E29: 50 | F29: überkritisch
A30: 70 | B30: 16.7 | C30: flüssig | D30: – | E30: 45.8 | F30: gasförmig (T>Tk)
A31: 65 | B31: 16.3 | C31: flüssig | D31: – | E31: 41.5 | F31: gasförmig (T>Tk)
... A33: 55 | B33: 15.4 | C33: flüssig | D33: – | E33: 31.9 | F33: gasförmig (T>Tk)
A34: 50 | B34: 14.3 | C34: ZWEIPHASIG | D34: 0.01 | E34: 26.7 | F34: gasförmig
A35: 45 | B35: 10 | C35: ZWEIPHASIG | D35: 0.07 | E35: 21.2 | F35: gasförmig
A36: 40 | B36: 5.3 | C36: ZWEIPHASIG | D36: 0.12 | E36: 15.3 | F36: gasförmig
A37: Ohne Vorwärmung: ab ~74 bar zweiphasig, Ende 5,3 °C mit q=0,12. Mit Vorwärmung auf 79 °C: einphasig gasförmig.
A38: Fazit: Vorwärmung/Stufen sind nur nötig, wenn UNTER den kritischen Druck entspannt wird – nicht im Fernleitungsfall.

Sheet Phasendiagramm
A1: Phasendiagramm mit Prozesspfaden (Daten für das Diagramm)
A2: Sättigungslinie + kritischer Punkt aus CoolProp. Pfade aus den Blättern 'Einspeichern Stufen' und 'Ausspeichern Drossel'.
A4: Sättigung T | B4: Sättigung p | D4: Verdichtung T | E4: Verdichtung p | G4: Drossel A T | H4: Drossel A p | J4: Drossel B T | K4: Drossel B p | M4: krit. Punkt T | N4: krit. Punkt p | P4: einstufig T | Q4: einstufig p | S4: Grenze T=31°C | T4: p | V4: Grenze p=73,8 bar T | W4: p | Y4: Pumpe T | Z4: Pumpe p | AB4: Sz1 T | AC4: Sz1 p | AE4: OGE-Fenster T | AF4: OGE-Fenster p | AH4: Kaverne T | AI4: Kaverne p | AK4: Bohrloch runter T | AL4: p | AN4: Bohrloch hoch T | AO4: p | AQ4: Bohrloch hoch adiabat T | AR4: p | AT4: Drossel warm T | AU4: p | AW4: Zone III Bohrloch T | AX4: p
A5: -56.06 | B5: 5.29 | D5: 15 | E5: 10 | G5: 20 | H5: 120 | J5: 20 | K5: 120 | M5: 31 | N5: 73.8 | P5: 15 | Q5: 10 | S5: 31 | T5: 73.8 | V5: 31 | W5: 73.8 | Y5: 15 | Z5: 85 | AB5: 20 | AC5: 120 | AE5: 5 | AF5: 80 | AH5: 30 | AI5: 70 | AK5: 17.9 | AL5: 111 | AN5: 20 | AO5: 120 | AQ5: 42.3 | AR5: 129 | AT5: 41 | AU5: 120 | AW5: 51 | AX5: 110
A6: -53.83 | B6: 5.82 | D6: 84.5 | E6: 22.3 | G6: 19.7 | H6: 115 | J6: 79.2 | K6: 120 | P6: 39.9 | Q6: 13.5 | S6: 31 | T6: 140 | V6: 140 | W6: 73.8 | Y6: 15.6 | Z6: 90.2 | AB6: 19.7 | AC6: 115 | AE6: 25 | AF6: 80 | AH6: 60 | AI6: 70 | AK6: 19.4 | AL6: 115.3 | AN6: 21.5 | AO6: 124.3 | AQ6: 43 | AR6: 132.5 | AT6: 40.2 | AU6: 115 | AW6: 50.9 | AX6: 109.9
A7: -51.6 | B7: 6.39 | D7: 40 | E7: 22.3 | G7: 19.5 | H7: 110 | J7: 76.5 | K7: 115 | P7: 60.1 | Q7: 17 | Y7: 16.2 | Z7: 95.4 | AB7: 19.5 | AC7: 110 | AE7: 25 | AF7: 90 | AH7: 60 | AI7: 210 | AK7: 20.9 | AL7: 119.6 | AN7: 23 | AO7: 128.6 | AQ7: 43.6 | AR7: 136.1 | AT7: 39.3 | AU7: 110 | AW7: 50.9 | AX7: 109.8
A8: -49.37 | B8: 7 | D8: 40 | E8: 22.3 | G8: 19.2 | H8: 105 | J8: 73.8 | K8: 110 | P8: 77.2 | Q8: 20.4 | Y8: 16.7 | Z8: 100.6 | AB8: 19.2 | AC8: 105 | AE8: 5 | AF8: 90 | AH8: 30 | AI8: 210 | AK8: 22.4 | AL8: 123.9 | AN8: 24.5 | AO8: 132.8 | AQ8: 44.3 | AR8: 139.7 | AT8: 38.4 | AU8: 105 | AW8: 50.8 | AX8: 109.6
A9: -47.14 | B9: 7.65 | D9: 114.2 | E9: 49.8 | G9: 18.9 | H9: 100 | J9: 70.9 | K9: 105 | P9: 92.1 | Q9: 23.9 | Y9: 17.3 | Z9: 105.8 | AB9: 18.9 | AC9: 100 | AE9: 5 | AF9: 80 | AH9: 30 | AI9: 70 | AK9: 23.9 | AL9: 128.2 | AN9: 26 | AO9: 137.1 | AQ9: 44.9 | AR9: 143.2 | AT9: 37.3 | AU9: 100 | AW9: 50.7 | AX9: 109.5
A10: -44.91 | B10: 8.35 | D10: 40 | E10: 49.8 | G10: 18.6 | H10: 95 | J10: 67.8 | K10: 100 | P10: 105.3 | Q10: 27.4 | Y10: 17.9 | Z10: 111 | AB10: 18.6 | AC10: 95 | AK10: 25.4 | AL10: 132.4 | AN10: 27.5 | AO10: 141.3 | AQ10: 45.5 | AR10: 146.8 | AT10: 36.3 | AU10: 95 | AW10: 50.6 | AX10: 109.4
A11: -42.68 | B11: 9.09 | D11: 40 | E11: 49.8 | G11: 18.3 | H11: 90 | J11: 64.6 | K11: 95 | P11: 117.2 | Q11: 30.9 | AB11: 18.3 | AC11: 90 | AK11: 26.9 | AL11: 136.6 | AN11: 29 | AO11: 145.5 | AQ11: 46.1 | AR11: 150.4 | AT11: 35.1 | AU11: 90 | AW11: 50.5 | AX11: 109.3
A12: -40.45 | B12: 9.88 | D12: 113.6 | E12: 111 | G12: 17.9 | H12: 85 | J12: 61.2 | K12: 90 | P12: 128.1 | Q12: 34.4 | AB12: 17.9 | AC12: 85 | AK12: 28.4 | AL12: 140.8 | AN12: 30.5 | AO12: 149.6 | AQ12: 46.7 | AR12: 154 | AT12: 33.8 | AU12: 85 | AW12: 50.5 | AX12: 109.2
A13: -38.21 | B13: 10.72 | D13: 40 | E13: 111 | G13: 17.5 | H13: 80 | J13: 57.7 | K13: 85 | P13: 138.1 | Q13: 37.9 | AK13: 29.9 | AL13: 144.9 | AN13: 32 | AO13: 153.8 | AQ13: 47.3 | AR13: 157.6 | AW13: 50.4 | AX13: 109.1
A14: -35.98 | B14: 11.61 | G14: 17.2 | H14: 75 | J14: 53.9 | K14: 80 | P14: 147.4 | Q14: 41.3 | AK14: 31.4 | AL14: 149.1 | AN14: 33.5 | AO14: 157.9 | AQ14: 47.9 | AR14: 161.3 | AW14: 50.3 | AX14: 108.9
A15: -33.75 | B15: 12.56 | G15: 16.7 | H15: 70 | J15: 50 | K15: 75 | P15: 156.1 | Q15: 44.8 | AK15: 32.9 | AL15: 153.2 | AN15: 35 | AO15: 162 | AQ15: 48.5 | AR15: 164.9 | AW15: 50.2 | AX15: 108.8
A16: -31.52 | B16: 13.56 | G16: 16.3 | H16: 65 | J16: 45.8 | K16: 70 | P16: 164.3 | Q16: 48.3 | AK16: 34.4 | AL16: 157.2 | AN16: 36.5 | AO16: 166 | AQ16: 49.1 | AR16: 168.6 | AW16: 50.2 | AX16: 108.7
A17: -29.29 | B17: 14.62 | G17: 15.9 | H17: 60 | J17: 41.5 | K17: 65 | P17: 172 | Q17: 51.8 | AK17: 35.9 | AL17: 161.3 | AN17: 38 | AO17: 170.1 | AQ17: 49.6 | AR17: 172.2 | AW17: 50.1 | AX17: 108.6
A18: -27.06 | B18: 15.74 | G18: 15.4 | H18: 55 | J18: 36.8 | K18: 60 | P18: 179.3 | Q18: 55.3 | AK18: 37.4 | AL18: 165.3 | AN18: 39.5 | AO18: 174.1 | AQ18: 50.2 | AR18: 175.9 | AW18: 50 | AX18: 108.5
A19: -24.83 | B19: 16.92 | G19: 14.3 | H19: 50 | J19: 31.9 | K19: 55 | P19: 186.2 | Q19: 58.8 | AK19: 38.9 | AL19: 169.4 | AN19: 41 | AO19: 178.1 | AQ19: 50.8 | AR19: 179.6 | AW19: 49.9 | AX19: 108.3
A20: -22.6 | B20: 18.16 | G20: 10 | H20: 45 | J20: 26.7 | K20: 50 | P20: 192.8 | Q20: 62.2 | AK20: 40.4 | AL20: 173.3 | AN20: 42.5 | AO20: 182.1 | AQ20: 51.3 | AR20: 183.3 | AW20: 49.9 | AX20: 108.2
A21: -20.37 | B21: 19.47 | G21: 5.3 | H21: 40 | J21: 21.2 | K21: 45 | P21: 199.1 | Q21: 65.7 | AK21: 41.9 | AL21: 177.3 | AN21: 44 | AO21: 186.1 | AQ21: 51.8 | AR21: 187 | AW21: 49.8 | AX21: 108.1
A22: -18.14 | B22: 20.85 | J22: 15.3 | K22: 40 | P22: 205.1 | Q22: 69.2 | AK22: 43.4 | AL22: 181.3 | AN22: 45.5 | AO22: 190 | AQ22: 52.4 | AR22: 190.7 | AW22: 49.7 | AX22: 108
A23: -15.91 | B23: 22.3 | P23: 210.9 | Q23: 72.7 | AK23: 44.9 | AL23: 185.2 | AN23: 47 | AO23: 193.9 | AQ23: 52.9 | AR23: 194.4 | AW23: 49.6 | AX23: 107.9
A24: -13.68 | B24: 23.82 | P24: 216.4 | Q24: 76.2 | AK24: 46.4 | AL24: 189.1 | AN24: 48.5 | AO24: 197.8 | AQ24: 53.4 | AR24: 198.2 | AW24: 49.6 | AX24: 107.7
A25: -11.45 | B25: 25.41 | P25: 221.8 | Q25: 79.7 | AK25: 47.9 | AL25: 193 | AN25: 50 | AO25: 201.7 | AQ25: 54 | AR25: 201.9 | AW25: 49.5 | AX25: 107.6
A26: -9.22 | B26: 27.08 | P26: 227 | Q26: 83.1 | AK26: 49.4 | AL26: 196.9 | AN26: 51.5 | AO26: 205.5 | AQ26: 54.5 | AR26: 205.7 | AW26: 49.4 | AX26: 107.5
A27: -6.99 | B27: 28.83 | P27: 232 | Q27: 86.6 | AK27: 50.9 | AL27: 200.7 | AN27: 53 | AO27: 209.4 | AQ27: 55 | AR27: 209.4 | AW27: 49.4 | AX27: 107.4
A28: -4.76 | B28: 30.66 | P28: 236.8 | Q28: 90.1 | AK28: 52.4 | AL28: 204.5 | AN28: 54.5 | AO28: 213.2 | AQ28: 55.5 | AR28: 213.2 | AW28: 49.3 | AX28: 107.3
A29: -2.53 | B29: 32.58 | P29: 241.5 | Q29: 93.6 | AK29: 53.9 | AL29: 208.3 | AN29: 56 | AO29: 217 | AQ29: 56 | AR29: 217 | AW29: 49.2 | AX29: 107.1
A30: -0.3 | B30: 34.58 | P30: 246 | Q30: 97.1 | AW30: 49.1 | AX30: 107
A31: 1.93 | B31: 36.67 | P31: 250.5 | Q31: 100.6 | AW31: 49 | AX31: 106.9
A32: 4.16 | B32: 38.85 | P32: 254.8 | Q32: 104 | AW32: 49 | AX32: 106.8
A33: 6.39 | B33: 41.13 | P33: 258.9 | Q33: 107.5 | AW33: 48.9 | AX33: 106.7
A34: 8.62 | B34: 43.51 | P34: 263 | Q34: 111 | AW34: 48.8 | AX34: 106.5
A35: 10.85 | B35: 45.98 | AW35: 48.8 | AX35: 106.4
A36: 13.08 | B36: 48.57 | AW36: 48.7 | AX36: 106.3
A37: 15.32 | B37: 51.26 | AW37: 48.6 | AX37: 106.2
A38: 17.55 | B38: 54.07 | AW38: 48.5 | AX38: 106.1
A39: 19.78 | B39: 56.99 | AW39: 48.4 | AX39: 105.9
A40: 22.01 | B40: 60.04 | AW40: 48.4 | AX40: 105.8
A41: 24.24 | B41: 63.22 | AW41: 48.3 | AX41: 105.7
...

Sheet p-h Diagramm
A1: p-h-Diagramm: Nassdampfdom mit Prozesspfaden
A2: Klassische Ingenieursdarstellung: Drosselung = senkrechte Linie (h=konst). Alles INNERHALB des Doms = Zweiphasengebiet.
A4: Dom h | B4: Dom p | D4: 3 Stufen h | E4: 3 Stufen p | G4: einstufig h | H4: einstufig p | J4: Drossel A h | K4: Drossel A p | M4: Drossel B h | N4: Drossel B p | P4: krit h | Q4: krit p | S4: Pumpe h | T4: Pumpe p | V4: Sz1 h | W4: Sz1 p | Y4: Fenster h | Z4: Fenster p | AB4: Kaverne h | AC4: Kaverne p | AE4: Drossel warm h | AF4: p
A5: 81 | B5: 5.3 | D5: 487.9 | E5: 10 | G5: 487.9 | H5: 10 | J5: 239.8 | K5: 120 | M5: 239.8 | N5: 120 | P5: 332.2 | Q5: 73.8 | S5: 232.1 | T5: 85 | V5: 239.8 | W5: 120 | Y5: 208 | Z5: 80 | AB5: 392.7 | AC5: 70 | AE5: 299.5 | AF5: 120
A6: 86 | B6: 5.9 | D6: 544.1 | E6: 22.3 | G6: 507.7 | H6: 13.5 | J6: 239.8 | K6: 40 | M6: 445.7 | N6: 120 | S6: 232.8 | T6: 90.2 | V6: 239.8 | W6: 85 | Y6: 263.1 | Z6: 80 | AB6: 471.5 | AC6: 70 | AE6: 299.5 | AF6: 85
A7: 91.1 | B7: 6.6 | D7: 499.4 | E7: 22.3 | G7: 524.1 | H7: 17 | M7: 445.7 | N7: 40 | S7: 233.5 | T7: 95.4 | Y7: 259.2 | Z7: 90 | AB7: 322.1 | AC7: 210
A8: 96.1 | B8: 7.3 | D8: 499.4 | E8: 22.3 | G8: 538.2 | H8: 20.4 | S8: 234.3 | T8: 100.6 | Y8: 207.2 | Z8: 90 | AB8: 254.3 | AC8: 210
A9: 101.2 | B9: 8.1 | D9: 557.5 | E9: 49.8 | G9: 550.6 | H9: 23.9 | S9: 235 | T9: 105.8 | Y9: 208 | Z9: 80 | AB9: 392.7 | AC9: 70
A10: 106.3 | B10: 8.9 | D10: 467.5 | E10: 49.8 | G10: 561.8 | H10: 27.4 | S10: 235.8 | T10: 111
A11: 111.5 | B11: 9.8 | D11: 467.5 | E11: 49.8 | G11: 571.9 | H11: 30.9
A12: 116.6 | B12: 10.7 | D12: 516.3 | E12: 111 | G12: 581.3 | H12: 34.4
A13: 121.8 | B13: 11.8 | D13: 301.6 | E13: 111 | G13: 589.9 | H13: 37.9
A14: 127.1 | B14: 12.9 | G14: 598 | H14: 41.3
A15: 132.4 | B15: 14.1 | G15: 605.6 | H15: 44.8
A16: 137.7 | B16: 15.3 | G16: 612.8 | H16: 48.3
A17: 143 | B17: 16.6 | G17: 619.6 | H17: 51.8
A18: 148.5 | B18: 18 | G18: 626.1 | H18: 55.3
A19: 153.9 | B19: 19.6 | G19: 632.2 | H19: 58.8
A20: 159.5 | B20: 21.1 | G20: 638.1 | H20: 62.2
A21: 165.1 | B21: 22.8 | G21: 643.8 | H21: 65.7
A22: 170.7 | B22: 24.6 | G22: 649.3 | H22: 69.2
A23: 176.5 | B23: 26.5 | G23: 654.5 | H23: 72.7
A24: 182.4 | B24: 28.5 | G24: 659.6 | H24: 76.2
A25: 188.3 | B25: 30.6 | G25: 664.5 | H25: 79.7
... A34: 249.7 | B34: 54.8 | G34: 702.8 | H34: 111
A35: 258.3 | B35: 58.2
A36: 267.7 | B36: 61.8
A37: 278.4 | B37: 65.6
A38: 291.9 | B38: 69.5
A39: 321.8 | B39: 73.7
A40: 343.5 | B40: 73.7
A41: 379 | B41: 69.5
A42: 391.4 | B42: 65.6
A43: 399.9 | B43: 61.8
A44: 406.4 | B44: 58.2
A45: 411.5 | B45: 54.8
A46: 415.8 | B46: 51.6
... A74: 430.6 | B74: 5.3
A78: Lesart (p-h):
A79: • OGE-Fall spielt sich komplett LINKS OBERHALB des Doms ab (dichte Phase, kleine h-Werte): Pumpe = kurzer Strich, Drossel Sz1 = kurze Senkrechte.
...

Sheet Phasendiagramm gasförmig
A1: Szenario: gasförmige Anlieferung und gasförmige Rücklieferung
A2: Einspeichern: 3-stufige Verdichtung ab 10 bar (vs. einstufig). Ausspeichern: Drossel unter pkrit – ohne vs. mit Vorwärmung.
A3: Datenreihen (aus CoolProp, Span-Wagner):
A4: Sättigung T [°C] | B4: p [bar] | D4: Verdicht. 3 Stufen T | E4: p [bar] | G4: Verdicht. einstufig T | H4: p [bar] | J4: Drossel ohne Vorw. T | K4: p [bar] | M4: Drossel mit Vorw. T | N4: p [bar] | P4: krit. Punkt T | Q4: p [bar] | S4: Isotherme 31°C T | T4: p [bar] | V4: Isobare 73,8 bar T | W4: p [bar] | Y4: Kaverne T | Z4: p [bar]
A5: -56.1 | B5: 5.3 | D5: 15 | E5: 10 | G5: 15 | H5: 10 | J5: 20 | K5: 120 | M5: 20 | N5: 120 | P5: 31 | Q5: 73.8 | S5: 31 | T5: 73.8 | V5: 31 | W5: 73.8 | Y5: 30 | Z5: 70
A6: -53.8 | B6: 5.8 | D6: 84.5 | E6: 22.3 | G6: 39.9 | H6: 13.5 | J6: 19.7 | K6: 115 | M6: 79.2 | N6: 120 | S6: 31 | T6: 140 | V6: 140 | W6: 73.8 | Y6: 60 | Z6: 70
A7: -51.6 | B7: 6.4 | D7: 40 | E7: 22.3 | G7: 60.1 | H7: 17 | J7: 19.5 | K7: 110 | M7: 76.5 | N7: 115 | Y7: 60 | Z7: 210
A8: -49.4 | B8: 7 | D8: 40 | E8: 22.3 | G8: 77.2 | H8: 20.4 | J8: 19.2 | K8: 105 | M8: 73.8 | N8: 110 | Y8: 30 | Z8: 210
A9: -47.1 | B9: 7.7 | D9: 114.2 | E9: 49.8 | G9: 92.1 | H9: 23.9 | J9: 18.9 | K9: 100 | M9: 70.9 | N9: 105 | Y9: 30 | Z9: 70
A10: -44.9 | B10: 8.3 | D10: 40 | E10: 49.8 | G10: 105.3 | H10: 27.4 | J10: 18.6 | K10: 95 | M10: 67.8 | N10: 100
A11: -42.7 | B11: 9.1 | D11: 40 | E11: 49.8 | G11: 117.2 | H11: 30.9 | J11: 18.3 | K11: 90 | M11: 64.6 | N11: 95
A12: -40.4 | B12: 9.9 | D12: 113.6 | E12: 111 | G12: 128.1 | H12: 34.4 | J12: 17.9 | K12: 85 | M12: 61.2 | N12: 90
A13: -38.2 | B13: 10.7 | D13: 40 | E13: 111 | G13: 138.1 | H13: 37.9 | J13: 17.5 | K13: 80 | M13: 57.7 | N13: 85
A14: -36 | B14: 11.6 | G14: 147.4 | H14: 41.3 | J14: 17.2 | K14: 75 | M14: 53.9 | N14: 80
A15: -33.8 | B15: 12.6 | G15: 156.1 | H15: 44.8 | J15: 16.7 | K15: 70 | M15: 50 | N15: 75
A16: -31.5 | B16: 13.6 | G16: 164.3 | H16: 48.3 | J16: 16.3 | K16: 65 | M16: 45.8 | N16: 70
A17: -29.3 | B17: 14.6 | G17: 172 | H17: 51.8 | J17: 15.9 | K17: 60 | M17: 41.5 | N17: 65
A18: -27.1 | B18: 15.7 | G18: 179.3 | H18: 55.3 | J18: 15.4 | K18: 55 | M18: 36.8 | N18: 60
A19: -24.8 | B19: 16.9 | G19: 186.2 | H19: 58.8 | J19: 14.3 | K19: 50 | M19: 31.9 | N19: 55
A20: -22.6 | B20: 18.2 | G20: 192.8 | H20: 62.2 | J20: 10 | K20: 45 | M20: 26.7 | N20: 50
A21: -20.4 | B21: 19.5 | G21: 199.1 | H21: 65.7 | J21: 5.3 | K21: 40 | M21: 21.2 | N21: 45
A22: -18.1 | B22: 20.8 | G22: 205.1 | H22: 69.2 | M22: 15.3 | N22: 40
A23: -15.9 | B23: 22.3 | G23: 210.9 | H23: 72.7
A24: -13.7 | B24: 23.8 | G24: 216.4 | H24: 76.2
A25: -11.4 | B25: 25.4 | G25: 221.8 | H25: 79.7
A26: -9.2 | B26: 27.1 | G26: 227 | H26: 83.1
A27: -7 | B27: 28.8 | G27: 232 | H27: 86.6
A28: -4.8 | B28: 30.7 | G28: 236.8 | H28: 90.1
A29: -2.5 | B29: 32.6 | G29: 241.5 | H29: 93.6
A30: -0.3 | B30: 34.6 | G30: 246 | H30: 97.1
A31: 1.9 | B31: 36.7 | G31: 250.5 | H31: 100.6
A32: 4.2 | B32: 38.9 | G32: 254.8 | H32: 104
A33: 6.4 | B33: 41.1 | G33: 258.9 | H33: 107.5
A34: 8.6 | B34: 43.5 | G34: 263 | H34: 111
A35: 10.9 | B35: 46
A36: 13.1 | B36: 48.6
A37: 15.3 | B37: 51.3
A38: 17.5 | B38: 54.1
A39: 19.8 | B39: 57
A40: 22 | B40: 60
...
